INFO 2025-09-09 00:11:21,923 autoreload 15700 14468 Watching for file changes with StatReloader
INFO 2025-09-09 00:11:45,586 autoreload 16968 23048 Watching for file changes with StatReloader
INFO 2025-09-09 00:12:35,221 autoreload 7732 12492 Watching for file changes with StatReloader
INFO 2025-09-09 00:13:06,861 autoreload 5576 15768 Watching for file changes with StatReloader
INFO 2025-09-09 00:13:40,834 autoreload 12212 18652 Watching for file changes with StatReloader
INFO 2025-09-09 00:14:21,079 autoreload 12212 18652 D:\project\uni\backend\config\settings.py changed, reloading.
INFO 2025-09-09 00:14:21,506 autoreload 8284 4068 Watching for file changes with StatReloader
INFO 2025-09-09 00:14:22,705 autoreload 8284 4068 D:\project\uni\backend\apps\courses\serializers.py changed, reloading.
INFO 2025-09-09 00:14:23,131 autoreload 22468 11540 Watching for file changes with StatReloader
INFO 2025-09-09 00:20:38,968 autoreload 22468 11540 D:\project\uni\backend\config\settings.py changed, reloading.
INFO 2025-09-09 00:23:23,234 autoreload 2608 26540 Watching for file changes with StatReloader
INFO 2025-09-09 00:23:57,417 autoreload 2608 26540 D:\project\uni\backend\apps\grades\models.py changed, reloading.
INFO 2025-09-09 00:23:57,856 autoreload 10992 7152 Watching for file changes with StatReloader
INFO 2025-09-09 00:23:59,091 autoreload 10992 7152 D:\project\uni\backend\apps\attendance\serializers.py changed, reloading.
INFO 2025-09-09 00:23:59,561 autoreload 23420 9896 Watching for file changes with StatReloader
INFO 2025-09-09 00:27:56,728 autoreload 16276 21648 Watching for file changes with StatReloader
INFO 2025-09-09 00:29:25,310 autoreload 16276 21648 D:\project\uni\backend\config\settings.py changed, reloading.
INFO 2025-09-09 00:29:25,749 autoreload 24068 2720 Watching for file changes with StatReloader
INFO 2025-09-09 00:32:05,654 autoreload 24068 2720 D:\project\uni\backend\config\settings.py changed, reloading.
INFO 2025-09-09 00:32:06,258 autoreload 1388 12372 Watching for file changes with StatReloader
INFO 2025-09-09 00:32:07,483 autoreload 1388 12372 D:\project\uni\backend\config\api_urls.py changed, reloading.
INFO 2025-09-09 00:32:07,957 autoreload 17524 10620 Watching for file changes with StatReloader
INFO 2025-09-09 00:32:11,157 autoreload 17524 10620 D:\project\uni\backend\config\settings.py changed, reloading.
INFO 2025-09-09 00:32:11,615 autoreload 11540 9360 Watching for file changes with StatReloader
INFO 2025-09-09 00:32:15,864 autoreload 11540 9360 D:\project\uni\backend\config\settings.py changed, reloading.
INFO 2025-09-09 00:32:16,277 autoreload 15444 23652 Watching for file changes with StatReloader
INFO 2025-09-09 00:32:17,441 autoreload 15444 23652 D:\project\uni\backend\config\settings.py changed, reloading.
INFO 2025-09-09 00:32:17,822 autoreload 11520 27288 Watching for file changes with StatReloader
INFO 2025-09-09 00:32:20,007 autoreload 11520 27288 D:\project\uni\backend\config\settings.py changed, reloading.
INFO 2025-09-09 00:32:20,373 autoreload 16712 8328 Watching for file changes with StatReloader
INFO 2025-09-09 00:33:18,424 autoreload 27564 17412 Watching for file changes with StatReloader
INFO 2025-09-09 00:39:37,789 autoreload 27328 26432 Watching for file changes with StatReloader
INFO 2025-09-09 00:40:52,277 autoreload 25988 7224 Watching for file changes with StatReloader
INFO 2025-09-09 00:44:50,186 autoreload 25988 7224 D:\project\uni\backend\apps\announcements\serializers.py changed, reloading.
INFO 2025-09-09 00:44:50,786 autoreload 25960 3504 Watching for file changes with StatReloader
INFO 2025-09-10 16:24:41,518 autoreload 3876 17660 Watching for file changes with StatReloader
INFO 2025-09-10 16:24:51,947 autoreload 8000 12684 Watching for file changes with StatReloader
INFO 2025-09-10 16:25:03,697 security_middleware 8000 17660 REQUEST - GET /api/health/ - User: Anonymous - IP: 127.0.0.1 - User-Agent: Mozilla/5.0 (Windows NT; Windows NT 10.0; en-US) WindowsPowerShell/5.1.19041.2673
ERROR 2025-09-10 16:25:03,716 log 8000 17660 Internal Server Error: /api/health/
Traceback (most recent call last):
  File "C:\Users\sina\AppData\Local\Programs\Python\Python313\Lib\site-packages\django\core\handlers\exception.py", line 55, in inner
    response = get_response(request)
  File "D:\project\uni\backend\config\security_middleware.py", line 111, in __call__
    f"User: {getattr(request.user, 'username', 'Anonymous')}"
                     ^^^^^^^^^^^^
AttributeError: 'WSGIRequest' object has no attribute 'user'
WARNING 2025-09-10 16:25:03,717 security_middleware 8000 17660 RESPONSE - GET /api/health/ - Status: 500 - Duration: 0.020s
ERROR 2025-09-10 16:25:03,717 basehttp 8000 17660 "GET /api/health/ HTTP/1.1" 500 73504
INFO 2025-09-10 16:25:38,198 autoreload 8000 12684 D:\project\uni\backend\config\security_middleware.py changed, reloading.
INFO 2025-09-10 16:25:38,886 autoreload 7364 12096 Watching for file changes with StatReloader
INFO 2025-09-10 16:25:59,197 security_middleware 7364 7152 REQUEST - GET /api/health/ - User: Anonymous - IP: 127.0.0.1 - User-Agent: Mozilla/5.0 (Windows NT; Windows NT 10.0; en-US) WindowsPowerShell/5.1.19041.2673
INFO 2025-09-10 16:25:59,198 security_middleware 7364 7152 API_REQUEST [d9763d95] - GET /api/health/ - User: Anonymous
ERROR 2025-09-10 16:25:59,239 log 7364 7152 Internal Server Error: /api/health/
Traceback (most recent call last):
  File "C:\Users\sina\AppData\Local\Programs\Python\Python313\Lib\site-packages\django\core\handlers\exception.py", line 55, in inner
    response = get_response(request)
  File "C:\Users\sina\AppData\Local\Programs\Python\Python313\Lib\site-packages\django\core\handlers\base.py", line 197, in _get_response
    response = wrapped_callback(request, *callback_args, **callback_kwargs)
  File "C:\Users\sina\AppData\Local\Programs\Python\Python313\Lib\site-packages\django\views\decorators\csrf.py", line 56, in wrapper_view
    return view_func(*args, **kwargs)
  File "C:\Users\sina\AppData\Local\Programs\Python\Python313\Lib\site-packages\django\views\generic\base.py", line 104, in view
    return self.dispatch(request, *args, **kwargs)
           ~~~~~~~~~~~~~^^^^^^^^^^^^^^^^^^^^^^^^^^
  File "C:\Users\sina\AppData\Local\Programs\Python\Python313\Lib\site-packages\rest_framework\views.py", line 509, in dispatch
    response = self.handle_exception(exc)
  File "C:\Users\sina\AppData\Local\Programs\Python\Python313\Lib\site-packages\rest_framework\views.py", line 469, in handle_exception
    self.raise_uncaught_exception(exc)
    ~~~~~~~~~~~~~~~~~~~~~~~~~~~~~^^^^^
  File "C:\Users\sina\AppData\Local\Programs\Python\Python313\Lib\site-packages\rest_framework\views.py", line 480, in raise_uncaught_exception
    raise exc
  File "C:\Users\sina\AppData\Local\Programs\Python\Python313\Lib\site-packages\rest_framework\views.py", line 497, in dispatch
    self.initial(request, *args, **kwargs)
    ~~~~~~~~~~~~^^^^^^^^^^^^^^^^^^^^^^^^^^
  File "C:\Users\sina\AppData\Local\Programs\Python\Python313\Lib\site-packages\rest_framework\views.py", line 416, in initial
    self.check_throttles(request)
    ~~~~~~~~~~~~~~~~~~~~^^^^^^^^^
  File "C:\Users\sina\AppData\Local\Programs\Python\Python313\Lib\site-packages\rest_framework\views.py", line 358, in check_throttles
    for throttle in self.get_throttles():
                    ~~~~~~~~~~~~~~~~~~^^
  File "C:\Users\sina\AppData\Local\Programs\Python\Python313\Lib\site-packages\rest_framework\views.py", line 284, in get_throttles
    return [throttle() for throttle in self.throttle_classes]
            ~~~~~~~~^^
  File "C:\Users\sina\AppData\Local\Programs\Python\Python313\Lib\site-packages\rest_framework\throttling.py", line 70, in __init__
    self.rate = self.get_rate()
                ~~~~~~~~~~~~~^^
  File "D:\project\uni\backend\config\throttling.py", line 46, in get_rate
    if self.view and hasattr(self.view, 'get_view_name'):
       ^^^^^^^^^
AttributeError: 'APIEndpointThrottle' object has no attribute 'view'
INFO 2025-09-10 16:25:59,244 security_middleware 7364 7152 API_RESPONSE [d9763d95] - GET /api/health/ - Status: 500
WARNING 2025-09-10 16:25:59,244 security_middleware 7364 7152 RESPONSE - GET /api/health/ - Status: 500 - Duration: 0.047s
ERROR 2025-09-10 16:25:59,245 basehttp 7364 7152 "GET /api/health/ HTTP/1.1" 500 121302
INFO 2025-09-10 16:26:15,739 autoreload 7364 12096 D:\project\uni\backend\config\throttling.py changed, reloading.
INFO 2025-09-10 16:26:16,329 autoreload 14152 552 Watching for file changes with StatReloader
INFO 2025-09-10 16:26:34,731 security_middleware 14152 11088 REQUEST - GET /api/health/ - User: Anonymous - IP: 127.0.0.1 - User-Agent: Mozilla/5.0 (Windows NT; Windows NT 10.0; en-US) WindowsPowerShell/5.1.19041.2673
INFO 2025-09-10 16:26:34,732 security_middleware 14152 11088 API_REQUEST [602aa5db] - GET /api/health/ - User: Anonymous
INFO 2025-09-10 16:26:34,737 security_middleware 14152 11088 API_RESPONSE [602aa5db] - GET /api/health/ - Status: 200
INFO 2025-09-10 16:26:34,738 security_middleware 14152 11088 RESPONSE - GET /api/health/ - Status: 200 - Duration: 0.006s
INFO 2025-09-10 16:26:34,738 basehttp 14152 11088 "GET /api/health/ HTTP/1.1" 200 100
INFO 2025-09-10 16:26:52,497 security_middleware 14152 11088 REQUEST - GET /api/health/ - User: Anonymous - IP: 127.0.0.1 - User-Agent: Mozilla/5.0 (Windows NT; Windows NT 10.0; en-US) WindowsPowerShell/5.1.19041.2673
INFO 2025-09-10 16:26:52,498 security_middleware 14152 11088 API_REQUEST [44a37ce5] - GET /api/health/ - User: Anonymous
INFO 2025-09-10 16:26:52,500 security_middleware 14152 11088 API_RESPONSE [44a37ce5] - GET /api/health/ - Status: 200
INFO 2025-09-10 16:26:52,500 security_middleware 14152 11088 RESPONSE - GET /api/health/ - Status: 200 - Duration: 0.003s
INFO 2025-09-10 16:26:52,500 basehttp 14152 11088 "GET /api/health/ HTTP/1.1" 200 100
INFO 2025-09-10 16:27:20,454 security_middleware 14152 11088 REQUEST - GET /api/health/ - User: Anonymous - IP: 127.0.0.1 - User-Agent: Mozilla/5.0 (Windows NT; Windows NT 10.0; en-US) WindowsPowerShell/5.1.19041.2673
INFO 2025-09-10 16:27:20,454 security_middleware 14152 11088 API_REQUEST [057f053b] - GET /api/health/ - User: Anonymous
WARNING 2025-09-10 16:27:20,455 advanced_security 14152 11088 XSS attempt detected in query parameter - IP: 127.0.0.1 - Param: test - Value: <script>alert('xss')</script>
INFO 2025-09-10 16:27:20,455 security_middleware 14152 11088 API_RESPONSE [057f053b] - GET /api/health/ - Status: 403
WARNING 2025-09-10 16:27:20,455 security_middleware 14152 11088 RESPONSE - GET /api/health/ - Status: 403 - Duration: 0.002s
WARNING 2025-09-10 16:27:20,456 log 14152 11088 Forbidden: /api/health/
WARNING 2025-09-10 16:27:20,456 basehttp 14152 11088 "GET /api/health/?test=%3Cscript%3Ealert('xss')%3C/script%3E HTTP/1.1" 403 15
INFO 2025-09-10 16:28:57,231 autoreload 14152 552 D:\project\uni\backend\apps\users\urls.py changed, reloading.
INFO 2025-09-10 16:28:58,161 autoreload 7152 17336 Watching for file changes with StatReloader
INFO 2025-09-10 16:30:12,296 autoreload 7152 17336 D:\project\uni\backend\config\settings.py changed, reloading.
INFO 2025-09-10 16:30:13,612 autoreload 6728 8880 Watching for file changes with StatReloader
INFO 2025-09-10 16:30:24,110 autoreload 6728 8880 D:\project\uni\backend\config\settings.py changed, reloading.
INFO 2025-09-10 16:30:25,750 autoreload 20204 19388 Watching for file changes with StatReloader
INFO 2025-09-10 16:30:37,908 autoreload 20204 19388 D:\project\uni\backend\config\settings.py changed, reloading.
INFO 2025-09-10 16:30:38,823 autoreload 20336 20136 Watching for file changes with StatReloader
INFO 2025-09-10 16:41:54,352 security_middleware 6600 6824 REQUEST - POST /api/courses/courses/ - User: Anonymous - IP: 127.0.0.1 - User-Agent: Unknown
INFO 2025-09-10 16:41:54,353 security_middleware 6600 6824 API_REQUEST [a8352e21] - POST /api/courses/courses/ - User: Anonymous
ERROR 2025-09-10 16:41:56,409 log 6600 6824 Internal Server Error: /api/courses/courses/
Traceback (most recent call last):
  File "C:\Users\sina\AppData\Local\Programs\Python\Python313\Lib\site-packages\django_redis\cache.py", line 29, in _decorator
    return method(self, *args, **kwargs)
  File "C:\Users\sina\AppData\Local\Programs\Python\Python313\Lib\site-packages\django_redis\cache.py", line 99, in _get
    return self.client.get(key, default=default, version=version, client=client)
           ~~~~~~~~~~~~~~~^^^^^^^^^^^^^^^^^^^^^^^^^^^^^^^^^^^^^^^^^^^^^^^^^^^^^^
  File "C:\Users\sina\AppData\Local\Programs\Python\Python313\Lib\site-packages\django_redis\client\default.py", line 260, in get
    raise ConnectionInterrupted(connection=client) from e
django_redis.exceptions.ConnectionInterrupted: Redis ConnectionError: Error 10061 connecting to 127.0.0.1:6379. No connection could be made because the target machine actively refused it.

During handling of the above exception, another exception occurred:

Traceback (most recent call last):
  File "C:\Users\sina\AppData\Local\Programs\Python\Python313\Lib\site-packages\django\core\handlers\exception.py", line 55, in inner
    response = get_response(request)
  File "C:\Users\sina\AppData\Local\Programs\Python\Python313\Lib\site-packages\django\core\handlers\base.py", line 197, in _get_response
    response = wrapped_callback(request, *callback_args, **callback_kwargs)
  File "C:\Users\sina\AppData\Local\Programs\Python\Python313\Lib\site-packages\django\views\decorators\csrf.py", line 56, in wrapper_view
    return view_func(*args, **kwargs)
  File "C:\Users\sina\AppData\Local\Programs\Python\Python313\Lib\site-packages\rest_framework\viewsets.py", line 125, in view
    return self.dispatch(request, *args, **kwargs)
           ~~~~~~~~~~~~~^^^^^^^^^^^^^^^^^^^^^^^^^^
  File "C:\Users\sina\AppData\Local\Programs\Python\Python313\Lib\site-packages\rest_framework\views.py", line 509, in dispatch
    response = self.handle_exception(exc)
  File "C:\Users\sina\AppData\Local\Programs\Python\Python313\Lib\site-packages\rest_framework\views.py", line 469, in handle_exception
    self.raise_uncaught_exception(exc)
    ~~~~~~~~~~~~~~~~~~~~~~~~~~~~~^^^^^
  File "C:\Users\sina\AppData\Local\Programs\Python\Python313\Lib\site-packages\rest_framework\views.py", line 480, in raise_uncaught_exception
    raise exc
  File "C:\Users\sina\AppData\Local\Programs\Python\Python313\Lib\site-packages\rest_framework\views.py", line 497, in dispatch
    self.initial(request, *args, **kwargs)
    ~~~~~~~~~~~~^^^^^^^^^^^^^^^^^^^^^^^^^^
  File "C:\Users\sina\AppData\Local\Programs\Python\Python313\Lib\site-packages\rest_framework\views.py", line 416, in initial
    self.check_throttles(request)
    ~~~~~~~~~~~~~~~~~~~~^^^^^^^^^
  File "C:\Users\sina\AppData\Local\Programs\Python\Python313\Lib\site-packages\rest_framework\views.py", line 359, in check_throttles
    if not throttle.allow_request(request, self):
           ~~~~~~~~~~~~~~~~~~~~~~^^^^^^^^^^^^^^^
  File "C:\Users\sina\AppData\Local\Programs\Python\Python313\Lib\site-packages\rest_framework\throttling.py", line 123, in allow_request
    self.history = self.cache.get(self.key, [])
                   ~~~~~~~~~~~~~~^^^^^^^^^^^^^^
  File "C:\Users\sina\AppData\Local\Programs\Python\Python313\Lib\site-packages\django_redis\cache.py", line 92, in get
    value = self._get(key, default, version, client)
  File "C:\Users\sina\AppData\Local\Programs\Python\Python313\Lib\site-packages\django_redis\cache.py", line 36, in _decorator
    raise e.__cause__
  File "C:\Users\sina\AppData\Local\Programs\Python\Python313\Lib\site-packages\django_redis\client\default.py", line 258, in get
    value = client.get(key)
  File "C:\Users\sina\AppData\Local\Programs\Python\Python313\Lib\site-packages\redis\commands\core.py", line 1821, in get
    return self.execute_command("GET", name)
           ~~~~~~~~~~~~~~~~~~~~^^^^^^^^^^^^^
  File "C:\Users\sina\AppData\Local\Programs\Python\Python313\Lib\site-packages\redis\client.py", line 545, in execute_command
    conn = self.connection or pool.get_connection(command_name, **options)
                              ~~~~~~~~~~~~~~~~~~~^^^^^^^^^^^^^^^^^^^^^^^^^
  File "C:\Users\sina\AppData\Local\Programs\Python\Python313\Lib\site-packages\redis\connection.py", line 1074, in get_connection
    connection.connect()
    ~~~~~~~~~~~~~~~~~~^^
  File "C:\Users\sina\AppData\Local\Programs\Python\Python313\Lib\site-packages\redis\connection.py", line 283, in connect
    raise ConnectionError(self._error_message(e))
redis.exceptions.ConnectionError: Error 10061 connecting to 127.0.0.1:6379. No connection could be made because the target machine actively refused it.
INFO 2025-09-10 16:41:56,483 security_middleware 6600 6824 API_RESPONSE [a8352e21] - POST /api/courses/courses/ - Status: 500
WARNING 2025-09-10 16:41:56,483 security_middleware 6600 6824 RESPONSE - POST /api/courses/courses/ - Status: 500 - Duration: 2.131s
INFO 2025-09-10 16:41:57,096 security_middleware 6600 6824 REQUEST - POST /api/courses/courses/1/enroll_student/ - User: Anonymous - IP: 127.0.0.1 - User-Agent: Unknown
INFO 2025-09-10 16:41:57,097 security_middleware 6600 6824 API_REQUEST [5ee06bc6] - POST /api/courses/courses/1/enroll_student/ - User: Anonymous
ERROR 2025-09-10 16:41:59,134 log 6600 6824 Internal Server Error: /api/courses/courses/1/enroll_student/
Traceback (most recent call last):
  File "C:\Users\sina\AppData\Local\Programs\Python\Python313\Lib\site-packages\django_redis\cache.py", line 29, in _decorator
    return method(self, *args, **kwargs)
  File "C:\Users\sina\AppData\Local\Programs\Python\Python313\Lib\site-packages\django_redis\cache.py", line 99, in _get
    return self.client.get(key, default=default, version=version, client=client)
           ~~~~~~~~~~~~~~~^^^^^^^^^^^^^^^^^^^^^^^^^^^^^^^^^^^^^^^^^^^^^^^^^^^^^^
  File "C:\Users\sina\AppData\Local\Programs\Python\Python313\Lib\site-packages\django_redis\client\default.py", line 260, in get
    raise ConnectionInterrupted(connection=client) from e
django_redis.exceptions.ConnectionInterrupted: Redis ConnectionError: Error 10061 connecting to 127.0.0.1:6379. No connection could be made because the target machine actively refused it.

During handling of the above exception, another exception occurred:

Traceback (most recent call last):
  File "C:\Users\sina\AppData\Local\Programs\Python\Python313\Lib\site-packages\django\core\handlers\exception.py", line 55, in inner
    response = get_response(request)
  File "C:\Users\sina\AppData\Local\Programs\Python\Python313\Lib\site-packages\django\core\handlers\base.py", line 197, in _get_response
    response = wrapped_callback(request, *callback_args, **callback_kwargs)
  File "C:\Users\sina\AppData\Local\Programs\Python\Python313\Lib\site-packages\django\views\decorators\csrf.py", line 56, in wrapper_view
    return view_func(*args, **kwargs)
  File "C:\Users\sina\AppData\Local\Programs\Python\Python313\Lib\site-packages\rest_framework\viewsets.py", line 125, in view
    return self.dispatch(request, *args, **kwargs)
           ~~~~~~~~~~~~~^^^^^^^^^^^^^^^^^^^^^^^^^^
  File "C:\Users\sina\AppData\Local\Programs\Python\Python313\Lib\site-packages\rest_framework\views.py", line 509, in dispatch
    response = self.handle_exception(exc)
  File "C:\Users\sina\AppData\Local\Programs\Python\Python313\Lib\site-packages\rest_framework\views.py", line 469, in handle_exception
    self.raise_uncaught_exception(exc)
    ~~~~~~~~~~~~~~~~~~~~~~~~~~~~~^^^^^
  File "C:\Users\sina\AppData\Local\Programs\Python\Python313\Lib\site-packages\rest_framework\views.py", line 480, in raise_uncaught_exception
    raise exc
  File "C:\Users\sina\AppData\Local\Programs\Python\Python313\Lib\site-packages\rest_framework\views.py", line 497, in dispatch
    self.initial(request, *args, **kwargs)
    ~~~~~~~~~~~~^^^^^^^^^^^^^^^^^^^^^^^^^^
  File "C:\Users\sina\AppData\Local\Programs\Python\Python313\Lib\site-packages\rest_framework\views.py", line 416, in initial
    self.check_throttles(request)
    ~~~~~~~~~~~~~~~~~~~~^^^^^^^^^
  File "C:\Users\sina\AppData\Local\Programs\Python\Python313\Lib\site-packages\rest_framework\views.py", line 359, in check_throttles
    if not throttle.allow_request(request, self):
           ~~~~~~~~~~~~~~~~~~~~~~^^^^^^^^^^^^^^^
  File "C:\Users\sina\AppData\Local\Programs\Python\Python313\Lib\site-packages\rest_framework\throttling.py", line 123, in allow_request
    self.history = self.cache.get(self.key, [])
                   ~~~~~~~~~~~~~~^^^^^^^^^^^^^^
  File "C:\Users\sina\AppData\Local\Programs\Python\Python313\Lib\site-packages\django_redis\cache.py", line 92, in get
    value = self._get(key, default, version, client)
  File "C:\Users\sina\AppData\Local\Programs\Python\Python313\Lib\site-packages\django_redis\cache.py", line 36, in _decorator
    raise e.__cause__
  File "C:\Users\sina\AppData\Local\Programs\Python\Python313\Lib\site-packages\django_redis\client\default.py", line 258, in get
    value = client.get(key)
  File "C:\Users\sina\AppData\Local\Programs\Python\Python313\Lib\site-packages\redis\commands\core.py", line 1821, in get
    return self.execute_command("GET", name)
           ~~~~~~~~~~~~~~~~~~~~^^^^^^^^^^^^^
  File "C:\Users\sina\AppData\Local\Programs\Python\Python313\Lib\site-packages\redis\client.py", line 545, in execute_command
    conn = self.connection or pool.get_connection(command_name, **options)
                              ~~~~~~~~~~~~~~~~~~~^^^^^^^^^^^^^^^^^^^^^^^^^
  File "C:\Users\sina\AppData\Local\Programs\Python\Python313\Lib\site-packages\redis\connection.py", line 1074, in get_connection
    connection.connect()
    ~~~~~~~~~~~~~~~~~~^^
  File "C:\Users\sina\AppData\Local\Programs\Python\Python313\Lib\site-packages\redis\connection.py", line 283, in connect
    raise ConnectionError(self._error_message(e))
redis.exceptions.ConnectionError: Error 10061 connecting to 127.0.0.1:6379. No connection could be made because the target machine actively refused it.
INFO 2025-09-10 16:41:59,139 security_middleware 6600 6824 API_RESPONSE [5ee06bc6] - POST /api/courses/courses/1/enroll_student/ - Status: 500
WARNING 2025-09-10 16:41:59,139 security_middleware 6600 6824 RESPONSE - POST /api/courses/courses/1/enroll_student/ - Status: 500 - Duration: 2.043s
INFO 2025-09-10 16:41:59,738 security_middleware 6600 6824 REQUEST - POST /api/courses/courses/1/enroll_student/ - User: Anonymous - IP: 127.0.0.1 - User-Agent: Unknown
INFO 2025-09-10 16:41:59,738 security_middleware 6600 6824 API_REQUEST [532884e0] - POST /api/courses/courses/1/enroll_student/ - User: Anonymous
ERROR 2025-09-10 16:42:01,770 log 6600 6824 Internal Server Error: /api/courses/courses/1/enroll_student/
Traceback (most recent call last):
  File "C:\Users\sina\AppData\Local\Programs\Python\Python313\Lib\site-packages\django_redis\cache.py", line 29, in _decorator
    return method(self, *args, **kwargs)
  File "C:\Users\sina\AppData\Local\Programs\Python\Python313\Lib\site-packages\django_redis\cache.py", line 99, in _get
    return self.client.get(key, default=default, version=version, client=client)
           ~~~~~~~~~~~~~~~^^^^^^^^^^^^^^^^^^^^^^^^^^^^^^^^^^^^^^^^^^^^^^^^^^^^^^
  File "C:\Users\sina\AppData\Local\Programs\Python\Python313\Lib\site-packages\django_redis\client\default.py", line 260, in get
    raise ConnectionInterrupted(connection=client) from e
django_redis.exceptions.ConnectionInterrupted: Redis ConnectionError: Error 10061 connecting to 127.0.0.1:6379. No connection could be made because the target machine actively refused it.

During handling of the above exception, another exception occurred:

Traceback (most recent call last):
  File "C:\Users\sina\AppData\Local\Programs\Python\Python313\Lib\site-packages\django\core\handlers\exception.py", line 55, in inner
    response = get_response(request)
  File "C:\Users\sina\AppData\Local\Programs\Python\Python313\Lib\site-packages\django\core\handlers\base.py", line 197, in _get_response
    response = wrapped_callback(request, *callback_args, **callback_kwargs)
  File "C:\Users\sina\AppData\Local\Programs\Python\Python313\Lib\site-packages\django\views\decorators\csrf.py", line 56, in wrapper_view
    return view_func(*args, **kwargs)
  File "C:\Users\sina\AppData\Local\Programs\Python\Python313\Lib\site-packages\rest_framework\viewsets.py", line 125, in view
    return self.dispatch(request, *args, **kwargs)
           ~~~~~~~~~~~~~^^^^^^^^^^^^^^^^^^^^^^^^^^
  File "C:\Users\sina\AppData\Local\Programs\Python\Python313\Lib\site-packages\rest_framework\views.py", line 509, in dispatch
    response = self.handle_exception(exc)
  File "C:\Users\sina\AppData\Local\Programs\Python\Python313\Lib\site-packages\rest_framework\views.py", line 469, in handle_exception
    self.raise_uncaught_exception(exc)
    ~~~~~~~~~~~~~~~~~~~~~~~~~~~~~^^^^^
  File "C:\Users\sina\AppData\Local\Programs\Python\Python313\Lib\site-packages\rest_framework\views.py", line 480, in raise_uncaught_exception
    raise exc
  File "C:\Users\sina\AppData\Local\Programs\Python\Python313\Lib\site-packages\rest_framework\views.py", line 497, in dispatch
    self.initial(request, *args, **kwargs)
    ~~~~~~~~~~~~^^^^^^^^^^^^^^^^^^^^^^^^^^
  File "C:\Users\sina\AppData\Local\Programs\Python\Python313\Lib\site-packages\rest_framework\views.py", line 416, in initial
    self.check_throttles(request)
    ~~~~~~~~~~~~~~~~~~~~^^^^^^^^^
  File "C:\Users\sina\AppData\Local\Programs\Python\Python313\Lib\site-packages\rest_framework\views.py", line 359, in check_throttles
    if not throttle.allow_request(request, self):
           ~~~~~~~~~~~~~~~~~~~~~~^^^^^^^^^^^^^^^
  File "C:\Users\sina\AppData\Local\Programs\Python\Python313\Lib\site-packages\rest_framework\throttling.py", line 123, in allow_request
    self.history = self.cache.get(self.key, [])
                   ~~~~~~~~~~~~~~^^^^^^^^^^^^^^
  File "C:\Users\sina\AppData\Local\Programs\Python\Python313\Lib\site-packages\django_redis\cache.py", line 92, in get
    value = self._get(key, default, version, client)
  File "C:\Users\sina\AppData\Local\Programs\Python\Python313\Lib\site-packages\django_redis\cache.py", line 36, in _decorator
    raise e.__cause__
  File "C:\Users\sina\AppData\Local\Programs\Python\Python313\Lib\site-packages\django_redis\client\default.py", line 258, in get
    value = client.get(key)
  File "C:\Users\sina\AppData\Local\Programs\Python\Python313\Lib\site-packages\redis\commands\core.py", line 1821, in get
    return self.execute_command("GET", name)
           ~~~~~~~~~~~~~~~~~~~~^^^^^^^^^^^^^
  File "C:\Users\sina\AppData\Local\Programs\Python\Python313\Lib\site-packages\redis\client.py", line 545, in execute_command
    conn = self.connection or pool.get_connection(command_name, **options)
                              ~~~~~~~~~~~~~~~~~~~^^^^^^^^^^^^^^^^^^^^^^^^^
  File "C:\Users\sina\AppData\Local\Programs\Python\Python313\Lib\site-packages\redis\connection.py", line 1074, in get_connection
    connection.connect()
    ~~~~~~~~~~~~~~~~~~^^
  File "C:\Users\sina\AppData\Local\Programs\Python\Python313\Lib\site-packages\redis\connection.py", line 283, in connect
    raise ConnectionError(self._error_message(e))
redis.exceptions.ConnectionError: Error 10061 connecting to 127.0.0.1:6379. No connection could be made because the target machine actively refused it.
INFO 2025-09-10 16:42:01,775 security_middleware 6600 6824 API_RESPONSE [532884e0] - POST /api/courses/courses/1/enroll_student/ - Status: 500
WARNING 2025-09-10 16:42:01,776 security_middleware 6600 6824 RESPONSE - POST /api/courses/courses/1/enroll_student/ - Status: 500 - Duration: 2.038s
INFO 2025-09-10 16:42:02,353 security_middleware 6600 6824 REQUEST - GET /api/courses/courses/ - User: Anonymous - IP: 127.0.0.1 - User-Agent: Unknown
INFO 2025-09-10 16:42:02,353 security_middleware 6600 6824 API_REQUEST [61dbc3ee] - GET /api/courses/courses/ - User: Anonymous
ERROR 2025-09-10 16:42:04,388 log 6600 6824 Internal Server Error: /api/courses/courses/
Traceback (most recent call last):
  File "C:\Users\sina\AppData\Local\Programs\Python\Python313\Lib\site-packages\django_redis\cache.py", line 29, in _decorator
    return method(self, *args, **kwargs)
  File "C:\Users\sina\AppData\Local\Programs\Python\Python313\Lib\site-packages\django_redis\cache.py", line 99, in _get
    return self.client.get(key, default=default, version=version, client=client)
           ~~~~~~~~~~~~~~~^^^^^^^^^^^^^^^^^^^^^^^^^^^^^^^^^^^^^^^^^^^^^^^^^^^^^^
  File "C:\Users\sina\AppData\Local\Programs\Python\Python313\Lib\site-packages\django_redis\client\default.py", line 260, in get
    raise ConnectionInterrupted(connection=client) from e
django_redis.exceptions.ConnectionInterrupted: Redis ConnectionError: Error 10061 connecting to 127.0.0.1:6379. No connection could be made because the target machine actively refused it.

During handling of the above exception, another exception occurred:

Traceback (most recent call last):
  File "C:\Users\sina\AppData\Local\Programs\Python\Python313\Lib\site-packages\django\core\handlers\exception.py", line 55, in inner
    response = get_response(request)
  File "C:\Users\sina\AppData\Local\Programs\Python\Python313\Lib\site-packages\django\utils\deprecation.py", line 133, in __call__
    response = self.process_request(request)
  File "C:\Users\sina\AppData\Local\Programs\Python\Python313\Lib\site-packages\django\middleware\cache.py", line 158, in process_request
    cache_key = get_cache_key(request, self.key_prefix, "GET", cache=self.cache)
  File "C:\Users\sina\AppData\Local\Programs\Python\Python313\Lib\site-packages\django\utils\cache.py", line 391, in get_cache_key
    headerlist = cache.get(cache_key)
  File "C:\Users\sina\AppData\Local\Programs\Python\Python313\Lib\site-packages\django_redis\cache.py", line 92, in get
    value = self._get(key, default, version, client)
  File "C:\Users\sina\AppData\Local\Programs\Python\Python313\Lib\site-packages\django_redis\cache.py", line 36, in _decorator
    raise e.__cause__
  File "C:\Users\sina\AppData\Local\Programs\Python\Python313\Lib\site-packages\django_redis\client\default.py", line 258, in get
    value = client.get(key)
  File "C:\Users\sina\AppData\Local\Programs\Python\Python313\Lib\site-packages\redis\commands\core.py", line 1821, in get
    return self.execute_command("GET", name)
           ~~~~~~~~~~~~~~~~~~~~^^^^^^^^^^^^^
  File "C:\Users\sina\AppData\Local\Programs\Python\Python313\Lib\site-packages\redis\client.py", line 545, in execute_command
    conn = self.connection or pool.get_connection(command_name, **options)
                              ~~~~~~~~~~~~~~~~~~~^^^^^^^^^^^^^^^^^^^^^^^^^
  File "C:\Users\sina\AppData\Local\Programs\Python\Python313\Lib\site-packages\redis\connection.py", line 1074, in get_connection
    connection.connect()
    ~~~~~~~~~~~~~~~~~~^^
  File "C:\Users\sina\AppData\Local\Programs\Python\Python313\Lib\site-packages\redis\connection.py", line 283, in connect
    raise ConnectionError(self._error_message(e))
redis.exceptions.ConnectionError: Error 10061 connecting to 127.0.0.1:6379. No connection could be made because the target machine actively refused it.
INFO 2025-09-10 16:42:04,423 security_middleware 6600 6824 API_RESPONSE [61dbc3ee] - GET /api/courses/courses/ - Status: 500
WARNING 2025-09-10 16:42:04,424 security_middleware 6600 6824 RESPONSE - GET /api/courses/courses/ - Status: 500 - Duration: 2.071s
INFO 2025-09-10 16:42:05,012 security_middleware 6600 6824 REQUEST - GET /api/courses/courses/ - User: Anonymous - IP: 127.0.0.1 - User-Agent: Unknown
INFO 2025-09-10 16:42:05,013 security_middleware 6600 6824 API_REQUEST [4aae9b53] - GET /api/courses/courses/ - User: Anonymous
ERROR 2025-09-10 16:42:07,043 log 6600 6824 Internal Server Error: /api/courses/courses/
Traceback (most recent call last):
  File "C:\Users\sina\AppData\Local\Programs\Python\Python313\Lib\site-packages\django_redis\cache.py", line 29, in _decorator
    return method(self, *args, **kwargs)
  File "C:\Users\sina\AppData\Local\Programs\Python\Python313\Lib\site-packages\django_redis\cache.py", line 99, in _get
    return self.client.get(key, default=default, version=version, client=client)
           ~~~~~~~~~~~~~~~^^^^^^^^^^^^^^^^^^^^^^^^^^^^^^^^^^^^^^^^^^^^^^^^^^^^^^
  File "C:\Users\sina\AppData\Local\Programs\Python\Python313\Lib\site-packages\django_redis\client\default.py", line 260, in get
    raise ConnectionInterrupted(connection=client) from e
django_redis.exceptions.ConnectionInterrupted: Redis ConnectionError: Error 10061 connecting to 127.0.0.1:6379. No connection could be made because the target machine actively refused it.

During handling of the above exception, another exception occurred:

Traceback (most recent call last):
  File "C:\Users\sina\AppData\Local\Programs\Python\Python313\Lib\site-packages\django\core\handlers\exception.py", line 55, in inner
    response = get_response(request)
  File "C:\Users\sina\AppData\Local\Programs\Python\Python313\Lib\site-packages\django\utils\deprecation.py", line 133, in __call__
    response = self.process_request(request)
  File "C:\Users\sina\AppData\Local\Programs\Python\Python313\Lib\site-packages\django\middleware\cache.py", line 158, in process_request
    cache_key = get_cache_key(request, self.key_prefix, "GET", cache=self.cache)
  File "C:\Users\sina\AppData\Local\Programs\Python\Python313\Lib\site-packages\django\utils\cache.py", line 391, in get_cache_key
    headerlist = cache.get(cache_key)
  File "C:\Users\sina\AppData\Local\Programs\Python\Python313\Lib\site-packages\django_redis\cache.py", line 92, in get
    value = self._get(key, default, version, client)
  File "C:\Users\sina\AppData\Local\Programs\Python\Python313\Lib\site-packages\django_redis\cache.py", line 36, in _decorator
    raise e.__cause__
  File "C:\Users\sina\AppData\Local\Programs\Python\Python313\Lib\site-packages\django_redis\client\default.py", line 258, in get
    value = client.get(key)
  File "C:\Users\sina\AppData\Local\Programs\Python\Python313\Lib\site-packages\redis\commands\core.py", line 1821, in get
    return self.execute_command("GET", name)
           ~~~~~~~~~~~~~~~~~~~~^^^^^^^^^^^^^
  File "C:\Users\sina\AppData\Local\Programs\Python\Python313\Lib\site-packages\redis\client.py", line 545, in execute_command
    conn = self.connection or pool.get_connection(command_name, **options)
                              ~~~~~~~~~~~~~~~~~~~^^^^^^^^^^^^^^^^^^^^^^^^^
  File "C:\Users\sina\AppData\Local\Programs\Python\Python313\Lib\site-packages\redis\connection.py", line 1074, in get_connection
    connection.connect()
    ~~~~~~~~~~~~~~~~~~^^
  File "C:\Users\sina\AppData\Local\Programs\Python\Python313\Lib\site-packages\redis\connection.py", line 283, in connect
    raise ConnectionError(self._error_message(e))
redis.exceptions.ConnectionError: Error 10061 connecting to 127.0.0.1:6379. No connection could be made because the target machine actively refused it.
INFO 2025-09-10 16:42:07,045 security_middleware 6600 6824 API_RESPONSE [4aae9b53] - GET /api/courses/courses/ - Status: 500
WARNING 2025-09-10 16:42:07,046 security_middleware 6600 6824 RESPONSE - GET /api/courses/courses/ - Status: 500 - Duration: 2.033s
INFO 2025-09-10 16:42:07,746 security_middleware 6600 6824 REQUEST - GET /api/courses/courses/ - User: Anonymous - IP: 127.0.0.1 - User-Agent: Unknown
INFO 2025-09-10 16:42:07,747 security_middleware 6600 6824 API_REQUEST [4c84b4b0] - GET /api/courses/courses/ - User: Anonymous
ERROR 2025-09-10 16:42:09,798 log 6600 6824 Internal Server Error: /api/courses/courses/
Traceback (most recent call last):
  File "C:\Users\sina\AppData\Local\Programs\Python\Python313\Lib\site-packages\django_redis\cache.py", line 29, in _decorator
    return method(self, *args, **kwargs)
  File "C:\Users\sina\AppData\Local\Programs\Python\Python313\Lib\site-packages\django_redis\cache.py", line 99, in _get
    return self.client.get(key, default=default, version=version, client=client)
           ~~~~~~~~~~~~~~~^^^^^^^^^^^^^^^^^^^^^^^^^^^^^^^^^^^^^^^^^^^^^^^^^^^^^^
  File "C:\Users\sina\AppData\Local\Programs\Python\Python313\Lib\site-packages\django_redis\client\default.py", line 260, in get
    raise ConnectionInterrupted(connection=client) from e
django_redis.exceptions.ConnectionInterrupted: Redis ConnectionError: Error 10061 connecting to 127.0.0.1:6379. No connection could be made because the target machine actively refused it.

During handling of the above exception, another exception occurred:

Traceback (most recent call last):
  File "C:\Users\sina\AppData\Local\Programs\Python\Python313\Lib\site-packages\django\core\handlers\exception.py", line 55, in inner
    response = get_response(request)
  File "C:\Users\sina\AppData\Local\Programs\Python\Python313\Lib\site-packages\django\utils\deprecation.py", line 133, in __call__
    response = self.process_request(request)
  File "C:\Users\sina\AppData\Local\Programs\Python\Python313\Lib\site-packages\django\middleware\cache.py", line 158, in process_request
    cache_key = get_cache_key(request, self.key_prefix, "GET", cache=self.cache)
  File "C:\Users\sina\AppData\Local\Programs\Python\Python313\Lib\site-packages\django\utils\cache.py", line 391, in get_cache_key
    headerlist = cache.get(cache_key)
  File "C:\Users\sina\AppData\Local\Programs\Python\Python313\Lib\site-packages\django_redis\cache.py", line 92, in get
    value = self._get(key, default, version, client)
  File "C:\Users\sina\AppData\Local\Programs\Python\Python313\Lib\site-packages\django_redis\cache.py", line 36, in _decorator
    raise e.__cause__
  File "C:\Users\sina\AppData\Local\Programs\Python\Python313\Lib\site-packages\django_redis\client\default.py", line 258, in get
    value = client.get(key)
  File "C:\Users\sina\AppData\Local\Programs\Python\Python313\Lib\site-packages\redis\commands\core.py", line 1821, in get
    return self.execute_command("GET", name)
           ~~~~~~~~~~~~~~~~~~~~^^^^^^^^^^^^^
  File "C:\Users\sina\AppData\Local\Programs\Python\Python313\Lib\site-packages\redis\client.py", line 545, in execute_command
    conn = self.connection or pool.get_connection(command_name, **options)
                              ~~~~~~~~~~~~~~~~~~~^^^^^^^^^^^^^^^^^^^^^^^^^
  File "C:\Users\sina\AppData\Local\Programs\Python\Python313\Lib\site-packages\redis\connection.py", line 1074, in get_connection
    connection.connect()
    ~~~~~~~~~~~~~~~~~~^^
  File "C:\Users\sina\AppData\Local\Programs\Python\Python313\Lib\site-packages\redis\connection.py", line 283, in connect
    raise ConnectionError(self._error_message(e))
redis.exceptions.ConnectionError: Error 10061 connecting to 127.0.0.1:6379. No connection could be made because the target machine actively refused it.
INFO 2025-09-10 16:42:09,803 security_middleware 6600 6824 API_RESPONSE [4c84b4b0] - GET /api/courses/courses/ - Status: 500
WARNING 2025-09-10 16:42:09,803 security_middleware 6600 6824 RESPONSE - GET /api/courses/courses/ - Status: 500 - Duration: 2.057s
INFO 2025-09-10 16:42:10,601 security_middleware 6600 6824 REQUEST - GET /api/courses/courses/ - User: Anonymous - IP: 127.0.0.1 - User-Agent: Unknown
INFO 2025-09-10 16:42:10,601 security_middleware 6600 6824 API_REQUEST [1c742fb0] - GET /api/courses/courses/ - User: Anonymous
ERROR 2025-09-10 16:42:12,652 log 6600 6824 Internal Server Error: /api/courses/courses/
Traceback (most recent call last):
  File "C:\Users\sina\AppData\Local\Programs\Python\Python313\Lib\site-packages\django_redis\cache.py", line 29, in _decorator
    return method(self, *args, **kwargs)
  File "C:\Users\sina\AppData\Local\Programs\Python\Python313\Lib\site-packages\django_redis\cache.py", line 99, in _get
    return self.client.get(key, default=default, version=version, client=client)
           ~~~~~~~~~~~~~~~^^^^^^^^^^^^^^^^^^^^^^^^^^^^^^^^^^^^^^^^^^^^^^^^^^^^^^
  File "C:\Users\sina\AppData\Local\Programs\Python\Python313\Lib\site-packages\django_redis\client\default.py", line 260, in get
    raise ConnectionInterrupted(connection=client) from e
django_redis.exceptions.ConnectionInterrupted: Redis ConnectionError: Error 10061 connecting to 127.0.0.1:6379. No connection could be made because the target machine actively refused it.

During handling of the above exception, another exception occurred:

Traceback (most recent call last):
  File "C:\Users\sina\AppData\Local\Programs\Python\Python313\Lib\site-packages\django\core\handlers\exception.py", line 55, in inner
    response = get_response(request)
  File "C:\Users\sina\AppData\Local\Programs\Python\Python313\Lib\site-packages\django\utils\deprecation.py", line 133, in __call__
    response = self.process_request(request)
  File "C:\Users\sina\AppData\Local\Programs\Python\Python313\Lib\site-packages\django\middleware\cache.py", line 158, in process_request
    cache_key = get_cache_key(request, self.key_prefix, "GET", cache=self.cache)
  File "C:\Users\sina\AppData\Local\Programs\Python\Python313\Lib\site-packages\django\utils\cache.py", line 391, in get_cache_key
    headerlist = cache.get(cache_key)
  File "C:\Users\sina\AppData\Local\Programs\Python\Python313\Lib\site-packages\django_redis\cache.py", line 92, in get
    value = self._get(key, default, version, client)
  File "C:\Users\sina\AppData\Local\Programs\Python\Python313\Lib\site-packages\django_redis\cache.py", line 36, in _decorator
    raise e.__cause__
  File "C:\Users\sina\AppData\Local\Programs\Python\Python313\Lib\site-packages\django_redis\client\default.py", line 258, in get
    value = client.get(key)
  File "C:\Users\sina\AppData\Local\Programs\Python\Python313\Lib\site-packages\redis\commands\core.py", line 1821, in get
    return self.execute_command("GET", name)
           ~~~~~~~~~~~~~~~~~~~~^^^^^^^^^^^^^
  File "C:\Users\sina\AppData\Local\Programs\Python\Python313\Lib\site-packages\redis\client.py", line 545, in execute_command
    conn = self.connection or pool.get_connection(command_name, **options)
                              ~~~~~~~~~~~~~~~~~~~^^^^^^^^^^^^^^^^^^^^^^^^^
  File "C:\Users\sina\AppData\Local\Programs\Python\Python313\Lib\site-packages\redis\connection.py", line 1074, in get_connection
    connection.connect()
    ~~~~~~~~~~~~~~~~~~^^
  File "C:\Users\sina\AppData\Local\Programs\Python\Python313\Lib\site-packages\redis\connection.py", line 283, in connect
    raise ConnectionError(self._error_message(e))
redis.exceptions.ConnectionError: Error 10061 connecting to 127.0.0.1:6379. No connection could be made because the target machine actively refused it.
INFO 2025-09-10 16:42:12,656 security_middleware 6600 6824 API_RESPONSE [1c742fb0] - GET /api/courses/courses/ - Status: 500
WARNING 2025-09-10 16:42:12,656 security_middleware 6600 6824 RESPONSE - GET /api/courses/courses/ - Status: 500 - Duration: 2.055s
INFO 2025-09-10 16:42:13,325 security_middleware 6600 6824 REQUEST - GET /api/courses/courses/ - User: Anonymous - IP: 127.0.0.1 - User-Agent: Unknown
INFO 2025-09-10 16:42:13,325 security_middleware 6600 6824 API_REQUEST [6b4db0f8] - GET /api/courses/courses/ - User: Anonymous
ERROR 2025-09-10 16:42:15,356 log 6600 6824 Internal Server Error: /api/courses/courses/
Traceback (most recent call last):
  File "C:\Users\sina\AppData\Local\Programs\Python\Python313\Lib\site-packages\django_redis\cache.py", line 29, in _decorator
    return method(self, *args, **kwargs)
  File "C:\Users\sina\AppData\Local\Programs\Python\Python313\Lib\site-packages\django_redis\cache.py", line 99, in _get
    return self.client.get(key, default=default, version=version, client=client)
           ~~~~~~~~~~~~~~~^^^^^^^^^^^^^^^^^^^^^^^^^^^^^^^^^^^^^^^^^^^^^^^^^^^^^^
  File "C:\Users\sina\AppData\Local\Programs\Python\Python313\Lib\site-packages\django_redis\client\default.py", line 260, in get
    raise ConnectionInterrupted(connection=client) from e
django_redis.exceptions.ConnectionInterrupted: Redis ConnectionError: Error 10061 connecting to 127.0.0.1:6379. No connection could be made because the target machine actively refused it.

During handling of the above exception, another exception occurred:

Traceback (most recent call last):
  File "C:\Users\sina\AppData\Local\Programs\Python\Python313\Lib\site-packages\django\core\handlers\exception.py", line 55, in inner
    response = get_response(request)
  File "C:\Users\sina\AppData\Local\Programs\Python\Python313\Lib\site-packages\django\utils\deprecation.py", line 133, in __call__
    response = self.process_request(request)
  File "C:\Users\sina\AppData\Local\Programs\Python\Python313\Lib\site-packages\django\middleware\cache.py", line 158, in process_request
    cache_key = get_cache_key(request, self.key_prefix, "GET", cache=self.cache)
  File "C:\Users\sina\AppData\Local\Programs\Python\Python313\Lib\site-packages\django\utils\cache.py", line 391, in get_cache_key
    headerlist = cache.get(cache_key)
  File "C:\Users\sina\AppData\Local\Programs\Python\Python313\Lib\site-packages\django_redis\cache.py", line 92, in get
    value = self._get(key, default, version, client)
  File "C:\Users\sina\AppData\Local\Programs\Python\Python313\Lib\site-packages\django_redis\cache.py", line 36, in _decorator
    raise e.__cause__
  File "C:\Users\sina\AppData\Local\Programs\Python\Python313\Lib\site-packages\django_redis\client\default.py", line 258, in get
    value = client.get(key)
  File "C:\Users\sina\AppData\Local\Programs\Python\Python313\Lib\site-packages\redis\commands\core.py", line 1821, in get
    return self.execute_command("GET", name)
           ~~~~~~~~~~~~~~~~~~~~^^^^^^^^^^^^^
  File "C:\Users\sina\AppData\Local\Programs\Python\Python313\Lib\site-packages\redis\client.py", line 545, in execute_command
    conn = self.connection or pool.get_connection(command_name, **options)
                              ~~~~~~~~~~~~~~~~~~~^^^^^^^^^^^^^^^^^^^^^^^^^
  File "C:\Users\sina\AppData\Local\Programs\Python\Python313\Lib\site-packages\redis\connection.py", line 1074, in get_connection
    connection.connect()
    ~~~~~~~~~~~~~~~~~~^^
  File "C:\Users\sina\AppData\Local\Programs\Python\Python313\Lib\site-packages\redis\connection.py", line 283, in connect
    raise ConnectionError(self._error_message(e))
redis.exceptions.ConnectionError: Error 10061 connecting to 127.0.0.1:6379. No connection could be made because the target machine actively refused it.
INFO 2025-09-10 16:42:15,363 security_middleware 6600 6824 API_RESPONSE [6b4db0f8] - GET /api/courses/courses/ - Status: 500
WARNING 2025-09-10 16:42:15,364 security_middleware 6600 6824 RESPONSE - GET /api/courses/courses/ - Status: 500 - Duration: 2.039s
INFO 2025-09-10 16:42:16,014 security_middleware 6600 6824 REQUEST - GET /api/courses/courses/statistics/ - User: Anonymous - IP: 127.0.0.1 - User-Agent: Unknown
INFO 2025-09-10 16:42:16,015 security_middleware 6600 6824 API_REQUEST [ec7af8d5] - GET /api/courses/courses/statistics/ - User: Anonymous
ERROR 2025-09-10 16:42:18,045 log 6600 6824 Internal Server Error: /api/courses/courses/statistics/
Traceback (most recent call last):
  File "C:\Users\sina\AppData\Local\Programs\Python\Python313\Lib\site-packages\django_redis\cache.py", line 29, in _decorator
    return method(self, *args, **kwargs)
  File "C:\Users\sina\AppData\Local\Programs\Python\Python313\Lib\site-packages\django_redis\cache.py", line 99, in _get
    return self.client.get(key, default=default, version=version, client=client)
           ~~~~~~~~~~~~~~~^^^^^^^^^^^^^^^^^^^^^^^^^^^^^^^^^^^^^^^^^^^^^^^^^^^^^^
  File "C:\Users\sina\AppData\Local\Programs\Python\Python313\Lib\site-packages\django_redis\client\default.py", line 260, in get
    raise ConnectionInterrupted(connection=client) from e
django_redis.exceptions.ConnectionInterrupted: Redis ConnectionError: Error 10061 connecting to 127.0.0.1:6379. No connection could be made because the target machine actively refused it.

During handling of the above exception, another exception occurred:

Traceback (most recent call last):
  File "C:\Users\sina\AppData\Local\Programs\Python\Python313\Lib\site-packages\django\core\handlers\exception.py", line 55, in inner
    response = get_response(request)
  File "C:\Users\sina\AppData\Local\Programs\Python\Python313\Lib\site-packages\django\utils\deprecation.py", line 133, in __call__
    response = self.process_request(request)
  File "C:\Users\sina\AppData\Local\Programs\Python\Python313\Lib\site-packages\django\middleware\cache.py", line 158, in process_request
    cache_key = get_cache_key(request, self.key_prefix, "GET", cache=self.cache)
  File "C:\Users\sina\AppData\Local\Programs\Python\Python313\Lib\site-packages\django\utils\cache.py", line 391, in get_cache_key
    headerlist = cache.get(cache_key)
  File "C:\Users\sina\AppData\Local\Programs\Python\Python313\Lib\site-packages\django_redis\cache.py", line 92, in get
    value = self._get(key, default, version, client)
  File "C:\Users\sina\AppData\Local\Programs\Python\Python313\Lib\site-packages\django_redis\cache.py", line 36, in _decorator
    raise e.__cause__
  File "C:\Users\sina\AppData\Local\Programs\Python\Python313\Lib\site-packages\django_redis\client\default.py", line 258, in get
    value = client.get(key)
  File "C:\Users\sina\AppData\Local\Programs\Python\Python313\Lib\site-packages\redis\commands\core.py", line 1821, in get
    return self.execute_command("GET", name)
           ~~~~~~~~~~~~~~~~~~~~^^^^^^^^^^^^^
  File "C:\Users\sina\AppData\Local\Programs\Python\Python313\Lib\site-packages\redis\client.py", line 545, in execute_command
    conn = self.connection or pool.get_connection(command_name, **options)
                              ~~~~~~~~~~~~~~~~~~~^^^^^^^^^^^^^^^^^^^^^^^^^
  File "C:\Users\sina\AppData\Local\Programs\Python\Python313\Lib\site-packages\redis\connection.py", line 1074, in get_connection
    connection.connect()
    ~~~~~~~~~~~~~~~~~~^^
  File "C:\Users\sina\AppData\Local\Programs\Python\Python313\Lib\site-packages\redis\connection.py", line 283, in connect
    raise ConnectionError(self._error_message(e))
redis.exceptions.ConnectionError: Error 10061 connecting to 127.0.0.1:6379. No connection could be made because the target machine actively refused it.
INFO 2025-09-10 16:42:18,049 security_middleware 6600 6824 API_RESPONSE [ec7af8d5] - GET /api/courses/courses/statistics/ - Status: 500
WARNING 2025-09-10 16:42:18,049 security_middleware 6600 6824 RESPONSE - GET /api/courses/courses/statistics/ - Status: 500 - Duration: 2.035s
INFO 2025-09-10 16:42:18,704 security_middleware 6600 6824 REQUEST - POST /api/courses/courses/1/unenroll_student/ - User: Anonymous - IP: 127.0.0.1 - User-Agent: Unknown
INFO 2025-09-10 16:42:18,704 security_middleware 6600 6824 API_REQUEST [d04bf783] - POST /api/courses/courses/1/unenroll_student/ - User: Anonymous
ERROR 2025-09-10 16:42:20,746 log 6600 6824 Internal Server Error: /api/courses/courses/1/unenroll_student/
Traceback (most recent call last):
  File "C:\Users\sina\AppData\Local\Programs\Python\Python313\Lib\site-packages\django_redis\cache.py", line 29, in _decorator
    return method(self, *args, **kwargs)
  File "C:\Users\sina\AppData\Local\Programs\Python\Python313\Lib\site-packages\django_redis\cache.py", line 99, in _get
    return self.client.get(key, default=default, version=version, client=client)
           ~~~~~~~~~~~~~~~^^^^^^^^^^^^^^^^^^^^^^^^^^^^^^^^^^^^^^^^^^^^^^^^^^^^^^
  File "C:\Users\sina\AppData\Local\Programs\Python\Python313\Lib\site-packages\django_redis\client\default.py", line 260, in get
    raise ConnectionInterrupted(connection=client) from e
django_redis.exceptions.ConnectionInterrupted: Redis ConnectionError: Error 10061 connecting to 127.0.0.1:6379. No connection could be made because the target machine actively refused it.

During handling of the above exception, another exception occurred:

Traceback (most recent call last):
  File "C:\Users\sina\AppData\Local\Programs\Python\Python313\Lib\site-packages\django\core\handlers\exception.py", line 55, in inner
    response = get_response(request)
  File "C:\Users\sina\AppData\Local\Programs\Python\Python313\Lib\site-packages\django\core\handlers\base.py", line 197, in _get_response
    response = wrapped_callback(request, *callback_args, **callback_kwargs)
  File "C:\Users\sina\AppData\Local\Programs\Python\Python313\Lib\site-packages\django\views\decorators\csrf.py", line 56, in wrapper_view
    return view_func(*args, **kwargs)
  File "C:\Users\sina\AppData\Local\Programs\Python\Python313\Lib\site-packages\rest_framework\viewsets.py", line 125, in view
    return self.dispatch(request, *args, **kwargs)
           ~~~~~~~~~~~~~^^^^^^^^^^^^^^^^^^^^^^^^^^
  File "C:\Users\sina\AppData\Local\Programs\Python\Python313\Lib\site-packages\rest_framework\views.py", line 509, in dispatch
    response = self.handle_exception(exc)
  File "C:\Users\sina\AppData\Local\Programs\Python\Python313\Lib\site-packages\rest_framework\views.py", line 469, in handle_exception
    self.raise_uncaught_exception(exc)
    ~~~~~~~~~~~~~~~~~~~~~~~~~~~~~^^^^^
  File "C:\Users\sina\AppData\Local\Programs\Python\Python313\Lib\site-packages\rest_framework\views.py", line 480, in raise_uncaught_exception
    raise exc
  File "C:\Users\sina\AppData\Local\Programs\Python\Python313\Lib\site-packages\rest_framework\views.py", line 497, in dispatch
    self.initial(request, *args, **kwargs)
    ~~~~~~~~~~~~^^^^^^^^^^^^^^^^^^^^^^^^^^
  File "C:\Users\sina\AppData\Local\Programs\Python\Python313\Lib\site-packages\rest_framework\views.py", line 416, in initial
    self.check_throttles(request)
    ~~~~~~~~~~~~~~~~~~~~^^^^^^^^^
  File "C:\Users\sina\AppData\Local\Programs\Python\Python313\Lib\site-packages\rest_framework\views.py", line 359, in check_throttles
    if not throttle.allow_request(request, self):
           ~~~~~~~~~~~~~~~~~~~~~~^^^^^^^^^^^^^^^
  File "C:\Users\sina\AppData\Local\Programs\Python\Python313\Lib\site-packages\rest_framework\throttling.py", line 123, in allow_request
    self.history = self.cache.get(self.key, [])
                   ~~~~~~~~~~~~~~^^^^^^^^^^^^^^
  File "C:\Users\sina\AppData\Local\Programs\Python\Python313\Lib\site-packages\django_redis\cache.py", line 92, in get
    value = self._get(key, default, version, client)
  File "C:\Users\sina\AppData\Local\Programs\Python\Python313\Lib\site-packages\django_redis\cache.py", line 36, in _decorator
    raise e.__cause__
  File "C:\Users\sina\AppData\Local\Programs\Python\Python313\Lib\site-packages\django_redis\client\default.py", line 258, in get
    value = client.get(key)
  File "C:\Users\sina\AppData\Local\Programs\Python\Python313\Lib\site-packages\redis\commands\core.py", line 1821, in get
    return self.execute_command("GET", name)
           ~~~~~~~~~~~~~~~~~~~~^^^^^^^^^^^^^
  File "C:\Users\sina\AppData\Local\Programs\Python\Python313\Lib\site-packages\redis\client.py", line 545, in execute_command
    conn = self.connection or pool.get_connection(command_name, **options)
                              ~~~~~~~~~~~~~~~~~~~^^^^^^^^^^^^^^^^^^^^^^^^^
  File "C:\Users\sina\AppData\Local\Programs\Python\Python313\Lib\site-packages\redis\connection.py", line 1074, in get_connection
    connection.connect()
    ~~~~~~~~~~~~~~~~~~^^
  File "C:\Users\sina\AppData\Local\Programs\Python\Python313\Lib\site-packages\redis\connection.py", line 283, in connect
    raise ConnectionError(self._error_message(e))
redis.exceptions.ConnectionError: Error 10061 connecting to 127.0.0.1:6379. No connection could be made because the target machine actively refused it.
INFO 2025-09-10 16:42:20,751 security_middleware 6600 6824 API_RESPONSE [d04bf783] - POST /api/courses/courses/1/unenroll_student/ - Status: 500
WARNING 2025-09-10 16:42:20,752 security_middleware 6600 6824 RESPONSE - POST /api/courses/courses/1/unenroll_student/ - Status: 500 - Duration: 2.048s
INFO 2025-09-10 16:42:21,676 security_middleware 6600 6824 REQUEST - GET /api/courses/courses/ - User: Anonymous - IP: 127.0.0.1 - User-Agent: Unknown
INFO 2025-09-10 16:42:21,677 security_middleware 6600 6824 API_REQUEST [1eaa4e51] - GET /api/courses/courses/ - User: Anonymous
ERROR 2025-09-10 16:42:23,712 log 6600 6824 Internal Server Error: /api/courses/courses/
Traceback (most recent call last):
  File "C:\Users\sina\AppData\Local\Programs\Python\Python313\Lib\site-packages\django_redis\cache.py", line 29, in _decorator
    return method(self, *args, **kwargs)
  File "C:\Users\sina\AppData\Local\Programs\Python\Python313\Lib\site-packages\django_redis\cache.py", line 99, in _get
    return self.client.get(key, default=default, version=version, client=client)
           ~~~~~~~~~~~~~~~^^^^^^^^^^^^^^^^^^^^^^^^^^^^^^^^^^^^^^^^^^^^^^^^^^^^^^
  File "C:\Users\sina\AppData\Local\Programs\Python\Python313\Lib\site-packages\django_redis\client\default.py", line 260, in get
    raise ConnectionInterrupted(connection=client) from e
django_redis.exceptions.ConnectionInterrupted: Redis ConnectionError: Error 10061 connecting to 127.0.0.1:6379. No connection could be made because the target machine actively refused it.

During handling of the above exception, another exception occurred:

Traceback (most recent call last):
  File "C:\Users\sina\AppData\Local\Programs\Python\Python313\Lib\site-packages\django\core\handlers\exception.py", line 55, in inner
    response = get_response(request)
  File "C:\Users\sina\AppData\Local\Programs\Python\Python313\Lib\site-packages\django\utils\deprecation.py", line 133, in __call__
    response = self.process_request(request)
  File "C:\Users\sina\AppData\Local\Programs\Python\Python313\Lib\site-packages\django\middleware\cache.py", line 158, in process_request
    cache_key = get_cache_key(request, self.key_prefix, "GET", cache=self.cache)
  File "C:\Users\sina\AppData\Local\Programs\Python\Python313\Lib\site-packages\django\utils\cache.py", line 391, in get_cache_key
    headerlist = cache.get(cache_key)
  File "C:\Users\sina\AppData\Local\Programs\Python\Python313\Lib\site-packages\django_redis\cache.py", line 92, in get
    value = self._get(key, default, version, client)
  File "C:\Users\sina\AppData\Local\Programs\Python\Python313\Lib\site-packages\django_redis\cache.py", line 36, in _decorator
    raise e.__cause__
  File "C:\Users\sina\AppData\Local\Programs\Python\Python313\Lib\site-packages\django_redis\client\default.py", line 258, in get
    value = client.get(key)
  File "C:\Users\sina\AppData\Local\Programs\Python\Python313\Lib\site-packages\redis\commands\core.py", line 1821, in get
    return self.execute_command("GET", name)
           ~~~~~~~~~~~~~~~~~~~~^^^^^^^^^^^^^
  File "C:\Users\sina\AppData\Local\Programs\Python\Python313\Lib\site-packages\redis\client.py", line 545, in execute_command
    conn = self.connection or pool.get_connection(command_name, **options)
                              ~~~~~~~~~~~~~~~~~~~^^^^^^^^^^^^^^^^^^^^^^^^^
  File "C:\Users\sina\AppData\Local\Programs\Python\Python313\Lib\site-packages\redis\connection.py", line 1074, in get_connection
    connection.connect()
    ~~~~~~~~~~~~~~~~~~^^
  File "C:\Users\sina\AppData\Local\Programs\Python\Python313\Lib\site-packages\redis\connection.py", line 283, in connect
    raise ConnectionError(self._error_message(e))
redis.exceptions.ConnectionError: Error 10061 connecting to 127.0.0.1:6379. No connection could be made because the target machine actively refused it.
INFO 2025-09-10 16:42:23,715 security_middleware 6600 6824 API_RESPONSE [1eaa4e51] - GET /api/courses/courses/ - Status: 500
WARNING 2025-09-10 16:42:23,715 security_middleware 6600 6824 RESPONSE - GET /api/courses/courses/ - Status: 500 - Duration: 2.038s
INFO 2025-09-10 16:42:24,383 security_middleware 6600 6824 REQUEST - GET /api/courses/courses/ - User: Anonymous - IP: 127.0.0.1 - User-Agent: Unknown
INFO 2025-09-10 16:42:24,383 security_middleware 6600 6824 API_REQUEST [7bf7f75c] - GET /api/courses/courses/ - User: Anonymous
ERROR 2025-09-10 16:42:26,426 log 6600 6824 Internal Server Error: /api/courses/courses/
Traceback (most recent call last):
  File "C:\Users\sina\AppData\Local\Programs\Python\Python313\Lib\site-packages\django_redis\cache.py", line 29, in _decorator
    return method(self, *args, **kwargs)
  File "C:\Users\sina\AppData\Local\Programs\Python\Python313\Lib\site-packages\django_redis\cache.py", line 99, in _get
    return self.client.get(key, default=default, version=version, client=client)
           ~~~~~~~~~~~~~~~^^^^^^^^^^^^^^^^^^^^^^^^^^^^^^^^^^^^^^^^^^^^^^^^^^^^^^
  File "C:\Users\sina\AppData\Local\Programs\Python\Python313\Lib\site-packages\django_redis\client\default.py", line 260, in get
    raise ConnectionInterrupted(connection=client) from e
django_redis.exceptions.ConnectionInterrupted: Redis ConnectionError: Error 10061 connecting to 127.0.0.1:6379. No connection could be made because the target machine actively refused it.

During handling of the above exception, another exception occurred:

Traceback (most recent call last):
  File "C:\Users\sina\AppData\Local\Programs\Python\Python313\Lib\site-packages\django\core\handlers\exception.py", line 55, in inner
    response = get_response(request)
  File "C:\Users\sina\AppData\Local\Programs\Python\Python313\Lib\site-packages\django\utils\deprecation.py", line 133, in __call__
    response = self.process_request(request)
  File "C:\Users\sina\AppData\Local\Programs\Python\Python313\Lib\site-packages\django\middleware\cache.py", line 158, in process_request
    cache_key = get_cache_key(request, self.key_prefix, "GET", cache=self.cache)
  File "C:\Users\sina\AppData\Local\Programs\Python\Python313\Lib\site-packages\django\utils\cache.py", line 391, in get_cache_key
    headerlist = cache.get(cache_key)
  File "C:\Users\sina\AppData\Local\Programs\Python\Python313\Lib\site-packages\django_redis\cache.py", line 92, in get
    value = self._get(key, default, version, client)
  File "C:\Users\sina\AppData\Local\Programs\Python\Python313\Lib\site-packages\django_redis\cache.py", line 36, in _decorator
    raise e.__cause__
  File "C:\Users\sina\AppData\Local\Programs\Python\Python313\Lib\site-packages\django_redis\client\default.py", line 258, in get
    value = client.get(key)
  File "C:\Users\sina\AppData\Local\Programs\Python\Python313\Lib\site-packages\redis\commands\core.py", line 1821, in get
    return self.execute_command("GET", name)
           ~~~~~~~~~~~~~~~~~~~~^^^^^^^^^^^^^
  File "C:\Users\sina\AppData\Local\Programs\Python\Python313\Lib\site-packages\redis\client.py", line 545, in execute_command
    conn = self.connection or pool.get_connection(command_name, **options)
                              ~~~~~~~~~~~~~~~~~~~^^^^^^^^^^^^^^^^^^^^^^^^^
  File "C:\Users\sina\AppData\Local\Programs\Python\Python313\Lib\site-packages\redis\connection.py", line 1074, in get_connection
    connection.connect()
    ~~~~~~~~~~~~~~~~~~^^
  File "C:\Users\sina\AppData\Local\Programs\Python\Python313\Lib\site-packages\redis\connection.py", line 283, in connect
    raise ConnectionError(self._error_message(e))
redis.exceptions.ConnectionError: Error 10061 connecting to 127.0.0.1:6379. No connection could be made because the target machine actively refused it.
INFO 2025-09-10 16:42:26,429 security_middleware 6600 6824 API_RESPONSE [7bf7f75c] - GET /api/courses/courses/ - Status: 500
WARNING 2025-09-10 16:42:26,430 security_middleware 6600 6824 RESPONSE - GET /api/courses/courses/ - Status: 500 - Duration: 2.047s
INFO 2025-09-10 16:42:27,463 security_middleware 6600 6824 REQUEST - POST /api/courses/courses/ - User: Anonymous - IP: 127.0.0.1 - User-Agent: Unknown
INFO 2025-09-10 16:42:27,464 security_middleware 6600 6824 API_REQUEST [c89dcc38] - POST /api/courses/courses/ - User: Anonymous
ERROR 2025-09-10 16:42:29,490 log 6600 6824 Internal Server Error: /api/courses/courses/
Traceback (most recent call last):
  File "C:\Users\sina\AppData\Local\Programs\Python\Python313\Lib\site-packages\django_redis\cache.py", line 29, in _decorator
    return method(self, *args, **kwargs)
  File "C:\Users\sina\AppData\Local\Programs\Python\Python313\Lib\site-packages\django_redis\cache.py", line 99, in _get
    return self.client.get(key, default=default, version=version, client=client)
           ~~~~~~~~~~~~~~~^^^^^^^^^^^^^^^^^^^^^^^^^^^^^^^^^^^^^^^^^^^^^^^^^^^^^^
  File "C:\Users\sina\AppData\Local\Programs\Python\Python313\Lib\site-packages\django_redis\client\default.py", line 260, in get
    raise ConnectionInterrupted(connection=client) from e
django_redis.exceptions.ConnectionInterrupted: Redis ConnectionError: Error 10061 connecting to 127.0.0.1:6379. No connection could be made because the target machine actively refused it.

During handling of the above exception, another exception occurred:

Traceback (most recent call last):
  File "C:\Users\sina\AppData\Local\Programs\Python\Python313\Lib\site-packages\django\core\handlers\exception.py", line 55, in inner
    response = get_response(request)
  File "C:\Users\sina\AppData\Local\Programs\Python\Python313\Lib\site-packages\django\core\handlers\base.py", line 197, in _get_response
    response = wrapped_callback(request, *callback_args, **callback_kwargs)
  File "C:\Users\sina\AppData\Local\Programs\Python\Python313\Lib\site-packages\django\views\decorators\csrf.py", line 56, in wrapper_view
    return view_func(*args, **kwargs)
  File "C:\Users\sina\AppData\Local\Programs\Python\Python313\Lib\site-packages\rest_framework\viewsets.py", line 125, in view
    return self.dispatch(request, *args, **kwargs)
           ~~~~~~~~~~~~~^^^^^^^^^^^^^^^^^^^^^^^^^^
  File "C:\Users\sina\AppData\Local\Programs\Python\Python313\Lib\site-packages\rest_framework\views.py", line 509, in dispatch
    response = self.handle_exception(exc)
  File "C:\Users\sina\AppData\Local\Programs\Python\Python313\Lib\site-packages\rest_framework\views.py", line 469, in handle_exception
    self.raise_uncaught_exception(exc)
    ~~~~~~~~~~~~~~~~~~~~~~~~~~~~~^^^^^
  File "C:\Users\sina\AppData\Local\Programs\Python\Python313\Lib\site-packages\rest_framework\views.py", line 480, in raise_uncaught_exception
    raise exc
  File "C:\Users\sina\AppData\Local\Programs\Python\Python313\Lib\site-packages\rest_framework\views.py", line 497, in dispatch
    self.initial(request, *args, **kwargs)
    ~~~~~~~~~~~~^^^^^^^^^^^^^^^^^^^^^^^^^^
  File "C:\Users\sina\AppData\Local\Programs\Python\Python313\Lib\site-packages\rest_framework\views.py", line 416, in initial
    self.check_throttles(request)
    ~~~~~~~~~~~~~~~~~~~~^^^^^^^^^
  File "C:\Users\sina\AppData\Local\Programs\Python\Python313\Lib\site-packages\rest_framework\views.py", line 359, in check_throttles
    if not throttle.allow_request(request, self):
           ~~~~~~~~~~~~~~~~~~~~~~^^^^^^^^^^^^^^^
  File "C:\Users\sina\AppData\Local\Programs\Python\Python313\Lib\site-packages\rest_framework\throttling.py", line 123, in allow_request
    self.history = self.cache.get(self.key, [])
                   ~~~~~~~~~~~~~~^^^^^^^^^^^^^^
  File "C:\Users\sina\AppData\Local\Programs\Python\Python313\Lib\site-packages\django_redis\cache.py", line 92, in get
    value = self._get(key, default, version, client)
  File "C:\Users\sina\AppData\Local\Programs\Python\Python313\Lib\site-packages\django_redis\cache.py", line 36, in _decorator
    raise e.__cause__
  File "C:\Users\sina\AppData\Local\Programs\Python\Python313\Lib\site-packages\django_redis\client\default.py", line 258, in get
    value = client.get(key)
  File "C:\Users\sina\AppData\Local\Programs\Python\Python313\Lib\site-packages\redis\commands\core.py", line 1821, in get
    return self.execute_command("GET", name)
           ~~~~~~~~~~~~~~~~~~~~^^^^^^^^^^^^^
  File "C:\Users\sina\AppData\Local\Programs\Python\Python313\Lib\site-packages\redis\client.py", line 545, in execute_command
    conn = self.connection or pool.get_connection(command_name, **options)
                              ~~~~~~~~~~~~~~~~~~~^^^^^^^^^^^^^^^^^^^^^^^^^
  File "C:\Users\sina\AppData\Local\Programs\Python\Python313\Lib\site-packages\redis\connection.py", line 1074, in get_connection
    connection.connect()
    ~~~~~~~~~~~~~~~~~~^^
  File "C:\Users\sina\AppData\Local\Programs\Python\Python313\Lib\site-packages\redis\connection.py", line 283, in connect
    raise ConnectionError(self._error_message(e))
redis.exceptions.ConnectionError: Error 10061 connecting to 127.0.0.1:6379. No connection could be made because the target machine actively refused it.
INFO 2025-09-10 16:42:29,495 security_middleware 6600 6824 API_RESPONSE [c89dcc38] - POST /api/courses/courses/ - Status: 500
WARNING 2025-09-10 16:42:29,495 security_middleware 6600 6824 RESPONSE - POST /api/courses/courses/ - Status: 500 - Duration: 2.032s
INFO 2025-09-10 16:42:29,887 security_middleware 6600 6824 REQUEST - POST /api/courses/courses/ - User: Anonymous - IP: 127.0.0.1 - User-Agent: Unknown
INFO 2025-09-10 16:42:29,888 security_middleware 6600 6824 API_REQUEST [083d93e1] - POST /api/courses/courses/ - User: Anonymous
ERROR 2025-09-10 16:42:31,913 log 6600 6824 Internal Server Error: /api/courses/courses/
Traceback (most recent call last):
  File "C:\Users\sina\AppData\Local\Programs\Python\Python313\Lib\site-packages\django_redis\cache.py", line 29, in _decorator
    return method(self, *args, **kwargs)
  File "C:\Users\sina\AppData\Local\Programs\Python\Python313\Lib\site-packages\django_redis\cache.py", line 99, in _get
    return self.client.get(key, default=default, version=version, client=client)
           ~~~~~~~~~~~~~~~^^^^^^^^^^^^^^^^^^^^^^^^^^^^^^^^^^^^^^^^^^^^^^^^^^^^^^
  File "C:\Users\sina\AppData\Local\Programs\Python\Python313\Lib\site-packages\django_redis\client\default.py", line 260, in get
    raise ConnectionInterrupted(connection=client) from e
django_redis.exceptions.ConnectionInterrupted: Redis ConnectionError: Error 10061 connecting to 127.0.0.1:6379. No connection could be made because the target machine actively refused it.

During handling of the above exception, another exception occurred:

Traceback (most recent call last):
  File "C:\Users\sina\AppData\Local\Programs\Python\Python313\Lib\site-packages\django\core\handlers\exception.py", line 55, in inner
    response = get_response(request)
  File "C:\Users\sina\AppData\Local\Programs\Python\Python313\Lib\site-packages\django\core\handlers\base.py", line 197, in _get_response
    response = wrapped_callback(request, *callback_args, **callback_kwargs)
  File "C:\Users\sina\AppData\Local\Programs\Python\Python313\Lib\site-packages\django\views\decorators\csrf.py", line 56, in wrapper_view
    return view_func(*args, **kwargs)
  File "C:\Users\sina\AppData\Local\Programs\Python\Python313\Lib\site-packages\rest_framework\viewsets.py", line 125, in view
    return self.dispatch(request, *args, **kwargs)
           ~~~~~~~~~~~~~^^^^^^^^^^^^^^^^^^^^^^^^^^
  File "C:\Users\sina\AppData\Local\Programs\Python\Python313\Lib\site-packages\rest_framework\views.py", line 509, in dispatch
    response = self.handle_exception(exc)
  File "C:\Users\sina\AppData\Local\Programs\Python\Python313\Lib\site-packages\rest_framework\views.py", line 469, in handle_exception
    self.raise_uncaught_exception(exc)
    ~~~~~~~~~~~~~~~~~~~~~~~~~~~~~^^^^^
  File "C:\Users\sina\AppData\Local\Programs\Python\Python313\Lib\site-packages\rest_framework\views.py", line 480, in raise_uncaught_exception
    raise exc
  File "C:\Users\sina\AppData\Local\Programs\Python\Python313\Lib\site-packages\rest_framework\views.py", line 497, in dispatch
    self.initial(request, *args, **kwargs)
    ~~~~~~~~~~~~^^^^^^^^^^^^^^^^^^^^^^^^^^
  File "C:\Users\sina\AppData\Local\Programs\Python\Python313\Lib\site-packages\rest_framework\views.py", line 416, in initial
    self.check_throttles(request)
    ~~~~~~~~~~~~~~~~~~~~^^^^^^^^^
  File "C:\Users\sina\AppData\Local\Programs\Python\Python313\Lib\site-packages\rest_framework\views.py", line 359, in check_throttles
    if not throttle.allow_request(request, self):
           ~~~~~~~~~~~~~~~~~~~~~~^^^^^^^^^^^^^^^
  File "C:\Users\sina\AppData\Local\Programs\Python\Python313\Lib\site-packages\rest_framework\throttling.py", line 123, in allow_request
    self.history = self.cache.get(self.key, [])
                   ~~~~~~~~~~~~~~^^^^^^^^^^^^^^
  File "C:\Users\sina\AppData\Local\Programs\Python\Python313\Lib\site-packages\django_redis\cache.py", line 92, in get
    value = self._get(key, default, version, client)
  File "C:\Users\sina\AppData\Local\Programs\Python\Python313\Lib\site-packages\django_redis\cache.py", line 36, in _decorator
    raise e.__cause__
  File "C:\Users\sina\AppData\Local\Programs\Python\Python313\Lib\site-packages\django_redis\client\default.py", line 258, in get
    value = client.get(key)
  File "C:\Users\sina\AppData\Local\Programs\Python\Python313\Lib\site-packages\redis\commands\core.py", line 1821, in get
    return self.execute_command("GET", name)
           ~~~~~~~~~~~~~~~~~~~~^^^^^^^^^^^^^
  File "C:\Users\sina\AppData\Local\Programs\Python\Python313\Lib\site-packages\redis\client.py", line 545, in execute_command
    conn = self.connection or pool.get_connection(command_name, **options)
                              ~~~~~~~~~~~~~~~~~~~^^^^^^^^^^^^^^^^^^^^^^^^^
  File "C:\Users\sina\AppData\Local\Programs\Python\Python313\Lib\site-packages\redis\connection.py", line 1074, in get_connection
    connection.connect()
    ~~~~~~~~~~~~~~~~~~^^
  File "C:\Users\sina\AppData\Local\Programs\Python\Python313\Lib\site-packages\redis\connection.py", line 283, in connect
    raise ConnectionError(self._error_message(e))
redis.exceptions.ConnectionError: Error 10061 connecting to 127.0.0.1:6379. No connection could be made because the target machine actively refused it.
INFO 2025-09-10 16:42:31,918 security_middleware 6600 6824 API_RESPONSE [083d93e1] - POST /api/courses/courses/ - Status: 500
WARNING 2025-09-10 16:42:31,918 security_middleware 6600 6824 RESPONSE - POST /api/courses/courses/ - Status: 500 - Duration: 2.031s
INFO 2025-09-10 16:42:32,592 security_middleware 6600 6824 REQUEST - POST /api/courses/courses/ - User: Anonymous - IP: 127.0.0.1 - User-Agent: Unknown
INFO 2025-09-10 16:42:32,592 security_middleware 6600 6824 API_REQUEST [4a88dfc7] - POST /api/courses/courses/ - User: Anonymous
ERROR 2025-09-10 16:42:34,614 log 6600 6824 Internal Server Error: /api/courses/courses/
Traceback (most recent call last):
  File "C:\Users\sina\AppData\Local\Programs\Python\Python313\Lib\site-packages\django_redis\cache.py", line 29, in _decorator
    return method(self, *args, **kwargs)
  File "C:\Users\sina\AppData\Local\Programs\Python\Python313\Lib\site-packages\django_redis\cache.py", line 99, in _get
    return self.client.get(key, default=default, version=version, client=client)
           ~~~~~~~~~~~~~~~^^^^^^^^^^^^^^^^^^^^^^^^^^^^^^^^^^^^^^^^^^^^^^^^^^^^^^
  File "C:\Users\sina\AppData\Local\Programs\Python\Python313\Lib\site-packages\django_redis\client\default.py", line 260, in get
    raise ConnectionInterrupted(connection=client) from e
django_redis.exceptions.ConnectionInterrupted: Redis ConnectionError: Error 10061 connecting to 127.0.0.1:6379. No connection could be made because the target machine actively refused it.

During handling of the above exception, another exception occurred:

Traceback (most recent call last):
  File "C:\Users\sina\AppData\Local\Programs\Python\Python313\Lib\site-packages\django\core\handlers\exception.py", line 55, in inner
    response = get_response(request)
  File "C:\Users\sina\AppData\Local\Programs\Python\Python313\Lib\site-packages\django\core\handlers\base.py", line 197, in _get_response
    response = wrapped_callback(request, *callback_args, **callback_kwargs)
  File "C:\Users\sina\AppData\Local\Programs\Python\Python313\Lib\site-packages\django\views\decorators\csrf.py", line 56, in wrapper_view
    return view_func(*args, **kwargs)
  File "C:\Users\sina\AppData\Local\Programs\Python\Python313\Lib\site-packages\rest_framework\viewsets.py", line 125, in view
    return self.dispatch(request, *args, **kwargs)
           ~~~~~~~~~~~~~^^^^^^^^^^^^^^^^^^^^^^^^^^
  File "C:\Users\sina\AppData\Local\Programs\Python\Python313\Lib\site-packages\rest_framework\views.py", line 509, in dispatch
    response = self.handle_exception(exc)
  File "C:\Users\sina\AppData\Local\Programs\Python\Python313\Lib\site-packages\rest_framework\views.py", line 469, in handle_exception
    self.raise_uncaught_exception(exc)
    ~~~~~~~~~~~~~~~~~~~~~~~~~~~~~^^^^^
  File "C:\Users\sina\AppData\Local\Programs\Python\Python313\Lib\site-packages\rest_framework\views.py", line 480, in raise_uncaught_exception
    raise exc
  File "C:\Users\sina\AppData\Local\Programs\Python\Python313\Lib\site-packages\rest_framework\views.py", line 497, in dispatch
    self.initial(request, *args, **kwargs)
    ~~~~~~~~~~~~^^^^^^^^^^^^^^^^^^^^^^^^^^
  File "C:\Users\sina\AppData\Local\Programs\Python\Python313\Lib\site-packages\rest_framework\views.py", line 416, in initial
    self.check_throttles(request)
    ~~~~~~~~~~~~~~~~~~~~^^^^^^^^^
  File "C:\Users\sina\AppData\Local\Programs\Python\Python313\Lib\site-packages\rest_framework\views.py", line 359, in check_throttles
    if not throttle.allow_request(request, self):
           ~~~~~~~~~~~~~~~~~~~~~~^^^^^^^^^^^^^^^
  File "C:\Users\sina\AppData\Local\Programs\Python\Python313\Lib\site-packages\rest_framework\throttling.py", line 123, in allow_request
    self.history = self.cache.get(self.key, [])
                   ~~~~~~~~~~~~~~^^^^^^^^^^^^^^
  File "C:\Users\sina\AppData\Local\Programs\Python\Python313\Lib\site-packages\django_redis\cache.py", line 92, in get
    value = self._get(key, default, version, client)
  File "C:\Users\sina\AppData\Local\Programs\Python\Python313\Lib\site-packages\django_redis\cache.py", line 36, in _decorator
    raise e.__cause__
  File "C:\Users\sina\AppData\Local\Programs\Python\Python313\Lib\site-packages\django_redis\client\default.py", line 258, in get
    value = client.get(key)
  File "C:\Users\sina\AppData\Local\Programs\Python\Python313\Lib\site-packages\redis\commands\core.py", line 1821, in get
    return self.execute_command("GET", name)
           ~~~~~~~~~~~~~~~~~~~~^^^^^^^^^^^^^
  File "C:\Users\sina\AppData\Local\Programs\Python\Python313\Lib\site-packages\redis\client.py", line 545, in execute_command
    conn = self.connection or pool.get_connection(command_name, **options)
                              ~~~~~~~~~~~~~~~~~~~^^^^^^^^^^^^^^^^^^^^^^^^^
  File "C:\Users\sina\AppData\Local\Programs\Python\Python313\Lib\site-packages\redis\connection.py", line 1074, in get_connection
    connection.connect()
    ~~~~~~~~~~~~~~~~~~^^
  File "C:\Users\sina\AppData\Local\Programs\Python\Python313\Lib\site-packages\redis\connection.py", line 283, in connect
    raise ConnectionError(self._error_message(e))
redis.exceptions.ConnectionError: Error 10061 connecting to 127.0.0.1:6379. No connection could be made because the target machine actively refused it.
INFO 2025-09-10 16:42:34,619 security_middleware 6600 6824 API_RESPONSE [4a88dfc7] - POST /api/courses/courses/ - Status: 500
WARNING 2025-09-10 16:42:34,619 security_middleware 6600 6824 RESPONSE - POST /api/courses/courses/ - Status: 500 - Duration: 2.027s
INFO 2025-09-10 16:43:14,849 autoreload 20336 20136 D:\project\uni\backend\apps\courses\models.py changed, reloading.
INFO 2025-09-10 16:43:15,556 autoreload 20860 21108 Watching for file changes with StatReloader
INFO 2025-09-10 16:46:02,770 autoreload 20860 21108 D:\project\uni\backend\apps\courses\views.py changed, reloading.
INFO 2025-09-10 16:46:03,635 autoreload 13400 4172 Watching for file changes with StatReloader
INFO 2025-09-10 16:48:13,586 autoreload 13400 4172 D:\project\uni\backend\config\settings.py changed, reloading.
INFO 2025-09-10 16:48:14,269 autoreload 19724 9512 Watching for file changes with StatReloader
INFO 2025-09-10 16:48:40,708 autoreload 19724 9512 D:\project\uni\backend\config\settings.py changed, reloading.
INFO 2025-09-10 16:48:41,380 autoreload 20364 18012 Watching for file changes with StatReloader
INFO 2025-09-10 16:49:16,055 autoreload 20364 18012 D:\project\uni\backend\config\settings.py changed, reloading.
INFO 2025-09-10 16:49:16,727 autoreload 3588 13404 Watching for file changes with StatReloader
INFO 2025-09-10 16:49:51,416 autoreload 3588 13404 D:\project\uni\backend\config\urls.py changed, reloading.
INFO 2025-09-10 16:49:52,127 autoreload 11156 10900 Watching for file changes with StatReloader
INFO 2025-09-10 16:50:48,714 autoreload 11156 10900 D:\project\uni\backend\config\settings.py changed, reloading.
INFO 2025-09-10 16:50:49,445 autoreload 2092 18904 Watching for file changes with StatReloader
INFO 2025-09-10 16:51:50,011 autoreload 2092 18904 D:\project\uni\backend\config\settings.py changed, reloading.
INFO 2025-09-10 16:51:50,734 autoreload 21148 21128 Watching for file changes with StatReloader
INFO 2025-09-10 16:52:09,948 autoreload 21148 21128 D:\project\uni\backend\apps\courses\views.py changed, reloading.
INFO 2025-09-10 16:52:10,653 autoreload 20404 13500 Watching for file changes with StatReloader
INFO 2025-09-10 16:52:21,640 autoreload 20404 13500 D:\project\uni\backend\apps\courses\views.py changed, reloading.
INFO 2025-09-10 16:52:22,330 autoreload 20136 10216 Watching for file changes with StatReloader
INFO 2025-09-10 16:52:37,451 autoreload 20136 10216 D:\project\uni\backend\apps\courses\views.py changed, reloading.
INFO 2025-09-10 16:52:38,131 autoreload 7244 21020 Watching for file changes with StatReloader
INFO 2025-09-10 16:52:49,089 autoreload 7244 21020 D:\project\uni\backend\apps\courses\views.py changed, reloading.
INFO 2025-09-10 16:52:49,824 autoreload 20080 12684 Watching for file changes with StatReloader
INFO 2025-09-10 16:53:10,093 autoreload 20080 12684 D:\project\uni\backend\apps\courses\views.py changed, reloading.
INFO 2025-09-10 16:53:10,765 autoreload 5188 3276 Watching for file changes with StatReloader
INFO 2025-09-10 16:53:30,018 autoreload 5188 3276 D:\project\uni\backend\apps\courses\views.py changed, reloading.
INFO 2025-09-10 16:53:30,735 autoreload 18444 21272 Watching for file changes with StatReloader
INFO 2025-09-10 16:53:49,970 autoreload 18444 21272 D:\project\uni\backend\apps\courses\views.py changed, reloading.
INFO 2025-09-10 16:53:50,612 autoreload 19616 15404 Watching for file changes with StatReloader
INFO 2025-09-10 16:54:04,754 autoreload 19616 15404 D:\project\uni\backend\config\error_handling.py changed, reloading.
INFO 2025-09-10 16:54:05,516 autoreload 18744 15744 Watching for file changes with StatReloader
INFO 2025-09-10 16:54:48,028 autoreload 6824 20228 Watching for file changes with StatReloader
INFO 2025-09-10 16:55:30,984 security_middleware 18744 17264 REQUEST - GET /api/docs/ - User: Anonymous - IP: 127.0.0.1 - User-Agent: Mozilla/5.0 (Windows NT 10.0; Win64; x64) AppleWebKit/537.36 (KHTML, like Gecko) Code/1.103.2 Chrome/138.0.7204.100 Electron/37.2.3 Safari/537.36
INFO 2025-09-10 16:55:30,984 security_middleware 18744 17264 API_REQUEST [1169063c] - GET /api/docs/ - User: Anonymous
ERROR 2025-09-10 16:55:33,057 log 18744 17264 Internal Server Error: /api/docs/
Traceback (most recent call last):
  File "C:\Users\sina\AppData\Local\Programs\Python\Python313\Lib\site-packages\django_redis\cache.py", line 29, in _decorator
    return method(self, *args, **kwargs)
  File "C:\Users\sina\AppData\Local\Programs\Python\Python313\Lib\site-packages\django_redis\cache.py", line 99, in _get
    return self.client.get(key, default=default, version=version, client=client)
           ~~~~~~~~~~~~~~~^^^^^^^^^^^^^^^^^^^^^^^^^^^^^^^^^^^^^^^^^^^^^^^^^^^^^^
  File "C:\Users\sina\AppData\Local\Programs\Python\Python313\Lib\site-packages\django_redis\client\default.py", line 260, in get
    raise ConnectionInterrupted(connection=client) from e
django_redis.exceptions.ConnectionInterrupted: Redis ConnectionError: Error 10061 connecting to 127.0.0.1:6379. No connection could be made because the target machine actively refused it.

During handling of the above exception, another exception occurred:

Traceback (most recent call last):
  File "C:\Users\sina\AppData\Local\Programs\Python\Python313\Lib\site-packages\django\core\handlers\exception.py", line 55, in inner
    response = get_response(request)
  File "C:\Users\sina\AppData\Local\Programs\Python\Python313\Lib\site-packages\django\utils\deprecation.py", line 133, in __call__
    response = self.process_request(request)
  File "C:\Users\sina\AppData\Local\Programs\Python\Python313\Lib\site-packages\django\middleware\cache.py", line 158, in process_request
    cache_key = get_cache_key(request, self.key_prefix, "GET", cache=self.cache)
  File "C:\Users\sina\AppData\Local\Programs\Python\Python313\Lib\site-packages\django\utils\cache.py", line 391, in get_cache_key
    headerlist = cache.get(cache_key)
  File "C:\Users\sina\AppData\Local\Programs\Python\Python313\Lib\site-packages\django_redis\cache.py", line 92, in get
    value = self._get(key, default, version, client)
  File "C:\Users\sina\AppData\Local\Programs\Python\Python313\Lib\site-packages\django_redis\cache.py", line 36, in _decorator
    raise e.__cause__
  File "C:\Users\sina\AppData\Local\Programs\Python\Python313\Lib\site-packages\django_redis\client\default.py", line 258, in get
    value = client.get(key)
  File "C:\Users\sina\AppData\Local\Programs\Python\Python313\Lib\site-packages\redis\commands\core.py", line 1821, in get
    return self.execute_command("GET", name)
           ~~~~~~~~~~~~~~~~~~~~^^^^^^^^^^^^^
  File "C:\Users\sina\AppData\Local\Programs\Python\Python313\Lib\site-packages\redis\client.py", line 545, in execute_command
    conn = self.connection or pool.get_connection(command_name, **options)
                              ~~~~~~~~~~~~~~~~~~~^^^^^^^^^^^^^^^^^^^^^^^^^
  File "C:\Users\sina\AppData\Local\Programs\Python\Python313\Lib\site-packages\redis\connection.py", line 1074, in get_connection
    connection.connect()
    ~~~~~~~~~~~~~~~~~~^^
  File "C:\Users\sina\AppData\Local\Programs\Python\Python313\Lib\site-packages\redis\connection.py", line 283, in connect
    raise ConnectionError(self._error_message(e))
redis.exceptions.ConnectionError: Error 10061 connecting to 127.0.0.1:6379. No connection could be made because the target machine actively refused it.
INFO 2025-09-10 16:55:33,062 security_middleware 18744 17264 API_RESPONSE [1169063c] - GET /api/docs/ - Status: 500
WARNING 2025-09-10 16:55:33,062 security_middleware 18744 17264 RESPONSE - GET /api/docs/ - Status: 500 - Duration: 2.078s
ERROR 2025-09-10 16:55:33,062 basehttp 18744 17264 "GET /api/docs/?id=7eda25ab-688e-4790-acbd-62584a55e741&vscodeBrowserReqId=1757510730978 HTTP/1.1" 500 134825
INFO 2025-09-10 16:55:45,138 security_middleware 18744 17264 REQUEST - GET /api/docs/ - User: Anonymous - IP: 127.0.0.1 - User-Agent: Mozilla/5.0 (Windows NT 10.0; Win64; x64) AppleWebKit/537.36 (KHTML, like Gecko) Code/1.103.2 Chrome/138.0.7204.100 Electron/37.2.3 Safari/537.36
INFO 2025-09-10 16:55:45,139 security_middleware 18744 17264 API_REQUEST [95f60f7f] - GET /api/docs/ - User: Anonymous
ERROR 2025-09-10 16:55:47,199 log 18744 17264 Internal Server Error: /api/docs/
Traceback (most recent call last):
  File "C:\Users\sina\AppData\Local\Programs\Python\Python313\Lib\site-packages\django_redis\cache.py", line 29, in _decorator
    return method(self, *args, **kwargs)
  File "C:\Users\sina\AppData\Local\Programs\Python\Python313\Lib\site-packages\django_redis\cache.py", line 99, in _get
    return self.client.get(key, default=default, version=version, client=client)
           ~~~~~~~~~~~~~~~^^^^^^^^^^^^^^^^^^^^^^^^^^^^^^^^^^^^^^^^^^^^^^^^^^^^^^
  File "C:\Users\sina\AppData\Local\Programs\Python\Python313\Lib\site-packages\django_redis\client\default.py", line 260, in get
    raise ConnectionInterrupted(connection=client) from e
django_redis.exceptions.ConnectionInterrupted: Redis ConnectionError: Error 10061 connecting to 127.0.0.1:6379. No connection could be made because the target machine actively refused it.

During handling of the above exception, another exception occurred:

Traceback (most recent call last):
  File "C:\Users\sina\AppData\Local\Programs\Python\Python313\Lib\site-packages\django\core\handlers\exception.py", line 55, in inner
    response = get_response(request)
  File "C:\Users\sina\AppData\Local\Programs\Python\Python313\Lib\site-packages\django\utils\deprecation.py", line 133, in __call__
    response = self.process_request(request)
  File "C:\Users\sina\AppData\Local\Programs\Python\Python313\Lib\site-packages\django\middleware\cache.py", line 158, in process_request
    cache_key = get_cache_key(request, self.key_prefix, "GET", cache=self.cache)
  File "C:\Users\sina\AppData\Local\Programs\Python\Python313\Lib\site-packages\django\utils\cache.py", line 391, in get_cache_key
    headerlist = cache.get(cache_key)
  File "C:\Users\sina\AppData\Local\Programs\Python\Python313\Lib\site-packages\django_redis\cache.py", line 92, in get
    value = self._get(key, default, version, client)
  File "C:\Users\sina\AppData\Local\Programs\Python\Python313\Lib\site-packages\django_redis\cache.py", line 36, in _decorator
    raise e.__cause__
  File "C:\Users\sina\AppData\Local\Programs\Python\Python313\Lib\site-packages\django_redis\client\default.py", line 258, in get
    value = client.get(key)
  File "C:\Users\sina\AppData\Local\Programs\Python\Python313\Lib\site-packages\redis\commands\core.py", line 1821, in get
    return self.execute_command("GET", name)
           ~~~~~~~~~~~~~~~~~~~~^^^^^^^^^^^^^
  File "C:\Users\sina\AppData\Local\Programs\Python\Python313\Lib\site-packages\redis\client.py", line 545, in execute_command
    conn = self.connection or pool.get_connection(command_name, **options)
                              ~~~~~~~~~~~~~~~~~~~^^^^^^^^^^^^^^^^^^^^^^^^^
  File "C:\Users\sina\AppData\Local\Programs\Python\Python313\Lib\site-packages\redis\connection.py", line 1074, in get_connection
    connection.connect()
    ~~~~~~~~~~~~~~~~~~^^
  File "C:\Users\sina\AppData\Local\Programs\Python\Python313\Lib\site-packages\redis\connection.py", line 283, in connect
    raise ConnectionError(self._error_message(e))
redis.exceptions.ConnectionError: Error 10061 connecting to 127.0.0.1:6379. No connection could be made because the target machine actively refused it.
INFO 2025-09-10 16:55:47,202 security_middleware 18744 17264 API_RESPONSE [95f60f7f] - GET /api/docs/ - Status: 500
WARNING 2025-09-10 16:55:47,202 security_middleware 18744 17264 RESPONSE - GET /api/docs/ - Status: 500 - Duration: 2.064s
ERROR 2025-09-10 16:55:47,202 basehttp 18744 17264 "GET /api/docs/?id=7eda25ab-688e-4790-acbd-62584a55e741&vscodeBrowserReqId=1757510745134 HTTP/1.1" 500 134825
INFO 2025-09-10 16:58:01,666 autoreload 18744 15744 D:\project\uni\backend\config\settings.py changed, reloading.
INFO 2025-09-10 16:58:02,483 autoreload 16900 19708 Watching for file changes with StatReloader
INFO 2025-09-10 16:58:36,157 security_middleware 16900 8596 REQUEST - GET /api/redoc/ - User: Anonymous - IP: 127.0.0.1 - User-Agent: Mozilla/5.0 (Windows NT 10.0; Win64; x64) AppleWebKit/537.36 (KHTML, like Gecko) Code/1.103.2 Chrome/138.0.7204.100 Electron/37.2.3 Safari/537.36
INFO 2025-09-10 16:58:36,158 security_middleware 16900 8596 API_REQUEST [62ec469b] - GET /api/redoc/ - User: Anonymous
ERROR 2025-09-10 16:58:38,227 log 16900 8596 Internal Server Error: /api/redoc/
Traceback (most recent call last):
  File "C:\Users\sina\AppData\Local\Programs\Python\Python313\Lib\site-packages\django_redis\cache.py", line 29, in _decorator
    return method(self, *args, **kwargs)
  File "C:\Users\sina\AppData\Local\Programs\Python\Python313\Lib\site-packages\django_redis\cache.py", line 99, in _get
    return self.client.get(key, default=default, version=version, client=client)
           ~~~~~~~~~~~~~~~^^^^^^^^^^^^^^^^^^^^^^^^^^^^^^^^^^^^^^^^^^^^^^^^^^^^^^
  File "C:\Users\sina\AppData\Local\Programs\Python\Python313\Lib\site-packages\django_redis\client\default.py", line 260, in get
    raise ConnectionInterrupted(connection=client) from e
django_redis.exceptions.ConnectionInterrupted: Redis ConnectionError: Error 10061 connecting to 127.0.0.1:6379. No connection could be made because the target machine actively refused it.

During handling of the above exception, another exception occurred:

Traceback (most recent call last):
  File "C:\Users\sina\AppData\Local\Programs\Python\Python313\Lib\site-packages\django\core\handlers\exception.py", line 55, in inner
    response = get_response(request)
  File "C:\Users\sina\AppData\Local\Programs\Python\Python313\Lib\site-packages\django\utils\deprecation.py", line 133, in __call__
    response = self.process_request(request)
  File "C:\Users\sina\AppData\Local\Programs\Python\Python313\Lib\site-packages\django\middleware\cache.py", line 158, in process_request
    cache_key = get_cache_key(request, self.key_prefix, "GET", cache=self.cache)
  File "C:\Users\sina\AppData\Local\Programs\Python\Python313\Lib\site-packages\django\utils\cache.py", line 391, in get_cache_key
    headerlist = cache.get(cache_key)
  File "C:\Users\sina\AppData\Local\Programs\Python\Python313\Lib\site-packages\django_redis\cache.py", line 92, in get
    value = self._get(key, default, version, client)
  File "C:\Users\sina\AppData\Local\Programs\Python\Python313\Lib\site-packages\django_redis\cache.py", line 36, in _decorator
    raise e.__cause__
  File "C:\Users\sina\AppData\Local\Programs\Python\Python313\Lib\site-packages\django_redis\client\default.py", line 258, in get
    value = client.get(key)
  File "C:\Users\sina\AppData\Local\Programs\Python\Python313\Lib\site-packages\redis\commands\core.py", line 1821, in get
    return self.execute_command("GET", name)
           ~~~~~~~~~~~~~~~~~~~~^^^^^^^^^^^^^
  File "C:\Users\sina\AppData\Local\Programs\Python\Python313\Lib\site-packages\redis\client.py", line 545, in execute_command
    conn = self.connection or pool.get_connection(command_name, **options)
                              ~~~~~~~~~~~~~~~~~~~^^^^^^^^^^^^^^^^^^^^^^^^^
  File "C:\Users\sina\AppData\Local\Programs\Python\Python313\Lib\site-packages\redis\connection.py", line 1074, in get_connection
    connection.connect()
    ~~~~~~~~~~~~~~~~~~^^
  File "C:\Users\sina\AppData\Local\Programs\Python\Python313\Lib\site-packages\redis\connection.py", line 283, in connect
    raise ConnectionError(self._error_message(e))
redis.exceptions.ConnectionError: Error 10061 connecting to 127.0.0.1:6379. No connection could be made because the target machine actively refused it.
INFO 2025-09-10 16:58:38,232 security_middleware 16900 8596 API_RESPONSE [62ec469b] - GET /api/redoc/ - Status: 500
WARNING 2025-09-10 16:58:38,232 security_middleware 16900 8596 RESPONSE - GET /api/redoc/ - Status: 500 - Duration: 2.075s
ERROR 2025-09-10 16:58:38,233 basehttp 16900 8596 "GET /api/redoc/?id=7eda25ab-688e-4790-acbd-62584a55e741&vscodeBrowserReqId=1757510916152 HTTP/1.1" 500 130823
INFO 2025-09-10 17:00:50,079 autoreload 16900 19708 D:\project\uni\backend\config\urls.py changed, reloading.
INFO 2025-09-10 17:00:50,720 autoreload 5744 20976 Watching for file changes with StatReloader
INFO 2025-09-10 17:01:26,323 autoreload 5744 20976 D:\project\uni\backend\config\settings.py changed, reloading.
INFO 2025-09-10 17:01:26,997 autoreload 14752 14944 Watching for file changes with StatReloader
INFO 2025-09-10 17:04:55,174 autoreload 17784 20176 Watching for file changes with StatReloader
INFO 2025-09-10 17:05:12,134 autoreload 16128 1144 Watching for file changes with StatReloader
INFO 2025-09-10 17:05:16,730 security_middleware 16128 15424 REQUEST - GET /api/health/ - User: Anonymous - IP: 127.0.0.1 - User-Agent: python-requests/2.32.4
INFO 2025-09-10 17:05:16,730 security_middleware 16128 15424 API_REQUEST [ad18ea26] - GET /api/health/ - User: Anonymous
ERROR 2025-09-10 17:05:18,810 log 16128 15424 Internal Server Error: /api/health/
Traceback (most recent call last):
  File "C:\Users\sina\AppData\Local\Programs\Python\Python313\Lib\site-packages\django_redis\cache.py", line 29, in _decorator
    return method(self, *args, **kwargs)
  File "C:\Users\sina\AppData\Local\Programs\Python\Python313\Lib\site-packages\django_redis\cache.py", line 99, in _get
    return self.client.get(key, default=default, version=version, client=client)
           ~~~~~~~~~~~~~~~^^^^^^^^^^^^^^^^^^^^^^^^^^^^^^^^^^^^^^^^^^^^^^^^^^^^^^
  File "C:\Users\sina\AppData\Local\Programs\Python\Python313\Lib\site-packages\django_redis\client\default.py", line 260, in get
    raise ConnectionInterrupted(connection=client) from e
django_redis.exceptions.ConnectionInterrupted: Redis ConnectionError: Error 10061 connecting to 127.0.0.1:6379. No connection could be made because the target machine actively refused it.

During handling of the above exception, another exception occurred:

Traceback (most recent call last):
  File "C:\Users\sina\AppData\Local\Programs\Python\Python313\Lib\site-packages\django\core\handlers\exception.py", line 55, in inner
    response = get_response(request)
  File "C:\Users\sina\AppData\Local\Programs\Python\Python313\Lib\site-packages\django\utils\deprecation.py", line 133, in __call__
    response = self.process_request(request)
  File "C:\Users\sina\AppData\Local\Programs\Python\Python313\Lib\site-packages\django\middleware\cache.py", line 158, in process_request
    cache_key = get_cache_key(request, self.key_prefix, "GET", cache=self.cache)
  File "C:\Users\sina\AppData\Local\Programs\Python\Python313\Lib\site-packages\django\utils\cache.py", line 391, in get_cache_key
    headerlist = cache.get(cache_key)
  File "C:\Users\sina\AppData\Local\Programs\Python\Python313\Lib\site-packages\django_redis\cache.py", line 92, in get
    value = self._get(key, default, version, client)
  File "C:\Users\sina\AppData\Local\Programs\Python\Python313\Lib\site-packages\django_redis\cache.py", line 36, in _decorator
    raise e.__cause__
  File "C:\Users\sina\AppData\Local\Programs\Python\Python313\Lib\site-packages\django_redis\client\default.py", line 258, in get
    value = client.get(key)
  File "C:\Users\sina\AppData\Local\Programs\Python\Python313\Lib\site-packages\redis\commands\core.py", line 1821, in get
    return self.execute_command("GET", name)
           ~~~~~~~~~~~~~~~~~~~~^^^^^^^^^^^^^
  File "C:\Users\sina\AppData\Local\Programs\Python\Python313\Lib\site-packages\redis\client.py", line 545, in execute_command
    conn = self.connection or pool.get_connection(command_name, **options)
                              ~~~~~~~~~~~~~~~~~~~^^^^^^^^^^^^^^^^^^^^^^^^^
  File "C:\Users\sina\AppData\Local\Programs\Python\Python313\Lib\site-packages\redis\connection.py", line 1074, in get_connection
    connection.connect()
    ~~~~~~~~~~~~~~~~~~^^
  File "C:\Users\sina\AppData\Local\Programs\Python\Python313\Lib\site-packages\redis\connection.py", line 283, in connect
    raise ConnectionError(self._error_message(e))
redis.exceptions.ConnectionError: Error 10061 connecting to 127.0.0.1:6379. No connection could be made because the target machine actively refused it.
INFO 2025-09-10 17:05:18,814 security_middleware 16128 15424 API_RESPONSE [ad18ea26] - GET /api/health/ - Status: 500
WARNING 2025-09-10 17:05:18,815 security_middleware 16128 15424 RESPONSE - GET /api/health/ - Status: 500 - Duration: 2.085s
WARNING 2025-09-10 17:05:18,815 monitoring 16128 15424 Slow request: GET /api/health/ took 2085.14ms
ERROR 2025-09-10 17:05:18,815 basehttp 16128 15424 "GET /api/health/ HTTP/1.1" 500 128294
INFO 2025-09-10 17:05:18,818 security_middleware 16128 15424 REQUEST - GET /api/status/ - User: Anonymous - IP: 127.0.0.1 - User-Agent: python-requests/2.32.4
INFO 2025-09-10 17:05:18,818 security_middleware 16128 15424 API_REQUEST [1669c771] - GET /api/status/ - User: Anonymous
ERROR 2025-09-10 17:05:20,873 log 16128 15424 Internal Server Error: /api/status/
Traceback (most recent call last):
  File "C:\Users\sina\AppData\Local\Programs\Python\Python313\Lib\site-packages\django_redis\cache.py", line 29, in _decorator
    return method(self, *args, **kwargs)
  File "C:\Users\sina\AppData\Local\Programs\Python\Python313\Lib\site-packages\django_redis\cache.py", line 99, in _get
    return self.client.get(key, default=default, version=version, client=client)
           ~~~~~~~~~~~~~~~^^^^^^^^^^^^^^^^^^^^^^^^^^^^^^^^^^^^^^^^^^^^^^^^^^^^^^
  File "C:\Users\sina\AppData\Local\Programs\Python\Python313\Lib\site-packages\django_redis\client\default.py", line 260, in get
    raise ConnectionInterrupted(connection=client) from e
django_redis.exceptions.ConnectionInterrupted: Redis ConnectionError: Error 10061 connecting to 127.0.0.1:6379. No connection could be made because the target machine actively refused it.

During handling of the above exception, another exception occurred:

Traceback (most recent call last):
  File "C:\Users\sina\AppData\Local\Programs\Python\Python313\Lib\site-packages\django\core\handlers\exception.py", line 55, in inner
    response = get_response(request)
  File "C:\Users\sina\AppData\Local\Programs\Python\Python313\Lib\site-packages\django\utils\deprecation.py", line 133, in __call__
    response = self.process_request(request)
  File "C:\Users\sina\AppData\Local\Programs\Python\Python313\Lib\site-packages\django\middleware\cache.py", line 158, in process_request
    cache_key = get_cache_key(request, self.key_prefix, "GET", cache=self.cache)
  File "C:\Users\sina\AppData\Local\Programs\Python\Python313\Lib\site-packages\django\utils\cache.py", line 391, in get_cache_key
    headerlist = cache.get(cache_key)
  File "C:\Users\sina\AppData\Local\Programs\Python\Python313\Lib\site-packages\django_redis\cache.py", line 92, in get
    value = self._get(key, default, version, client)
  File "C:\Users\sina\AppData\Local\Programs\Python\Python313\Lib\site-packages\django_redis\cache.py", line 36, in _decorator
    raise e.__cause__
  File "C:\Users\sina\AppData\Local\Programs\Python\Python313\Lib\site-packages\django_redis\client\default.py", line 258, in get
    value = client.get(key)
  File "C:\Users\sina\AppData\Local\Programs\Python\Python313\Lib\site-packages\redis\commands\core.py", line 1821, in get
    return self.execute_command("GET", name)
           ~~~~~~~~~~~~~~~~~~~~^^^^^^^^^^^^^
  File "C:\Users\sina\AppData\Local\Programs\Python\Python313\Lib\site-packages\redis\client.py", line 545, in execute_command
    conn = self.connection or pool.get_connection(command_name, **options)
                              ~~~~~~~~~~~~~~~~~~~^^^^^^^^^^^^^^^^^^^^^^^^^
  File "C:\Users\sina\AppData\Local\Programs\Python\Python313\Lib\site-packages\redis\connection.py", line 1074, in get_connection
    connection.connect()
    ~~~~~~~~~~~~~~~~~~^^
  File "C:\Users\sina\AppData\Local\Programs\Python\Python313\Lib\site-packages\redis\connection.py", line 283, in connect
    raise ConnectionError(self._error_message(e))
redis.exceptions.ConnectionError: Error 10061 connecting to 127.0.0.1:6379. No connection could be made because the target machine actively refused it.
INFO 2025-09-10 17:05:20,876 security_middleware 16128 15424 API_RESPONSE [1669c771] - GET /api/status/ - Status: 500
WARNING 2025-09-10 17:05:20,876 security_middleware 16128 15424 RESPONSE - GET /api/status/ - Status: 500 - Duration: 2.058s
WARNING 2025-09-10 17:05:20,876 monitoring 16128 15424 Slow request: GET /api/status/ took 2058.06ms
ERROR 2025-09-10 17:05:20,876 basehttp 16128 15424 "GET /api/status/ HTTP/1.1" 500 128289
INFO 2025-09-10 17:05:20,877 security_middleware 16128 15424 REQUEST - GET /api/info/ - User: Anonymous - IP: 127.0.0.1 - User-Agent: python-requests/2.32.4
INFO 2025-09-10 17:05:20,878 security_middleware 16128 15424 API_REQUEST [46ea143d] - GET /api/info/ - User: Anonymous
ERROR 2025-09-10 17:05:22,914 log 16128 15424 Internal Server Error: /api/info/
Traceback (most recent call last):
  File "C:\Users\sina\AppData\Local\Programs\Python\Python313\Lib\site-packages\django_redis\cache.py", line 29, in _decorator
    return method(self, *args, **kwargs)
  File "C:\Users\sina\AppData\Local\Programs\Python\Python313\Lib\site-packages\django_redis\cache.py", line 99, in _get
    return self.client.get(key, default=default, version=version, client=client)
           ~~~~~~~~~~~~~~~^^^^^^^^^^^^^^^^^^^^^^^^^^^^^^^^^^^^^^^^^^^^^^^^^^^^^^
  File "C:\Users\sina\AppData\Local\Programs\Python\Python313\Lib\site-packages\django_redis\client\default.py", line 260, in get
    raise ConnectionInterrupted(connection=client) from e
django_redis.exceptions.ConnectionInterrupted: Redis ConnectionError: Error 10061 connecting to 127.0.0.1:6379. No connection could be made because the target machine actively refused it.

During handling of the above exception, another exception occurred:

Traceback (most recent call last):
  File "C:\Users\sina\AppData\Local\Programs\Python\Python313\Lib\site-packages\django\core\handlers\exception.py", line 55, in inner
    response = get_response(request)
  File "C:\Users\sina\AppData\Local\Programs\Python\Python313\Lib\site-packages\django\utils\deprecation.py", line 133, in __call__
    response = self.process_request(request)
  File "C:\Users\sina\AppData\Local\Programs\Python\Python313\Lib\site-packages\django\middleware\cache.py", line 158, in process_request
    cache_key = get_cache_key(request, self.key_prefix, "GET", cache=self.cache)
  File "C:\Users\sina\AppData\Local\Programs\Python\Python313\Lib\site-packages\django\utils\cache.py", line 391, in get_cache_key
    headerlist = cache.get(cache_key)
  File "C:\Users\sina\AppData\Local\Programs\Python\Python313\Lib\site-packages\django_redis\cache.py", line 92, in get
    value = self._get(key, default, version, client)
  File "C:\Users\sina\AppData\Local\Programs\Python\Python313\Lib\site-packages\django_redis\cache.py", line 36, in _decorator
    raise e.__cause__
  File "C:\Users\sina\AppData\Local\Programs\Python\Python313\Lib\site-packages\django_redis\client\default.py", line 258, in get
    value = client.get(key)
  File "C:\Users\sina\AppData\Local\Programs\Python\Python313\Lib\site-packages\redis\commands\core.py", line 1821, in get
    return self.execute_command("GET", name)
           ~~~~~~~~~~~~~~~~~~~~^^^^^^^^^^^^^
  File "C:\Users\sina\AppData\Local\Programs\Python\Python313\Lib\site-packages\redis\client.py", line 545, in execute_command
    conn = self.connection or pool.get_connection(command_name, **options)
                              ~~~~~~~~~~~~~~~~~~~^^^^^^^^^^^^^^^^^^^^^^^^^
  File "C:\Users\sina\AppData\Local\Programs\Python\Python313\Lib\site-packages\redis\connection.py", line 1074, in get_connection
    connection.connect()
    ~~~~~~~~~~~~~~~~~~^^
  File "C:\Users\sina\AppData\Local\Programs\Python\Python313\Lib\site-packages\redis\connection.py", line 283, in connect
    raise ConnectionError(self._error_message(e))
redis.exceptions.ConnectionError: Error 10061 connecting to 127.0.0.1:6379. No connection could be made because the target machine actively refused it.
INFO 2025-09-10 17:05:22,917 security_middleware 16128 15424 API_RESPONSE [46ea143d] - GET /api/info/ - Status: 500
WARNING 2025-09-10 17:05:22,917 security_middleware 16128 15424 RESPONSE - GET /api/info/ - Status: 500 - Duration: 2.040s
WARNING 2025-09-10 17:05:22,917 monitoring 16128 15424 Slow request: GET /api/info/ took 2039.93ms
ERROR 2025-09-10 17:05:22,918 basehttp 16128 15424 "GET /api/info/ HTTP/1.1" 500 128271
INFO 2025-09-10 17:05:22,920 security_middleware 16128 15424 REQUEST - GET /api/version/ - User: Anonymous - IP: 127.0.0.1 - User-Agent: python-requests/2.32.4
INFO 2025-09-10 17:05:22,920 security_middleware 16128 15424 API_REQUEST [b986bb27] - GET /api/version/ - User: Anonymous
ERROR 2025-09-10 17:05:24,966 log 16128 15424 Internal Server Error: /api/version/
Traceback (most recent call last):
  File "C:\Users\sina\AppData\Local\Programs\Python\Python313\Lib\site-packages\django_redis\cache.py", line 29, in _decorator
    return method(self, *args, **kwargs)
  File "C:\Users\sina\AppData\Local\Programs\Python\Python313\Lib\site-packages\django_redis\cache.py", line 99, in _get
    return self.client.get(key, default=default, version=version, client=client)
           ~~~~~~~~~~~~~~~^^^^^^^^^^^^^^^^^^^^^^^^^^^^^^^^^^^^^^^^^^^^^^^^^^^^^^
  File "C:\Users\sina\AppData\Local\Programs\Python\Python313\Lib\site-packages\django_redis\client\default.py", line 260, in get
    raise ConnectionInterrupted(connection=client) from e
django_redis.exceptions.ConnectionInterrupted: Redis ConnectionError: Error 10061 connecting to 127.0.0.1:6379. No connection could be made because the target machine actively refused it.

During handling of the above exception, another exception occurred:

Traceback (most recent call last):
  File "C:\Users\sina\AppData\Local\Programs\Python\Python313\Lib\site-packages\django\core\handlers\exception.py", line 55, in inner
    response = get_response(request)
  File "C:\Users\sina\AppData\Local\Programs\Python\Python313\Lib\site-packages\django\utils\deprecation.py", line 133, in __call__
    response = self.process_request(request)
  File "C:\Users\sina\AppData\Local\Programs\Python\Python313\Lib\site-packages\django\middleware\cache.py", line 158, in process_request
    cache_key = get_cache_key(request, self.key_prefix, "GET", cache=self.cache)
  File "C:\Users\sina\AppData\Local\Programs\Python\Python313\Lib\site-packages\django\utils\cache.py", line 391, in get_cache_key
    headerlist = cache.get(cache_key)
  File "C:\Users\sina\AppData\Local\Programs\Python\Python313\Lib\site-packages\django_redis\cache.py", line 92, in get
    value = self._get(key, default, version, client)
  File "C:\Users\sina\AppData\Local\Programs\Python\Python313\Lib\site-packages\django_redis\cache.py", line 36, in _decorator
    raise e.__cause__
  File "C:\Users\sina\AppData\Local\Programs\Python\Python313\Lib\site-packages\django_redis\client\default.py", line 258, in get
    value = client.get(key)
  File "C:\Users\sina\AppData\Local\Programs\Python\Python313\Lib\site-packages\redis\commands\core.py", line 1821, in get
    return self.execute_command("GET", name)
           ~~~~~~~~~~~~~~~~~~~~^^^^^^^^^^^^^
  File "C:\Users\sina\AppData\Local\Programs\Python\Python313\Lib\site-packages\redis\client.py", line 545, in execute_command
    conn = self.connection or pool.get_connection(command_name, **options)
                              ~~~~~~~~~~~~~~~~~~~^^^^^^^^^^^^^^^^^^^^^^^^^
  File "C:\Users\sina\AppData\Local\Programs\Python\Python313\Lib\site-packages\redis\connection.py", line 1074, in get_connection
    connection.connect()
    ~~~~~~~~~~~~~~~~~~^^
  File "C:\Users\sina\AppData\Local\Programs\Python\Python313\Lib\site-packages\redis\connection.py", line 283, in connect
    raise ConnectionError(self._error_message(e))
redis.exceptions.ConnectionError: Error 10061 connecting to 127.0.0.1:6379. No connection could be made because the target machine actively refused it.
INFO 2025-09-10 17:05:24,968 security_middleware 16128 15424 API_RESPONSE [b986bb27] - GET /api/version/ - Status: 500
WARNING 2025-09-10 17:05:24,969 security_middleware 16128 15424 RESPONSE - GET /api/version/ - Status: 500 - Duration: 2.049s
WARNING 2025-09-10 17:05:24,969 monitoring 16128 15424 Slow request: GET /api/version/ took 2049.51ms
ERROR 2025-09-10 17:05:24,970 basehttp 16128 15424 "GET /api/version/ HTTP/1.1" 500 128304
INFO 2025-09-10 17:05:24,972 security_middleware 16128 15424 REQUEST - GET /api/docs/ - User: Anonymous - IP: 127.0.0.1 - User-Agent: python-requests/2.32.4
INFO 2025-09-10 17:05:24,972 security_middleware 16128 15424 API_REQUEST [260a519c] - GET /api/docs/ - User: Anonymous
ERROR 2025-09-10 17:05:27,014 log 16128 15424 Internal Server Error: /api/docs/
Traceback (most recent call last):
  File "C:\Users\sina\AppData\Local\Programs\Python\Python313\Lib\site-packages\django_redis\cache.py", line 29, in _decorator
    return method(self, *args, **kwargs)
  File "C:\Users\sina\AppData\Local\Programs\Python\Python313\Lib\site-packages\django_redis\cache.py", line 99, in _get
    return self.client.get(key, default=default, version=version, client=client)
           ~~~~~~~~~~~~~~~^^^^^^^^^^^^^^^^^^^^^^^^^^^^^^^^^^^^^^^^^^^^^^^^^^^^^^
  File "C:\Users\sina\AppData\Local\Programs\Python\Python313\Lib\site-packages\django_redis\client\default.py", line 260, in get
    raise ConnectionInterrupted(connection=client) from e
django_redis.exceptions.ConnectionInterrupted: Redis ConnectionError: Error 10061 connecting to 127.0.0.1:6379. No connection could be made because the target machine actively refused it.

During handling of the above exception, another exception occurred:

Traceback (most recent call last):
  File "C:\Users\sina\AppData\Local\Programs\Python\Python313\Lib\site-packages\django\core\handlers\exception.py", line 55, in inner
    response = get_response(request)
  File "C:\Users\sina\AppData\Local\Programs\Python\Python313\Lib\site-packages\django\utils\deprecation.py", line 133, in __call__
    response = self.process_request(request)
  File "C:\Users\sina\AppData\Local\Programs\Python\Python313\Lib\site-packages\django\middleware\cache.py", line 158, in process_request
    cache_key = get_cache_key(request, self.key_prefix, "GET", cache=self.cache)
  File "C:\Users\sina\AppData\Local\Programs\Python\Python313\Lib\site-packages\django\utils\cache.py", line 391, in get_cache_key
    headerlist = cache.get(cache_key)
  File "C:\Users\sina\AppData\Local\Programs\Python\Python313\Lib\site-packages\django_redis\cache.py", line 92, in get
    value = self._get(key, default, version, client)
  File "C:\Users\sina\AppData\Local\Programs\Python\Python313\Lib\site-packages\django_redis\cache.py", line 36, in _decorator
    raise e.__cause__
  File "C:\Users\sina\AppData\Local\Programs\Python\Python313\Lib\site-packages\django_redis\client\default.py", line 258, in get
    value = client.get(key)
  File "C:\Users\sina\AppData\Local\Programs\Python\Python313\Lib\site-packages\redis\commands\core.py", line 1821, in get
    return self.execute_command("GET", name)
           ~~~~~~~~~~~~~~~~~~~~^^^^^^^^^^^^^
  File "C:\Users\sina\AppData\Local\Programs\Python\Python313\Lib\site-packages\redis\client.py", line 545, in execute_command
    conn = self.connection or pool.get_connection(command_name, **options)
                              ~~~~~~~~~~~~~~~~~~~^^^^^^^^^^^^^^^^^^^^^^^^^
  File "C:\Users\sina\AppData\Local\Programs\Python\Python313\Lib\site-packages\redis\connection.py", line 1074, in get_connection
    connection.connect()
    ~~~~~~~~~~~~~~~~~~^^
  File "C:\Users\sina\AppData\Local\Programs\Python\Python313\Lib\site-packages\redis\connection.py", line 283, in connect
    raise ConnectionError(self._error_message(e))
redis.exceptions.ConnectionError: Error 10061 connecting to 127.0.0.1:6379. No connection could be made because the target machine actively refused it.
INFO 2025-09-10 17:05:27,017 security_middleware 16128 15424 API_RESPONSE [260a519c] - GET /api/docs/ - Status: 500
WARNING 2025-09-10 17:05:27,017 security_middleware 16128 15424 RESPONSE - GET /api/docs/ - Status: 500 - Duration: 2.045s
WARNING 2025-09-10 17:05:27,017 monitoring 16128 15424 Slow request: GET /api/docs/ took 2045.24ms
ERROR 2025-09-10 17:05:27,017 basehttp 16128 15424 "GET /api/docs/ HTTP/1.1" 500 128283
INFO 2025-09-10 17:05:27,019 security_middleware 16128 15424 REQUEST - GET /api/redoc/ - User: Anonymous - IP: 127.0.0.1 - User-Agent: python-requests/2.32.4
INFO 2025-09-10 17:05:27,020 security_middleware 16128 15424 API_REQUEST [b7d9baa2] - GET /api/redoc/ - User: Anonymous
ERROR 2025-09-10 17:05:29,081 log 16128 15424 Internal Server Error: /api/redoc/
Traceback (most recent call last):
  File "C:\Users\sina\AppData\Local\Programs\Python\Python313\Lib\site-packages\django_redis\cache.py", line 29, in _decorator
    return method(self, *args, **kwargs)
  File "C:\Users\sina\AppData\Local\Programs\Python\Python313\Lib\site-packages\django_redis\cache.py", line 99, in _get
    return self.client.get(key, default=default, version=version, client=client)
           ~~~~~~~~~~~~~~~^^^^^^^^^^^^^^^^^^^^^^^^^^^^^^^^^^^^^^^^^^^^^^^^^^^^^^
  File "C:\Users\sina\AppData\Local\Programs\Python\Python313\Lib\site-packages\django_redis\client\default.py", line 260, in get
    raise ConnectionInterrupted(connection=client) from e
django_redis.exceptions.ConnectionInterrupted: Redis ConnectionError: Error 10061 connecting to 127.0.0.1:6379. No connection could be made because the target machine actively refused it.

During handling of the above exception, another exception occurred:

Traceback (most recent call last):
  File "C:\Users\sina\AppData\Local\Programs\Python\Python313\Lib\site-packages\django\core\handlers\exception.py", line 55, in inner
    response = get_response(request)
  File "C:\Users\sina\AppData\Local\Programs\Python\Python313\Lib\site-packages\django\utils\deprecation.py", line 133, in __call__
    response = self.process_request(request)
  File "C:\Users\sina\AppData\Local\Programs\Python\Python313\Lib\site-packages\django\middleware\cache.py", line 158, in process_request
    cache_key = get_cache_key(request, self.key_prefix, "GET", cache=self.cache)
  File "C:\Users\sina\AppData\Local\Programs\Python\Python313\Lib\site-packages\django\utils\cache.py", line 391, in get_cache_key
    headerlist = cache.get(cache_key)
  File "C:\Users\sina\AppData\Local\Programs\Python\Python313\Lib\site-packages\django_redis\cache.py", line 92, in get
    value = self._get(key, default, version, client)
  File "C:\Users\sina\AppData\Local\Programs\Python\Python313\Lib\site-packages\django_redis\cache.py", line 36, in _decorator
    raise e.__cause__
  File "C:\Users\sina\AppData\Local\Programs\Python\Python313\Lib\site-packages\django_redis\client\default.py", line 258, in get
    value = client.get(key)
  File "C:\Users\sina\AppData\Local\Programs\Python\Python313\Lib\site-packages\redis\commands\core.py", line 1821, in get
    return self.execute_command("GET", name)
           ~~~~~~~~~~~~~~~~~~~~^^^^^^^^^^^^^
  File "C:\Users\sina\AppData\Local\Programs\Python\Python313\Lib\site-packages\redis\client.py", line 545, in execute_command
    conn = self.connection or pool.get_connection(command_name, **options)
                              ~~~~~~~~~~~~~~~~~~~^^^^^^^^^^^^^^^^^^^^^^^^^
  File "C:\Users\sina\AppData\Local\Programs\Python\Python313\Lib\site-packages\redis\connection.py", line 1074, in get_connection
    connection.connect()
    ~~~~~~~~~~~~~~~~~~^^
  File "C:\Users\sina\AppData\Local\Programs\Python\Python313\Lib\site-packages\redis\connection.py", line 283, in connect
    raise ConnectionError(self._error_message(e))
redis.exceptions.ConnectionError: Error 10061 connecting to 127.0.0.1:6379. No connection could be made because the target machine actively refused it.
INFO 2025-09-10 17:05:29,084 security_middleware 16128 15424 API_RESPONSE [b7d9baa2] - GET /api/redoc/ - Status: 500
WARNING 2025-09-10 17:05:29,084 security_middleware 16128 15424 RESPONSE - GET /api/redoc/ - Status: 500 - Duration: 2.065s
WARNING 2025-09-10 17:05:29,085 monitoring 16128 15424 Slow request: GET /api/redoc/ took 2065.10ms
ERROR 2025-09-10 17:05:29,085 basehttp 16128 15424 "GET /api/redoc/ HTTP/1.1" 500 128292
INFO 2025-09-10 17:05:29,088 security_middleware 16128 15424 REQUEST - GET /api/schema/ - User: Anonymous - IP: 127.0.0.1 - User-Agent: python-requests/2.32.4
INFO 2025-09-10 17:05:29,088 security_middleware 16128 15424 API_REQUEST [113b2b9f] - GET /api/schema/ - User: Anonymous
ERROR 2025-09-10 17:05:31,140 log 16128 15424 Internal Server Error: /api/schema/
Traceback (most recent call last):
  File "C:\Users\sina\AppData\Local\Programs\Python\Python313\Lib\site-packages\django_redis\cache.py", line 29, in _decorator
    return method(self, *args, **kwargs)
  File "C:\Users\sina\AppData\Local\Programs\Python\Python313\Lib\site-packages\django_redis\cache.py", line 99, in _get
    return self.client.get(key, default=default, version=version, client=client)
           ~~~~~~~~~~~~~~~^^^^^^^^^^^^^^^^^^^^^^^^^^^^^^^^^^^^^^^^^^^^^^^^^^^^^^
  File "C:\Users\sina\AppData\Local\Programs\Python\Python313\Lib\site-packages\django_redis\client\default.py", line 260, in get
    raise ConnectionInterrupted(connection=client) from e
django_redis.exceptions.ConnectionInterrupted: Redis ConnectionError: Error 10061 connecting to 127.0.0.1:6379. No connection could be made because the target machine actively refused it.

During handling of the above exception, another exception occurred:

Traceback (most recent call last):
  File "C:\Users\sina\AppData\Local\Programs\Python\Python313\Lib\site-packages\django\core\handlers\exception.py", line 55, in inner
    response = get_response(request)
  File "C:\Users\sina\AppData\Local\Programs\Python\Python313\Lib\site-packages\django\utils\deprecation.py", line 133, in __call__
    response = self.process_request(request)
  File "C:\Users\sina\AppData\Local\Programs\Python\Python313\Lib\site-packages\django\middleware\cache.py", line 158, in process_request
    cache_key = get_cache_key(request, self.key_prefix, "GET", cache=self.cache)
  File "C:\Users\sina\AppData\Local\Programs\Python\Python313\Lib\site-packages\django\utils\cache.py", line 391, in get_cache_key
    headerlist = cache.get(cache_key)
  File "C:\Users\sina\AppData\Local\Programs\Python\Python313\Lib\site-packages\django_redis\cache.py", line 92, in get
    value = self._get(key, default, version, client)
  File "C:\Users\sina\AppData\Local\Programs\Python\Python313\Lib\site-packages\django_redis\cache.py", line 36, in _decorator
    raise e.__cause__
  File "C:\Users\sina\AppData\Local\Programs\Python\Python313\Lib\site-packages\django_redis\client\default.py", line 258, in get
    value = client.get(key)
  File "C:\Users\sina\AppData\Local\Programs\Python\Python313\Lib\site-packages\redis\commands\core.py", line 1821, in get
    return self.execute_command("GET", name)
           ~~~~~~~~~~~~~~~~~~~~^^^^^^^^^^^^^
  File "C:\Users\sina\AppData\Local\Programs\Python\Python313\Lib\site-packages\redis\client.py", line 545, in execute_command
    conn = self.connection or pool.get_connection(command_name, **options)
                              ~~~~~~~~~~~~~~~~~~~^^^^^^^^^^^^^^^^^^^^^^^^^
  File "C:\Users\sina\AppData\Local\Programs\Python\Python313\Lib\site-packages\redis\connection.py", line 1074, in get_connection
    connection.connect()
    ~~~~~~~~~~~~~~~~~~^^
  File "C:\Users\sina\AppData\Local\Programs\Python\Python313\Lib\site-packages\redis\connection.py", line 283, in connect
    raise ConnectionError(self._error_message(e))
redis.exceptions.ConnectionError: Error 10061 connecting to 127.0.0.1:6379. No connection could be made because the target machine actively refused it.
INFO 2025-09-10 17:05:31,144 security_middleware 16128 15424 API_RESPONSE [113b2b9f] - GET /api/schema/ - Status: 500
WARNING 2025-09-10 17:05:31,144 security_middleware 16128 15424 RESPONSE - GET /api/schema/ - Status: 500 - Duration: 2.056s
WARNING 2025-09-10 17:05:31,144 monitoring 16128 15424 Slow request: GET /api/schema/ took 2056.28ms
ERROR 2025-09-10 17:05:31,144 basehttp 16128 15424 "GET /api/schema/ HTTP/1.1" 500 128301
INFO 2025-09-10 17:05:31,146 security_middleware 16128 15424 REQUEST - GET /api/ - User: Anonymous - IP: 127.0.0.1 - User-Agent: python-requests/2.32.4
INFO 2025-09-10 17:05:31,146 security_middleware 16128 15424 API_REQUEST [cf51b025] - GET /api/ - User: Anonymous
ERROR 2025-09-10 17:05:33,190 log 16128 15424 Internal Server Error: /api/
Traceback (most recent call last):
  File "C:\Users\sina\AppData\Local\Programs\Python\Python313\Lib\site-packages\django_redis\cache.py", line 29, in _decorator
    return method(self, *args, **kwargs)
  File "C:\Users\sina\AppData\Local\Programs\Python\Python313\Lib\site-packages\django_redis\cache.py", line 99, in _get
    return self.client.get(key, default=default, version=version, client=client)
           ~~~~~~~~~~~~~~~^^^^^^^^^^^^^^^^^^^^^^^^^^^^^^^^^^^^^^^^^^^^^^^^^^^^^^
  File "C:\Users\sina\AppData\Local\Programs\Python\Python313\Lib\site-packages\django_redis\client\default.py", line 260, in get
    raise ConnectionInterrupted(connection=client) from e
django_redis.exceptions.ConnectionInterrupted: Redis ConnectionError: Error 10061 connecting to 127.0.0.1:6379. No connection could be made because the target machine actively refused it.

During handling of the above exception, another exception occurred:

Traceback (most recent call last):
  File "C:\Users\sina\AppData\Local\Programs\Python\Python313\Lib\site-packages\django\core\handlers\exception.py", line 55, in inner
    response = get_response(request)
  File "C:\Users\sina\AppData\Local\Programs\Python\Python313\Lib\site-packages\django\utils\deprecation.py", line 133, in __call__
    response = self.process_request(request)
  File "C:\Users\sina\AppData\Local\Programs\Python\Python313\Lib\site-packages\django\middleware\cache.py", line 158, in process_request
    cache_key = get_cache_key(request, self.key_prefix, "GET", cache=self.cache)
  File "C:\Users\sina\AppData\Local\Programs\Python\Python313\Lib\site-packages\django\utils\cache.py", line 391, in get_cache_key
    headerlist = cache.get(cache_key)
  File "C:\Users\sina\AppData\Local\Programs\Python\Python313\Lib\site-packages\django_redis\cache.py", line 92, in get
    value = self._get(key, default, version, client)
  File "C:\Users\sina\AppData\Local\Programs\Python\Python313\Lib\site-packages\django_redis\cache.py", line 36, in _decorator
    raise e.__cause__
  File "C:\Users\sina\AppData\Local\Programs\Python\Python313\Lib\site-packages\django_redis\client\default.py", line 258, in get
    value = client.get(key)
  File "C:\Users\sina\AppData\Local\Programs\Python\Python313\Lib\site-packages\redis\commands\core.py", line 1821, in get
    return self.execute_command("GET", name)
           ~~~~~~~~~~~~~~~~~~~~^^^^^^^^^^^^^
  File "C:\Users\sina\AppData\Local\Programs\Python\Python313\Lib\site-packages\redis\client.py", line 545, in execute_command
    conn = self.connection or pool.get_connection(command_name, **options)
                              ~~~~~~~~~~~~~~~~~~~^^^^^^^^^^^^^^^^^^^^^^^^^
  File "C:\Users\sina\AppData\Local\Programs\Python\Python313\Lib\site-packages\redis\connection.py", line 1074, in get_connection
    connection.connect()
    ~~~~~~~~~~~~~~~~~~^^
  File "C:\Users\sina\AppData\Local\Programs\Python\Python313\Lib\site-packages\redis\connection.py", line 283, in connect
    raise ConnectionError(self._error_message(e))
redis.exceptions.ConnectionError: Error 10061 connecting to 127.0.0.1:6379. No connection could be made because the target machine actively refused it.
INFO 2025-09-10 17:05:33,193 security_middleware 16128 15424 API_RESPONSE [cf51b025] - GET /api/ - Status: 500
WARNING 2025-09-10 17:05:33,193 security_middleware 16128 15424 RESPONSE - GET /api/ - Status: 500 - Duration: 2.047s
WARNING 2025-09-10 17:05:33,193 monitoring 16128 15424 Slow request: GET /api/ took 2047.43ms
ERROR 2025-09-10 17:05:33,194 basehttp 16128 15424 "GET /api/ HTTP/1.1" 500 128118
INFO 2025-09-10 17:05:33,196 security_middleware 16128 15424 REQUEST - GET /api/users/ - User: Anonymous - IP: 127.0.0.1 - User-Agent: python-requests/2.32.4
INFO 2025-09-10 17:05:33,196 security_middleware 16128 15424 API_REQUEST [c5616694] - GET /api/users/ - User: Anonymous
ERROR 2025-09-10 17:05:35,234 log 16128 15424 Internal Server Error: /api/users/
Traceback (most recent call last):
  File "C:\Users\sina\AppData\Local\Programs\Python\Python313\Lib\site-packages\django_redis\cache.py", line 29, in _decorator
    return method(self, *args, **kwargs)
  File "C:\Users\sina\AppData\Local\Programs\Python\Python313\Lib\site-packages\django_redis\cache.py", line 99, in _get
    return self.client.get(key, default=default, version=version, client=client)
           ~~~~~~~~~~~~~~~^^^^^^^^^^^^^^^^^^^^^^^^^^^^^^^^^^^^^^^^^^^^^^^^^^^^^^
  File "C:\Users\sina\AppData\Local\Programs\Python\Python313\Lib\site-packages\django_redis\client\default.py", line 260, in get
    raise ConnectionInterrupted(connection=client) from e
django_redis.exceptions.ConnectionInterrupted: Redis ConnectionError: Error 10061 connecting to 127.0.0.1:6379. No connection could be made because the target machine actively refused it.

During handling of the above exception, another exception occurred:

Traceback (most recent call last):
  File "C:\Users\sina\AppData\Local\Programs\Python\Python313\Lib\site-packages\django\core\handlers\exception.py", line 55, in inner
    response = get_response(request)
  File "C:\Users\sina\AppData\Local\Programs\Python\Python313\Lib\site-packages\django\utils\deprecation.py", line 133, in __call__
    response = self.process_request(request)
  File "C:\Users\sina\AppData\Local\Programs\Python\Python313\Lib\site-packages\django\middleware\cache.py", line 158, in process_request
    cache_key = get_cache_key(request, self.key_prefix, "GET", cache=self.cache)
  File "C:\Users\sina\AppData\Local\Programs\Python\Python313\Lib\site-packages\django\utils\cache.py", line 391, in get_cache_key
    headerlist = cache.get(cache_key)
  File "C:\Users\sina\AppData\Local\Programs\Python\Python313\Lib\site-packages\django_redis\cache.py", line 92, in get
    value = self._get(key, default, version, client)
  File "C:\Users\sina\AppData\Local\Programs\Python\Python313\Lib\site-packages\django_redis\cache.py", line 36, in _decorator
    raise e.__cause__
  File "C:\Users\sina\AppData\Local\Programs\Python\Python313\Lib\site-packages\django_redis\client\default.py", line 258, in get
    value = client.get(key)
  File "C:\Users\sina\AppData\Local\Programs\Python\Python313\Lib\site-packages\redis\commands\core.py", line 1821, in get
    return self.execute_command("GET", name)
           ~~~~~~~~~~~~~~~~~~~~^^^^^^^^^^^^^
  File "C:\Users\sina\AppData\Local\Programs\Python\Python313\Lib\site-packages\redis\client.py", line 545, in execute_command
    conn = self.connection or pool.get_connection(command_name, **options)
                              ~~~~~~~~~~~~~~~~~~~^^^^^^^^^^^^^^^^^^^^^^^^^
  File "C:\Users\sina\AppData\Local\Programs\Python\Python313\Lib\site-packages\redis\connection.py", line 1074, in get_connection
    connection.connect()
    ~~~~~~~~~~~~~~~~~~^^
  File "C:\Users\sina\AppData\Local\Programs\Python\Python313\Lib\site-packages\redis\connection.py", line 283, in connect
    raise ConnectionError(self._error_message(e))
redis.exceptions.ConnectionError: Error 10061 connecting to 127.0.0.1:6379. No connection could be made because the target machine actively refused it.
INFO 2025-09-10 17:05:35,237 security_middleware 16128 15424 API_RESPONSE [c5616694] - GET /api/users/ - Status: 500
WARNING 2025-09-10 17:05:35,237 security_middleware 16128 15424 RESPONSE - GET /api/users/ - Status: 500 - Duration: 2.042s
WARNING 2025-09-10 17:05:35,237 monitoring 16128 15424 Slow request: GET /api/users/ took 2041.73ms
ERROR 2025-09-10 17:05:35,238 basehttp 16128 15424 "GET /api/users/ HTTP/1.1" 500 128184
INFO 2025-09-10 17:05:35,240 security_middleware 16128 15424 REQUEST - GET /api/courses/ - User: Anonymous - IP: 127.0.0.1 - User-Agent: python-requests/2.32.4
INFO 2025-09-10 17:05:35,240 security_middleware 16128 15424 API_REQUEST [cb660b52] - GET /api/courses/ - User: Anonymous
ERROR 2025-09-10 17:05:37,270 log 16128 15424 Internal Server Error: /api/courses/
Traceback (most recent call last):
  File "C:\Users\sina\AppData\Local\Programs\Python\Python313\Lib\site-packages\django_redis\cache.py", line 29, in _decorator
    return method(self, *args, **kwargs)
  File "C:\Users\sina\AppData\Local\Programs\Python\Python313\Lib\site-packages\django_redis\cache.py", line 99, in _get
    return self.client.get(key, default=default, version=version, client=client)
           ~~~~~~~~~~~~~~~^^^^^^^^^^^^^^^^^^^^^^^^^^^^^^^^^^^^^^^^^^^^^^^^^^^^^^
  File "C:\Users\sina\AppData\Local\Programs\Python\Python313\Lib\site-packages\django_redis\client\default.py", line 260, in get
    raise ConnectionInterrupted(connection=client) from e
django_redis.exceptions.ConnectionInterrupted: Redis ConnectionError: Error 10061 connecting to 127.0.0.1:6379. No connection could be made because the target machine actively refused it.

During handling of the above exception, another exception occurred:

Traceback (most recent call last):
  File "C:\Users\sina\AppData\Local\Programs\Python\Python313\Lib\site-packages\django\core\handlers\exception.py", line 55, in inner
    response = get_response(request)
  File "C:\Users\sina\AppData\Local\Programs\Python\Python313\Lib\site-packages\django\utils\deprecation.py", line 133, in __call__
    response = self.process_request(request)
  File "C:\Users\sina\AppData\Local\Programs\Python\Python313\Lib\site-packages\django\middleware\cache.py", line 158, in process_request
    cache_key = get_cache_key(request, self.key_prefix, "GET", cache=self.cache)
  File "C:\Users\sina\AppData\Local\Programs\Python\Python313\Lib\site-packages\django\utils\cache.py", line 391, in get_cache_key
    headerlist = cache.get(cache_key)
  File "C:\Users\sina\AppData\Local\Programs\Python\Python313\Lib\site-packages\django_redis\cache.py", line 92, in get
    value = self._get(key, default, version, client)
  File "C:\Users\sina\AppData\Local\Programs\Python\Python313\Lib\site-packages\django_redis\cache.py", line 36, in _decorator
    raise e.__cause__
  File "C:\Users\sina\AppData\Local\Programs\Python\Python313\Lib\site-packages\django_redis\client\default.py", line 258, in get
    value = client.get(key)
  File "C:\Users\sina\AppData\Local\Programs\Python\Python313\Lib\site-packages\redis\commands\core.py", line 1821, in get
    return self.execute_command("GET", name)
           ~~~~~~~~~~~~~~~~~~~~^^^^^^^^^^^^^
  File "C:\Users\sina\AppData\Local\Programs\Python\Python313\Lib\site-packages\redis\client.py", line 545, in execute_command
    conn = self.connection or pool.get_connection(command_name, **options)
                              ~~~~~~~~~~~~~~~~~~~^^^^^^^^^^^^^^^^^^^^^^^^^
  File "C:\Users\sina\AppData\Local\Programs\Python\Python313\Lib\site-packages\redis\connection.py", line 1074, in get_connection
    connection.connect()
    ~~~~~~~~~~~~~~~~~~^^
  File "C:\Users\sina\AppData\Local\Programs\Python\Python313\Lib\site-packages\redis\connection.py", line 283, in connect
    raise ConnectionError(self._error_message(e))
redis.exceptions.ConnectionError: Error 10061 connecting to 127.0.0.1:6379. No connection could be made because the target machine actively refused it.
INFO 2025-09-10 17:05:37,273 security_middleware 16128 15424 API_RESPONSE [cb660b52] - GET /api/courses/ - Status: 500
WARNING 2025-09-10 17:05:37,273 security_middleware 16128 15424 RESPONSE - GET /api/courses/ - Status: 500 - Duration: 2.033s
WARNING 2025-09-10 17:05:37,273 monitoring 16128 15424 Slow request: GET /api/courses/ took 2033.52ms
ERROR 2025-09-10 17:05:37,274 basehttp 16128 15424 "GET /api/courses/ HTTP/1.1" 500 128306
INFO 2025-09-10 17:05:37,276 security_middleware 16128 15424 REQUEST - GET /api/announcements/ - User: Anonymous - IP: 127.0.0.1 - User-Agent: python-requests/2.32.4
INFO 2025-09-10 17:05:37,277 security_middleware 16128 15424 API_REQUEST [28e3fdb1] - GET /api/announcements/ - User: Anonymous
ERROR 2025-09-10 17:05:39,344 log 16128 15424 Internal Server Error: /api/announcements/
Traceback (most recent call last):
  File "C:\Users\sina\AppData\Local\Programs\Python\Python313\Lib\site-packages\django_redis\cache.py", line 29, in _decorator
    return method(self, *args, **kwargs)
  File "C:\Users\sina\AppData\Local\Programs\Python\Python313\Lib\site-packages\django_redis\cache.py", line 99, in _get
    return self.client.get(key, default=default, version=version, client=client)
           ~~~~~~~~~~~~~~~^^^^^^^^^^^^^^^^^^^^^^^^^^^^^^^^^^^^^^^^^^^^^^^^^^^^^^
  File "C:\Users\sina\AppData\Local\Programs\Python\Python313\Lib\site-packages\django_redis\client\default.py", line 260, in get
    raise ConnectionInterrupted(connection=client) from e
django_redis.exceptions.ConnectionInterrupted: Redis ConnectionError: Error 10061 connecting to 127.0.0.1:6379. No connection could be made because the target machine actively refused it.

During handling of the above exception, another exception occurred:

Traceback (most recent call last):
  File "C:\Users\sina\AppData\Local\Programs\Python\Python313\Lib\site-packages\django\core\handlers\exception.py", line 55, in inner
    response = get_response(request)
  File "C:\Users\sina\AppData\Local\Programs\Python\Python313\Lib\site-packages\django\utils\deprecation.py", line 133, in __call__
    response = self.process_request(request)
  File "C:\Users\sina\AppData\Local\Programs\Python\Python313\Lib\site-packages\django\middleware\cache.py", line 158, in process_request
    cache_key = get_cache_key(request, self.key_prefix, "GET", cache=self.cache)
  File "C:\Users\sina\AppData\Local\Programs\Python\Python313\Lib\site-packages\django\utils\cache.py", line 391, in get_cache_key
    headerlist = cache.get(cache_key)
  File "C:\Users\sina\AppData\Local\Programs\Python\Python313\Lib\site-packages\django_redis\cache.py", line 92, in get
    value = self._get(key, default, version, client)
  File "C:\Users\sina\AppData\Local\Programs\Python\Python313\Lib\site-packages\django_redis\cache.py", line 36, in _decorator
    raise e.__cause__
  File "C:\Users\sina\AppData\Local\Programs\Python\Python313\Lib\site-packages\django_redis\client\default.py", line 258, in get
    value = client.get(key)
  File "C:\Users\sina\AppData\Local\Programs\Python\Python313\Lib\site-packages\redis\commands\core.py", line 1821, in get
    return self.execute_command("GET", name)
           ~~~~~~~~~~~~~~~~~~~~^^^^^^^^^^^^^
  File "C:\Users\sina\AppData\Local\Programs\Python\Python313\Lib\site-packages\redis\client.py", line 545, in execute_command
    conn = self.connection or pool.get_connection(command_name, **options)
                              ~~~~~~~~~~~~~~~~~~~^^^^^^^^^^^^^^^^^^^^^^^^^
  File "C:\Users\sina\AppData\Local\Programs\Python\Python313\Lib\site-packages\redis\connection.py", line 1074, in get_connection
    connection.connect()
    ~~~~~~~~~~~~~~~~~~^^
  File "C:\Users\sina\AppData\Local\Programs\Python\Python313\Lib\site-packages\redis\connection.py", line 283, in connect
    raise ConnectionError(self._error_message(e))
redis.exceptions.ConnectionError: Error 10061 connecting to 127.0.0.1:6379. No connection could be made because the target machine actively refused it.
INFO 2025-09-10 17:05:39,346 security_middleware 16128 15424 API_RESPONSE [28e3fdb1] - GET /api/announcements/ - Status: 500
WARNING 2025-09-10 17:05:39,347 security_middleware 16128 15424 RESPONSE - GET /api/announcements/ - Status: 500 - Duration: 2.070s
WARNING 2025-09-10 17:05:39,347 monitoring 16128 15424 Slow request: GET /api/announcements/ took 2070.59ms
ERROR 2025-09-10 17:05:39,347 basehttp 16128 15424 "GET /api/announcements/ HTTP/1.1" 500 128372
INFO 2025-09-10 17:05:39,348 security_middleware 16128 15424 REQUEST - GET /api/assignments/ - User: Anonymous - IP: 127.0.0.1 - User-Agent: python-requests/2.32.4
INFO 2025-09-10 17:05:39,349 security_middleware 16128 15424 API_REQUEST [d7afd16b] - GET /api/assignments/ - User: Anonymous
ERROR 2025-09-10 17:05:41,389 log 16128 15424 Internal Server Error: /api/assignments/
Traceback (most recent call last):
  File "C:\Users\sina\AppData\Local\Programs\Python\Python313\Lib\site-packages\django_redis\cache.py", line 29, in _decorator
    return method(self, *args, **kwargs)
  File "C:\Users\sina\AppData\Local\Programs\Python\Python313\Lib\site-packages\django_redis\cache.py", line 99, in _get
    return self.client.get(key, default=default, version=version, client=client)
           ~~~~~~~~~~~~~~~^^^^^^^^^^^^^^^^^^^^^^^^^^^^^^^^^^^^^^^^^^^^^^^^^^^^^^
  File "C:\Users\sina\AppData\Local\Programs\Python\Python313\Lib\site-packages\django_redis\client\default.py", line 260, in get
    raise ConnectionInterrupted(connection=client) from e
django_redis.exceptions.ConnectionInterrupted: Redis ConnectionError: Error 10061 connecting to 127.0.0.1:6379. No connection could be made because the target machine actively refused it.

During handling of the above exception, another exception occurred:

Traceback (most recent call last):
  File "C:\Users\sina\AppData\Local\Programs\Python\Python313\Lib\site-packages\django\core\handlers\exception.py", line 55, in inner
    response = get_response(request)
  File "C:\Users\sina\AppData\Local\Programs\Python\Python313\Lib\site-packages\django\utils\deprecation.py", line 133, in __call__
    response = self.process_request(request)
  File "C:\Users\sina\AppData\Local\Programs\Python\Python313\Lib\site-packages\django\middleware\cache.py", line 158, in process_request
    cache_key = get_cache_key(request, self.key_prefix, "GET", cache=self.cache)
  File "C:\Users\sina\AppData\Local\Programs\Python\Python313\Lib\site-packages\django\utils\cache.py", line 391, in get_cache_key
    headerlist = cache.get(cache_key)
  File "C:\Users\sina\AppData\Local\Programs\Python\Python313\Lib\site-packages\django_redis\cache.py", line 92, in get
    value = self._get(key, default, version, client)
  File "C:\Users\sina\AppData\Local\Programs\Python\Python313\Lib\site-packages\django_redis\cache.py", line 36, in _decorator
    raise e.__cause__
  File "C:\Users\sina\AppData\Local\Programs\Python\Python313\Lib\site-packages\django_redis\client\default.py", line 258, in get
    value = client.get(key)
  File "C:\Users\sina\AppData\Local\Programs\Python\Python313\Lib\site-packages\redis\commands\core.py", line 1821, in get
    return self.execute_command("GET", name)
           ~~~~~~~~~~~~~~~~~~~~^^^^^^^^^^^^^
  File "C:\Users\sina\AppData\Local\Programs\Python\Python313\Lib\site-packages\redis\client.py", line 545, in execute_command
    conn = self.connection or pool.get_connection(command_name, **options)
                              ~~~~~~~~~~~~~~~~~~~^^^^^^^^^^^^^^^^^^^^^^^^^
  File "C:\Users\sina\AppData\Local\Programs\Python\Python313\Lib\site-packages\redis\connection.py", line 1074, in get_connection
    connection.connect()
    ~~~~~~~~~~~~~~~~~~^^
  File "C:\Users\sina\AppData\Local\Programs\Python\Python313\Lib\site-packages\redis\connection.py", line 283, in connect
    raise ConnectionError(self._error_message(e))
redis.exceptions.ConnectionError: Error 10061 connecting to 127.0.0.1:6379. No connection could be made because the target machine actively refused it.
INFO 2025-09-10 17:05:41,392 security_middleware 16128 15424 API_RESPONSE [d7afd16b] - GET /api/assignments/ - Status: 500
WARNING 2025-09-10 17:05:41,392 security_middleware 16128 15424 RESPONSE - GET /api/assignments/ - Status: 500 - Duration: 2.044s
WARNING 2025-09-10 17:05:41,392 monitoring 16128 15424 Slow request: GET /api/assignments/ took 2043.96ms
ERROR 2025-09-10 17:05:41,393 basehttp 16128 15424 "GET /api/assignments/ HTTP/1.1" 500 128350
INFO 2025-09-10 17:05:41,395 security_middleware 16128 15424 REQUEST - GET /api/nonexistent/ - User: Anonymous - IP: 127.0.0.1 - User-Agent: python-requests/2.32.4
INFO 2025-09-10 17:05:41,395 security_middleware 16128 15424 API_REQUEST [ee36d754] - GET /api/nonexistent/ - User: Anonymous
ERROR 2025-09-10 17:05:43,449 log 16128 15424 Internal Server Error: /api/nonexistent/
Traceback (most recent call last):
  File "C:\Users\sina\AppData\Local\Programs\Python\Python313\Lib\site-packages\django_redis\cache.py", line 29, in _decorator
    return method(self, *args, **kwargs)
  File "C:\Users\sina\AppData\Local\Programs\Python\Python313\Lib\site-packages\django_redis\cache.py", line 99, in _get
    return self.client.get(key, default=default, version=version, client=client)
           ~~~~~~~~~~~~~~~^^^^^^^^^^^^^^^^^^^^^^^^^^^^^^^^^^^^^^^^^^^^^^^^^^^^^^
  File "C:\Users\sina\AppData\Local\Programs\Python\Python313\Lib\site-packages\django_redis\client\default.py", line 260, in get
    raise ConnectionInterrupted(connection=client) from e
django_redis.exceptions.ConnectionInterrupted: Redis ConnectionError: Error 10061 connecting to 127.0.0.1:6379. No connection could be made because the target machine actively refused it.

During handling of the above exception, another exception occurred:

Traceback (most recent call last):
  File "C:\Users\sina\AppData\Local\Programs\Python\Python313\Lib\site-packages\django\core\handlers\exception.py", line 55, in inner
    response = get_response(request)
  File "C:\Users\sina\AppData\Local\Programs\Python\Python313\Lib\site-packages\django\utils\deprecation.py", line 133, in __call__
    response = self.process_request(request)
  File "C:\Users\sina\AppData\Local\Programs\Python\Python313\Lib\site-packages\django\middleware\cache.py", line 158, in process_request
    cache_key = get_cache_key(request, self.key_prefix, "GET", cache=self.cache)
  File "C:\Users\sina\AppData\Local\Programs\Python\Python313\Lib\site-packages\django\utils\cache.py", line 391, in get_cache_key
    headerlist = cache.get(cache_key)
  File "C:\Users\sina\AppData\Local\Programs\Python\Python313\Lib\site-packages\django_redis\cache.py", line 92, in get
    value = self._get(key, default, version, client)
  File "C:\Users\sina\AppData\Local\Programs\Python\Python313\Lib\site-packages\django_redis\cache.py", line 36, in _decorator
    raise e.__cause__
  File "C:\Users\sina\AppData\Local\Programs\Python\Python313\Lib\site-packages\django_redis\client\default.py", line 258, in get
    value = client.get(key)
  File "C:\Users\sina\AppData\Local\Programs\Python\Python313\Lib\site-packages\redis\commands\core.py", line 1821, in get
    return self.execute_command("GET", name)
           ~~~~~~~~~~~~~~~~~~~~^^^^^^^^^^^^^
  File "C:\Users\sina\AppData\Local\Programs\Python\Python313\Lib\site-packages\redis\client.py", line 545, in execute_command
    conn = self.connection or pool.get_connection(command_name, **options)
                              ~~~~~~~~~~~~~~~~~~~^^^^^^^^^^^^^^^^^^^^^^^^^
  File "C:\Users\sina\AppData\Local\Programs\Python\Python313\Lib\site-packages\redis\connection.py", line 1074, in get_connection
    connection.connect()
    ~~~~~~~~~~~~~~~~~~^^
  File "C:\Users\sina\AppData\Local\Programs\Python\Python313\Lib\site-packages\redis\connection.py", line 283, in connect
    raise ConnectionError(self._error_message(e))
redis.exceptions.ConnectionError: Error 10061 connecting to 127.0.0.1:6379. No connection could be made because the target machine actively refused it.
INFO 2025-09-10 17:05:43,452 security_middleware 16128 15424 API_RESPONSE [ee36d754] - GET /api/nonexistent/ - Status: 500
WARNING 2025-09-10 17:05:43,452 security_middleware 16128 15424 RESPONSE - GET /api/nonexistent/ - Status: 500 - Duration: 2.058s
WARNING 2025-09-10 17:05:43,453 monitoring 16128 15424 Slow request: GET /api/nonexistent/ took 2057.76ms
ERROR 2025-09-10 17:05:43,453 basehttp 16128 15424 "GET /api/nonexistent/ HTTP/1.1" 500 128250
INFO 2025-09-10 17:05:43,454 security_middleware 16128 15424 REQUEST - POST /api/health/ - User: Anonymous - IP: 127.0.0.1 - User-Agent: python-requests/2.32.4
INFO 2025-09-10 17:05:43,454 security_middleware 16128 15424 API_REQUEST [97b4c190] - POST /api/health/ - User: Anonymous
ERROR 2025-09-10 17:05:45,495 monitoring 16128 15424 Exception in POST /api/health/: Error 10061 connecting to 127.0.0.1:6379. No connection could be made because the target machine actively refused it.
Traceback (most recent call last):
  File "C:\Users\sina\AppData\Local\Programs\Python\Python313\Lib\site-packages\django_redis\cache.py", line 29, in _decorator
    return method(self, *args, **kwargs)
  File "C:\Users\sina\AppData\Local\Programs\Python\Python313\Lib\site-packages\django_redis\cache.py", line 99, in _get
    return self.client.get(key, default=default, version=version, client=client)
           ~~~~~~~~~~~~~~~^^^^^^^^^^^^^^^^^^^^^^^^^^^^^^^^^^^^^^^^^^^^^^^^^^^^^^
  File "C:\Users\sina\AppData\Local\Programs\Python\Python313\Lib\site-packages\django_redis\client\default.py", line 260, in get
    raise ConnectionInterrupted(connection=client) from e
django_redis.exceptions.ConnectionInterrupted: Redis ConnectionError: Error 10061 connecting to 127.0.0.1:6379. No connection could be made because the target machine actively refused it.

During handling of the above exception, another exception occurred:

Traceback (most recent call last):
  File "C:\Users\sina\AppData\Local\Programs\Python\Python313\Lib\site-packages\django\core\handlers\base.py", line 197, in _get_response
    response = wrapped_callback(request, *callback_args, **callback_kwargs)
  File "C:\Users\sina\AppData\Local\Programs\Python\Python313\Lib\site-packages\django\views\decorators\csrf.py", line 56, in wrapper_view
    return view_func(*args, **kwargs)
  File "C:\Users\sina\AppData\Local\Programs\Python\Python313\Lib\site-packages\django\views\generic\base.py", line 104, in view
    return self.dispatch(request, *args, **kwargs)
           ~~~~~~~~~~~~~^^^^^^^^^^^^^^^^^^^^^^^^^^
  File "C:\Users\sina\AppData\Local\Programs\Python\Python313\Lib\site-packages\rest_framework\views.py", line 509, in dispatch
    response = self.handle_exception(exc)
  File "C:\Users\sina\AppData\Local\Programs\Python\Python313\Lib\site-packages\rest_framework\views.py", line 469, in handle_exception
    self.raise_uncaught_exception(exc)
    ~~~~~~~~~~~~~~~~~~~~~~~~~~~~~^^^^^
  File "C:\Users\sina\AppData\Local\Programs\Python\Python313\Lib\site-packages\rest_framework\views.py", line 480, in raise_uncaught_exception
    raise exc
  File "C:\Users\sina\AppData\Local\Programs\Python\Python313\Lib\site-packages\rest_framework\views.py", line 497, in dispatch
    self.initial(request, *args, **kwargs)
    ~~~~~~~~~~~~^^^^^^^^^^^^^^^^^^^^^^^^^^
  File "C:\Users\sina\AppData\Local\Programs\Python\Python313\Lib\site-packages\rest_framework\views.py", line 416, in initial
    self.check_throttles(request)
    ~~~~~~~~~~~~~~~~~~~~^^^^^^^^^
  File "C:\Users\sina\AppData\Local\Programs\Python\Python313\Lib\site-packages\rest_framework\views.py", line 359, in check_throttles
    if not throttle.allow_request(request, self):
           ~~~~~~~~~~~~~~~~~~~~~~^^^^^^^^^^^^^^^
  File "C:\Users\sina\AppData\Local\Programs\Python\Python313\Lib\site-packages\rest_framework\throttling.py", line 123, in allow_request
    self.history = self.cache.get(self.key, [])
                   ~~~~~~~~~~~~~~^^^^^^^^^^^^^^
  File "C:\Users\sina\AppData\Local\Programs\Python\Python313\Lib\site-packages\django_redis\cache.py", line 92, in get
    value = self._get(key, default, version, client)
  File "C:\Users\sina\AppData\Local\Programs\Python\Python313\Lib\site-packages\django_redis\cache.py", line 36, in _decorator
    raise e.__cause__
  File "C:\Users\sina\AppData\Local\Programs\Python\Python313\Lib\site-packages\django_redis\client\default.py", line 258, in get
    value = client.get(key)
  File "C:\Users\sina\AppData\Local\Programs\Python\Python313\Lib\site-packages\redis\commands\core.py", line 1821, in get
    return self.execute_command("GET", name)
           ~~~~~~~~~~~~~~~~~~~~^^^^^^^^^^^^^
  File "C:\Users\sina\AppData\Local\Programs\Python\Python313\Lib\site-packages\redis\client.py", line 545, in execute_command
    conn = self.connection or pool.get_connection(command_name, **options)
                              ~~~~~~~~~~~~~~~~~~~^^^^^^^^^^^^^^^^^^^^^^^^^
  File "C:\Users\sina\AppData\Local\Programs\Python\Python313\Lib\site-packages\redis\connection.py", line 1074, in get_connection
    connection.connect()
    ~~~~~~~~~~~~~~~~~~^^
  File "C:\Users\sina\AppData\Local\Programs\Python\Python313\Lib\site-packages\redis\connection.py", line 283, in connect
    raise ConnectionError(self._error_message(e))
redis.exceptions.ConnectionError: Error 10061 connecting to 127.0.0.1:6379. No connection could be made because the target machine actively refused it.
ERROR 2025-09-10 17:05:45,519 log 16128 15424 Internal Server Error: /api/health/
Traceback (most recent call last):
  File "C:\Users\sina\AppData\Local\Programs\Python\Python313\Lib\site-packages\django_redis\cache.py", line 29, in _decorator
    return method(self, *args, **kwargs)
  File "C:\Users\sina\AppData\Local\Programs\Python\Python313\Lib\site-packages\django_redis\cache.py", line 99, in _get
    return self.client.get(key, default=default, version=version, client=client)
           ~~~~~~~~~~~~~~~^^^^^^^^^^^^^^^^^^^^^^^^^^^^^^^^^^^^^^^^^^^^^^^^^^^^^^
  File "C:\Users\sina\AppData\Local\Programs\Python\Python313\Lib\site-packages\django_redis\client\default.py", line 260, in get
    raise ConnectionInterrupted(connection=client) from e
django_redis.exceptions.ConnectionInterrupted: Redis ConnectionError: Error 10061 connecting to 127.0.0.1:6379. No connection could be made because the target machine actively refused it.

During handling of the above exception, another exception occurred:

Traceback (most recent call last):
  File "C:\Users\sina\AppData\Local\Programs\Python\Python313\Lib\site-packages\django\core\handlers\exception.py", line 55, in inner
    response = get_response(request)
  File "C:\Users\sina\AppData\Local\Programs\Python\Python313\Lib\site-packages\django\core\handlers\base.py", line 197, in _get_response
    response = wrapped_callback(request, *callback_args, **callback_kwargs)
  File "C:\Users\sina\AppData\Local\Programs\Python\Python313\Lib\site-packages\django\views\decorators\csrf.py", line 56, in wrapper_view
    return view_func(*args, **kwargs)
  File "C:\Users\sina\AppData\Local\Programs\Python\Python313\Lib\site-packages\django\views\generic\base.py", line 104, in view
    return self.dispatch(request, *args, **kwargs)
           ~~~~~~~~~~~~~^^^^^^^^^^^^^^^^^^^^^^^^^^
  File "C:\Users\sina\AppData\Local\Programs\Python\Python313\Lib\site-packages\rest_framework\views.py", line 509, in dispatch
    response = self.handle_exception(exc)
  File "C:\Users\sina\AppData\Local\Programs\Python\Python313\Lib\site-packages\rest_framework\views.py", line 469, in handle_exception
    self.raise_uncaught_exception(exc)
    ~~~~~~~~~~~~~~~~~~~~~~~~~~~~~^^^^^
  File "C:\Users\sina\AppData\Local\Programs\Python\Python313\Lib\site-packages\rest_framework\views.py", line 480, in raise_uncaught_exception
    raise exc
  File "C:\Users\sina\AppData\Local\Programs\Python\Python313\Lib\site-packages\rest_framework\views.py", line 497, in dispatch
    self.initial(request, *args, **kwargs)
    ~~~~~~~~~~~~^^^^^^^^^^^^^^^^^^^^^^^^^^
  File "C:\Users\sina\AppData\Local\Programs\Python\Python313\Lib\site-packages\rest_framework\views.py", line 416, in initial
    self.check_throttles(request)
    ~~~~~~~~~~~~~~~~~~~~^^^^^^^^^
  File "C:\Users\sina\AppData\Local\Programs\Python\Python313\Lib\site-packages\rest_framework\views.py", line 359, in check_throttles
    if not throttle.allow_request(request, self):
           ~~~~~~~~~~~~~~~~~~~~~~^^^^^^^^^^^^^^^
  File "C:\Users\sina\AppData\Local\Programs\Python\Python313\Lib\site-packages\rest_framework\throttling.py", line 123, in allow_request
    self.history = self.cache.get(self.key, [])
                   ~~~~~~~~~~~~~~^^^^^^^^^^^^^^
  File "C:\Users\sina\AppData\Local\Programs\Python\Python313\Lib\site-packages\django_redis\cache.py", line 92, in get
    value = self._get(key, default, version, client)
  File "C:\Users\sina\AppData\Local\Programs\Python\Python313\Lib\site-packages\django_redis\cache.py", line 36, in _decorator
    raise e.__cause__
  File "C:\Users\sina\AppData\Local\Programs\Python\Python313\Lib\site-packages\django_redis\client\default.py", line 258, in get
    value = client.get(key)
  File "C:\Users\sina\AppData\Local\Programs\Python\Python313\Lib\site-packages\redis\commands\core.py", line 1821, in get
    return self.execute_command("GET", name)
           ~~~~~~~~~~~~~~~~~~~~^^^^^^^^^^^^^
  File "C:\Users\sina\AppData\Local\Programs\Python\Python313\Lib\site-packages\redis\client.py", line 545, in execute_command
    conn = self.connection or pool.get_connection(command_name, **options)
                              ~~~~~~~~~~~~~~~~~~~^^^^^^^^^^^^^^^^^^^^^^^^^
  File "C:\Users\sina\AppData\Local\Programs\Python\Python313\Lib\site-packages\redis\connection.py", line 1074, in get_connection
    connection.connect()
    ~~~~~~~~~~~~~~~~~~^^
  File "C:\Users\sina\AppData\Local\Programs\Python\Python313\Lib\site-packages\redis\connection.py", line 283, in connect
    raise ConnectionError(self._error_message(e))
redis.exceptions.ConnectionError: Error 10061 connecting to 127.0.0.1:6379. No connection could be made because the target machine actively refused it.
INFO 2025-09-10 17:05:45,523 security_middleware 16128 15424 API_RESPONSE [97b4c190] - POST /api/health/ - Status: 500
WARNING 2025-09-10 17:05:45,523 security_middleware 16128 15424 RESPONSE - POST /api/health/ - Status: 500 - Duration: 2.069s
WARNING 2025-09-10 17:05:45,523 monitoring 16128 15424 Slow request: POST /api/health/ took 2069.02ms
ERROR 2025-09-10 17:05:45,524 basehttp 16128 15424 "POST /api/health/ HTTP/1.1" 500 160128
INFO 2025-09-10 17:05:45,526 security_middleware 16128 15424 REQUEST - GET /api/health/ - User: Anonymous - IP: 127.0.0.1 - User-Agent: python-requests/2.32.4
INFO 2025-09-10 17:05:45,526 security_middleware 16128 15424 API_REQUEST [a3dcc574] - GET /api/health/ - User: Anonymous
ERROR 2025-09-10 17:05:47,596 log 16128 15424 Internal Server Error: /api/health/
Traceback (most recent call last):
  File "C:\Users\sina\AppData\Local\Programs\Python\Python313\Lib\site-packages\django_redis\cache.py", line 29, in _decorator
    return method(self, *args, **kwargs)
  File "C:\Users\sina\AppData\Local\Programs\Python\Python313\Lib\site-packages\django_redis\cache.py", line 99, in _get
    return self.client.get(key, default=default, version=version, client=client)
           ~~~~~~~~~~~~~~~^^^^^^^^^^^^^^^^^^^^^^^^^^^^^^^^^^^^^^^^^^^^^^^^^^^^^^
  File "C:\Users\sina\AppData\Local\Programs\Python\Python313\Lib\site-packages\django_redis\client\default.py", line 260, in get
    raise ConnectionInterrupted(connection=client) from e
django_redis.exceptions.ConnectionInterrupted: Redis ConnectionError: Error 10061 connecting to 127.0.0.1:6379. No connection could be made because the target machine actively refused it.

During handling of the above exception, another exception occurred:

Traceback (most recent call last):
  File "C:\Users\sina\AppData\Local\Programs\Python\Python313\Lib\site-packages\django\core\handlers\exception.py", line 55, in inner
    response = get_response(request)
  File "C:\Users\sina\AppData\Local\Programs\Python\Python313\Lib\site-packages\django\utils\deprecation.py", line 133, in __call__
    response = self.process_request(request)
  File "C:\Users\sina\AppData\Local\Programs\Python\Python313\Lib\site-packages\django\middleware\cache.py", line 158, in process_request
    cache_key = get_cache_key(request, self.key_prefix, "GET", cache=self.cache)
  File "C:\Users\sina\AppData\Local\Programs\Python\Python313\Lib\site-packages\django\utils\cache.py", line 391, in get_cache_key
    headerlist = cache.get(cache_key)
  File "C:\Users\sina\AppData\Local\Programs\Python\Python313\Lib\site-packages\django_redis\cache.py", line 92, in get
    value = self._get(key, default, version, client)
  File "C:\Users\sina\AppData\Local\Programs\Python\Python313\Lib\site-packages\django_redis\cache.py", line 36, in _decorator
    raise e.__cause__
  File "C:\Users\sina\AppData\Local\Programs\Python\Python313\Lib\site-packages\django_redis\client\default.py", line 258, in get
    value = client.get(key)
  File "C:\Users\sina\AppData\Local\Programs\Python\Python313\Lib\site-packages\redis\commands\core.py", line 1821, in get
    return self.execute_command("GET", name)
           ~~~~~~~~~~~~~~~~~~~~^^^^^^^^^^^^^
  File "C:\Users\sina\AppData\Local\Programs\Python\Python313\Lib\site-packages\redis\client.py", line 545, in execute_command
    conn = self.connection or pool.get_connection(command_name, **options)
                              ~~~~~~~~~~~~~~~~~~~^^^^^^^^^^^^^^^^^^^^^^^^^
  File "C:\Users\sina\AppData\Local\Programs\Python\Python313\Lib\site-packages\redis\connection.py", line 1074, in get_connection
    connection.connect()
    ~~~~~~~~~~~~~~~~~~^^
  File "C:\Users\sina\AppData\Local\Programs\Python\Python313\Lib\site-packages\redis\connection.py", line 283, in connect
    raise ConnectionError(self._error_message(e))
redis.exceptions.ConnectionError: Error 10061 connecting to 127.0.0.1:6379. No connection could be made because the target machine actively refused it.
INFO 2025-09-10 17:05:47,599 security_middleware 16128 15424 API_RESPONSE [a3dcc574] - GET /api/health/ - Status: 500
WARNING 2025-09-10 17:05:47,599 security_middleware 16128 15424 RESPONSE - GET /api/health/ - Status: 500 - Duration: 2.073s
WARNING 2025-09-10 17:05:47,599 monitoring 16128 15424 Slow request: GET /api/health/ took 2073.49ms
ERROR 2025-09-10 17:05:47,600 basehttp 16128 15424 "GET /api/health/ HTTP/1.1" 500 128294
INFO 2025-09-10 17:05:47,602 security_middleware 16128 15424 REQUEST - GET /api/version/ - User: Anonymous - IP: 127.0.0.1 - User-Agent: python-requests/2.32.4
INFO 2025-09-10 17:05:47,603 security_middleware 16128 15424 API_REQUEST [f08362df] - GET /api/version/ - User: Anonymous
ERROR 2025-09-10 17:05:49,660 log 16128 15424 Internal Server Error: /api/version/
Traceback (most recent call last):
  File "C:\Users\sina\AppData\Local\Programs\Python\Python313\Lib\site-packages\django_redis\cache.py", line 29, in _decorator
    return method(self, *args, **kwargs)
  File "C:\Users\sina\AppData\Local\Programs\Python\Python313\Lib\site-packages\django_redis\cache.py", line 99, in _get
    return self.client.get(key, default=default, version=version, client=client)
           ~~~~~~~~~~~~~~~^^^^^^^^^^^^^^^^^^^^^^^^^^^^^^^^^^^^^^^^^^^^^^^^^^^^^^
  File "C:\Users\sina\AppData\Local\Programs\Python\Python313\Lib\site-packages\django_redis\client\default.py", line 260, in get
    raise ConnectionInterrupted(connection=client) from e
django_redis.exceptions.ConnectionInterrupted: Redis ConnectionError: Error 10061 connecting to 127.0.0.1:6379. No connection could be made because the target machine actively refused it.

During handling of the above exception, another exception occurred:

Traceback (most recent call last):
  File "C:\Users\sina\AppData\Local\Programs\Python\Python313\Lib\site-packages\django\core\handlers\exception.py", line 55, in inner
    response = get_response(request)
  File "C:\Users\sina\AppData\Local\Programs\Python\Python313\Lib\site-packages\django\utils\deprecation.py", line 133, in __call__
    response = self.process_request(request)
  File "C:\Users\sina\AppData\Local\Programs\Python\Python313\Lib\site-packages\django\middleware\cache.py", line 158, in process_request
    cache_key = get_cache_key(request, self.key_prefix, "GET", cache=self.cache)
  File "C:\Users\sina\AppData\Local\Programs\Python\Python313\Lib\site-packages\django\utils\cache.py", line 391, in get_cache_key
    headerlist = cache.get(cache_key)
  File "C:\Users\sina\AppData\Local\Programs\Python\Python313\Lib\site-packages\django_redis\cache.py", line 92, in get
    value = self._get(key, default, version, client)
  File "C:\Users\sina\AppData\Local\Programs\Python\Python313\Lib\site-packages\django_redis\cache.py", line 36, in _decorator
    raise e.__cause__
  File "C:\Users\sina\AppData\Local\Programs\Python\Python313\Lib\site-packages\django_redis\client\default.py", line 258, in get
    value = client.get(key)
  File "C:\Users\sina\AppData\Local\Programs\Python\Python313\Lib\site-packages\redis\commands\core.py", line 1821, in get
    return self.execute_command("GET", name)
           ~~~~~~~~~~~~~~~~~~~~^^^^^^^^^^^^^
  File "C:\Users\sina\AppData\Local\Programs\Python\Python313\Lib\site-packages\redis\client.py", line 545, in execute_command
    conn = self.connection or pool.get_connection(command_name, **options)
                              ~~~~~~~~~~~~~~~~~~~^^^^^^^^^^^^^^^^^^^^^^^^^
  File "C:\Users\sina\AppData\Local\Programs\Python\Python313\Lib\site-packages\redis\connection.py", line 1074, in get_connection
    connection.connect()
    ~~~~~~~~~~~~~~~~~~^^
  File "C:\Users\sina\AppData\Local\Programs\Python\Python313\Lib\site-packages\redis\connection.py", line 283, in connect
    raise ConnectionError(self._error_message(e))
redis.exceptions.ConnectionError: Error 10061 connecting to 127.0.0.1:6379. No connection could be made because the target machine actively refused it.
INFO 2025-09-10 17:05:49,662 security_middleware 16128 15424 API_RESPONSE [f08362df] - GET /api/version/ - Status: 500
WARNING 2025-09-10 17:05:49,663 security_middleware 16128 15424 RESPONSE - GET /api/version/ - Status: 500 - Duration: 2.060s
WARNING 2025-09-10 17:05:49,663 monitoring 16128 15424 Slow request: GET /api/version/ took 2060.60ms
ERROR 2025-09-10 17:05:49,664 basehttp 16128 15424 "GET /api/version/ HTTP/1.1" 500 27801
INFO 2025-09-10 17:05:49,665 security_middleware 16128 15424 REQUEST - GET /api/health/ - User: Anonymous - IP: 127.0.0.1 - User-Agent: python-requests/2.32.4
INFO 2025-09-10 17:05:49,665 security_middleware 16128 15424 API_REQUEST [58523600] - GET /api/health/ - User: Anonymous
ERROR 2025-09-10 17:05:51,753 log 16128 15424 Internal Server Error: /api/health/
Traceback (most recent call last):
  File "C:\Users\sina\AppData\Local\Programs\Python\Python313\Lib\site-packages\django_redis\cache.py", line 29, in _decorator
    return method(self, *args, **kwargs)
  File "C:\Users\sina\AppData\Local\Programs\Python\Python313\Lib\site-packages\django_redis\cache.py", line 99, in _get
    return self.client.get(key, default=default, version=version, client=client)
           ~~~~~~~~~~~~~~~^^^^^^^^^^^^^^^^^^^^^^^^^^^^^^^^^^^^^^^^^^^^^^^^^^^^^^
  File "C:\Users\sina\AppData\Local\Programs\Python\Python313\Lib\site-packages\django_redis\client\default.py", line 260, in get
    raise ConnectionInterrupted(connection=client) from e
django_redis.exceptions.ConnectionInterrupted: Redis ConnectionError: Error 10061 connecting to 127.0.0.1:6379. No connection could be made because the target machine actively refused it.

During handling of the above exception, another exception occurred:

Traceback (most recent call last):
  File "C:\Users\sina\AppData\Local\Programs\Python\Python313\Lib\site-packages\django\core\handlers\exception.py", line 55, in inner
    response = get_response(request)
  File "C:\Users\sina\AppData\Local\Programs\Python\Python313\Lib\site-packages\django\utils\deprecation.py", line 133, in __call__
    response = self.process_request(request)
  File "C:\Users\sina\AppData\Local\Programs\Python\Python313\Lib\site-packages\django\middleware\cache.py", line 158, in process_request
    cache_key = get_cache_key(request, self.key_prefix, "GET", cache=self.cache)
  File "C:\Users\sina\AppData\Local\Programs\Python\Python313\Lib\site-packages\django\utils\cache.py", line 391, in get_cache_key
    headerlist = cache.get(cache_key)
  File "C:\Users\sina\AppData\Local\Programs\Python\Python313\Lib\site-packages\django_redis\cache.py", line 92, in get
    value = self._get(key, default, version, client)
  File "C:\Users\sina\AppData\Local\Programs\Python\Python313\Lib\site-packages\django_redis\cache.py", line 36, in _decorator
    raise e.__cause__
  File "C:\Users\sina\AppData\Local\Programs\Python\Python313\Lib\site-packages\django_redis\client\default.py", line 258, in get
    value = client.get(key)
  File "C:\Users\sina\AppData\Local\Programs\Python\Python313\Lib\site-packages\redis\commands\core.py", line 1821, in get
    return self.execute_command("GET", name)
           ~~~~~~~~~~~~~~~~~~~~^^^^^^^^^^^^^
  File "C:\Users\sina\AppData\Local\Programs\Python\Python313\Lib\site-packages\redis\client.py", line 545, in execute_command
    conn = self.connection or pool.get_connection(command_name, **options)
                              ~~~~~~~~~~~~~~~~~~~^^^^^^^^^^^^^^^^^^^^^^^^^
  File "C:\Users\sina\AppData\Local\Programs\Python\Python313\Lib\site-packages\redis\connection.py", line 1074, in get_connection
    connection.connect()
    ~~~~~~~~~~~~~~~~~~^^
  File "C:\Users\sina\AppData\Local\Programs\Python\Python313\Lib\site-packages\redis\connection.py", line 283, in connect
    raise ConnectionError(self._error_message(e))
redis.exceptions.ConnectionError: Error 10061 connecting to 127.0.0.1:6379. No connection could be made because the target machine actively refused it.
INFO 2025-09-10 17:05:51,756 security_middleware 16128 15424 API_RESPONSE [58523600] - GET /api/health/ - Status: 500
WARNING 2025-09-10 17:05:51,756 security_middleware 16128 15424 RESPONSE - GET /api/health/ - Status: 500 - Duration: 2.091s
WARNING 2025-09-10 17:05:51,756 monitoring 16128 15424 Slow request: GET /api/health/ took 2091.47ms
ERROR 2025-09-10 17:05:51,757 basehttp 16128 15424 "GET /api/health/ HTTP/1.1" 500 128426
INFO 2025-09-10 17:05:51,758 security_middleware 16128 15424 REQUEST - GET /api/health/ - User: Anonymous - IP: 127.0.0.1 - User-Agent: python-requests/2.32.4
INFO 2025-09-10 17:05:51,758 security_middleware 16128 15424 API_REQUEST [662577ae] - GET /api/health/ - User: Anonymous
ERROR 2025-09-10 17:05:53,815 log 16128 15424 Internal Server Error: /api/health/
Traceback (most recent call last):
  File "C:\Users\sina\AppData\Local\Programs\Python\Python313\Lib\site-packages\django_redis\cache.py", line 29, in _decorator
    return method(self, *args, **kwargs)
  File "C:\Users\sina\AppData\Local\Programs\Python\Python313\Lib\site-packages\django_redis\cache.py", line 99, in _get
    return self.client.get(key, default=default, version=version, client=client)
           ~~~~~~~~~~~~~~~^^^^^^^^^^^^^^^^^^^^^^^^^^^^^^^^^^^^^^^^^^^^^^^^^^^^^^
  File "C:\Users\sina\AppData\Local\Programs\Python\Python313\Lib\site-packages\django_redis\client\default.py", line 260, in get
    raise ConnectionInterrupted(connection=client) from e
django_redis.exceptions.ConnectionInterrupted: Redis ConnectionError: Error 10061 connecting to 127.0.0.1:6379. No connection could be made because the target machine actively refused it.

During handling of the above exception, another exception occurred:

Traceback (most recent call last):
  File "C:\Users\sina\AppData\Local\Programs\Python\Python313\Lib\site-packages\django\core\handlers\exception.py", line 55, in inner
    response = get_response(request)
  File "C:\Users\sina\AppData\Local\Programs\Python\Python313\Lib\site-packages\django\utils\deprecation.py", line 133, in __call__
    response = self.process_request(request)
  File "C:\Users\sina\AppData\Local\Programs\Python\Python313\Lib\site-packages\django\middleware\cache.py", line 158, in process_request
    cache_key = get_cache_key(request, self.key_prefix, "GET", cache=self.cache)
  File "C:\Users\sina\AppData\Local\Programs\Python\Python313\Lib\site-packages\django\utils\cache.py", line 391, in get_cache_key
    headerlist = cache.get(cache_key)
  File "C:\Users\sina\AppData\Local\Programs\Python\Python313\Lib\site-packages\django_redis\cache.py", line 92, in get
    value = self._get(key, default, version, client)
  File "C:\Users\sina\AppData\Local\Programs\Python\Python313\Lib\site-packages\django_redis\cache.py", line 36, in _decorator
    raise e.__cause__
  File "C:\Users\sina\AppData\Local\Programs\Python\Python313\Lib\site-packages\django_redis\client\default.py", line 258, in get
    value = client.get(key)
  File "C:\Users\sina\AppData\Local\Programs\Python\Python313\Lib\site-packages\redis\commands\core.py", line 1821, in get
    return self.execute_command("GET", name)
           ~~~~~~~~~~~~~~~~~~~~^^^^^^^^^^^^^
  File "C:\Users\sina\AppData\Local\Programs\Python\Python313\Lib\site-packages\redis\client.py", line 545, in execute_command
    conn = self.connection or pool.get_connection(command_name, **options)
                              ~~~~~~~~~~~~~~~~~~~^^^^^^^^^^^^^^^^^^^^^^^^^
  File "C:\Users\sina\AppData\Local\Programs\Python\Python313\Lib\site-packages\redis\connection.py", line 1074, in get_connection
    connection.connect()
    ~~~~~~~~~~~~~~~~~~^^
  File "C:\Users\sina\AppData\Local\Programs\Python\Python313\Lib\site-packages\redis\connection.py", line 283, in connect
    raise ConnectionError(self._error_message(e))
redis.exceptions.ConnectionError: Error 10061 connecting to 127.0.0.1:6379. No connection could be made because the target machine actively refused it.
INFO 2025-09-10 17:05:53,819 security_middleware 16128 15424 API_RESPONSE [662577ae] - GET /api/health/ - Status: 500
WARNING 2025-09-10 17:05:53,819 security_middleware 16128 15424 RESPONSE - GET /api/health/ - Status: 500 - Duration: 2.061s
WARNING 2025-09-10 17:05:53,819 monitoring 16128 15424 Slow request: GET /api/health/ took 2061.38ms
ERROR 2025-09-10 17:05:53,820 basehttp 16128 15424 "GET /api/health/ HTTP/1.1" 500 128426
INFO 2025-09-10 17:05:53,821 security_middleware 16128 15424 REQUEST - GET /api/health/ - User: Anonymous - IP: 127.0.0.1 - User-Agent: python-requests/2.32.4
INFO 2025-09-10 17:05:53,821 security_middleware 16128 15424 API_REQUEST [7efe0965] - GET /api/health/ - User: Anonymous
ERROR 2025-09-10 17:05:55,941 log 16128 15424 Internal Server Error: /api/health/
Traceback (most recent call last):
  File "C:\Users\sina\AppData\Local\Programs\Python\Python313\Lib\site-packages\django_redis\cache.py", line 29, in _decorator
    return method(self, *args, **kwargs)
  File "C:\Users\sina\AppData\Local\Programs\Python\Python313\Lib\site-packages\django_redis\cache.py", line 99, in _get
    return self.client.get(key, default=default, version=version, client=client)
           ~~~~~~~~~~~~~~~^^^^^^^^^^^^^^^^^^^^^^^^^^^^^^^^^^^^^^^^^^^^^^^^^^^^^^
  File "C:\Users\sina\AppData\Local\Programs\Python\Python313\Lib\site-packages\django_redis\client\default.py", line 260, in get
    raise ConnectionInterrupted(connection=client) from e
django_redis.exceptions.ConnectionInterrupted: Redis ConnectionError: Error 10061 connecting to 127.0.0.1:6379. No connection could be made because the target machine actively refused it.

During handling of the above exception, another exception occurred:

Traceback (most recent call last):
  File "C:\Users\sina\AppData\Local\Programs\Python\Python313\Lib\site-packages\django\core\handlers\exception.py", line 55, in inner
    response = get_response(request)
  File "C:\Users\sina\AppData\Local\Programs\Python\Python313\Lib\site-packages\django\utils\deprecation.py", line 133, in __call__
    response = self.process_request(request)
  File "C:\Users\sina\AppData\Local\Programs\Python\Python313\Lib\site-packages\django\middleware\cache.py", line 158, in process_request
    cache_key = get_cache_key(request, self.key_prefix, "GET", cache=self.cache)
  File "C:\Users\sina\AppData\Local\Programs\Python\Python313\Lib\site-packages\django\utils\cache.py", line 391, in get_cache_key
    headerlist = cache.get(cache_key)
  File "C:\Users\sina\AppData\Local\Programs\Python\Python313\Lib\site-packages\django_redis\cache.py", line 92, in get
    value = self._get(key, default, version, client)
  File "C:\Users\sina\AppData\Local\Programs\Python\Python313\Lib\site-packages\django_redis\cache.py", line 36, in _decorator
    raise e.__cause__
  File "C:\Users\sina\AppData\Local\Programs\Python\Python313\Lib\site-packages\django_redis\client\default.py", line 258, in get
    value = client.get(key)
  File "C:\Users\sina\AppData\Local\Programs\Python\Python313\Lib\site-packages\redis\commands\core.py", line 1821, in get
    return self.execute_command("GET", name)
           ~~~~~~~~~~~~~~~~~~~~^^^^^^^^^^^^^
  File "C:\Users\sina\AppData\Local\Programs\Python\Python313\Lib\site-packages\redis\client.py", line 545, in execute_command
    conn = self.connection or pool.get_connection(command_name, **options)
                              ~~~~~~~~~~~~~~~~~~~^^^^^^^^^^^^^^^^^^^^^^^^^
  File "C:\Users\sina\AppData\Local\Programs\Python\Python313\Lib\site-packages\redis\connection.py", line 1074, in get_connection
    connection.connect()
    ~~~~~~~~~~~~~~~~~~^^
  File "C:\Users\sina\AppData\Local\Programs\Python\Python313\Lib\site-packages\redis\connection.py", line 283, in connect
    raise ConnectionError(self._error_message(e))
redis.exceptions.ConnectionError: Error 10061 connecting to 127.0.0.1:6379. No connection could be made because the target machine actively refused it.
INFO 2025-09-10 17:05:55,944 security_middleware 16128 15424 API_RESPONSE [7efe0965] - GET /api/health/ - Status: 500
WARNING 2025-09-10 17:05:55,944 security_middleware 16128 15424 RESPONSE - GET /api/health/ - Status: 500 - Duration: 2.123s
WARNING 2025-09-10 17:05:55,944 monitoring 16128 15424 Slow request: GET /api/health/ took 2123.24ms
ERROR 2025-09-10 17:05:55,945 basehttp 16128 15424 "GET /api/health/ HTTP/1.1" 500 128426
INFO 2025-09-10 17:07:16,751 autoreload 16128 1144 D:\project\uni\backend\config\settings.py changed, reloading.
INFO 2025-09-10 17:07:17,486 autoreload 15368 16440 Watching for file changes with StatReloader
INFO 2025-09-10 17:07:52,267 autoreload 15368 16440 D:\project\uni\backend\config\settings.py changed, reloading.
INFO 2025-09-10 17:07:52,983 autoreload 20864 19916 Watching for file changes with StatReloader
INFO 2025-09-10 17:08:09,325 security_middleware 20864 4172 REQUEST - GET /api/health/ - User: Anonymous - IP: 127.0.0.1 - User-Agent: python-requests/2.32.4
INFO 2025-09-10 17:08:09,326 security_middleware 20864 4172 API_REQUEST [0f5bad3a] - GET /api/health/ - User: Anonymous
INFO 2025-09-10 17:08:09,332 security_middleware 20864 4172 API_RESPONSE [0f5bad3a] - GET /api/health/ - Status: 200
INFO 2025-09-10 17:08:09,332 security_middleware 20864 4172 RESPONSE - GET /api/health/ - Status: 200 - Duration: 0.007s
INFO 2025-09-10 17:08:09,333 basehttp 20864 4172 "GET /api/health/ HTTP/1.1" 200 251
INFO 2025-09-10 17:08:09,334 security_middleware 20864 4172 REQUEST - GET /api/status/ - User: Anonymous - IP: 127.0.0.1 - User-Agent: python-requests/2.32.4
INFO 2025-09-10 17:08:09,334 security_middleware 20864 4172 API_REQUEST [806a7bb6] - GET /api/status/ - User: Anonymous
INFO 2025-09-10 17:08:09,335 security_middleware 20864 4172 API_RESPONSE [806a7bb6] - GET /api/status/ - Status: 200
INFO 2025-09-10 17:08:09,335 security_middleware 20864 4172 RESPONSE - GET /api/status/ - Status: 200 - Duration: 0.001s
INFO 2025-09-10 17:08:09,336 basehttp 20864 4172 "GET /api/status/ HTTP/1.1" 200 151
INFO 2025-09-10 17:08:09,337 security_middleware 20864 4172 REQUEST - GET /api/info/ - User: Anonymous - IP: 127.0.0.1 - User-Agent: python-requests/2.32.4
INFO 2025-09-10 17:08:09,337 security_middleware 20864 4172 API_REQUEST [fb7bc722] - GET /api/info/ - User: Anonymous
INFO 2025-09-10 17:08:10,346 security_middleware 20864 4172 API_RESPONSE [fb7bc722] - GET /api/info/ - Status: 200
INFO 2025-09-10 17:08:10,346 security_middleware 20864 4172 RESPONSE - GET /api/info/ - Status: 200 - Duration: 1.010s
WARNING 2025-09-10 17:08:10,347 monitoring 20864 4172 Slow request: GET /api/info/ took 1009.92ms
INFO 2025-09-10 17:08:10,347 basehttp 20864 4172 "GET /api/info/ HTTP/1.1" 200 803
INFO 2025-09-10 17:08:10,348 security_middleware 20864 4172 REQUEST - GET /api/version/ - User: Anonymous - IP: 127.0.0.1 - User-Agent: python-requests/2.32.4
INFO 2025-09-10 17:08:10,349 security_middleware 20864 4172 API_REQUEST [39434075] - GET /api/version/ - User: Anonymous
INFO 2025-09-10 17:08:10,349 security_middleware 20864 4172 API_RESPONSE [39434075] - GET /api/version/ - Status: 200
INFO 2025-09-10 17:08:10,350 security_middleware 20864 4172 RESPONSE - GET /api/version/ - Status: 200 - Duration: 0.001s
INFO 2025-09-10 17:08:10,350 basehttp 20864 4172 "GET /api/version/ HTTP/1.1" 200 914
INFO 2025-09-10 17:08:10,351 security_middleware 20864 4172 REQUEST - GET /api/docs/ - User: Anonymous - IP: 127.0.0.1 - User-Agent: python-requests/2.32.4
INFO 2025-09-10 17:08:10,352 security_middleware 20864 4172 API_REQUEST [e8847fb8] - GET /api/docs/ - User: Anonymous
INFO 2025-09-10 17:08:10,355 security_middleware 20864 4172 API_RESPONSE [e8847fb8] - GET /api/docs/ - Status: 401
WARNING 2025-09-10 17:08:10,355 security_middleware 20864 4172 RESPONSE - GET /api/docs/ - Status: 401 - Duration: 0.004s
WARNING 2025-09-10 17:08:10,356 log 20864 4172 Unauthorized: /api/docs/
WARNING 2025-09-10 17:08:10,356 basehttp 20864 4172 "GET /api/docs/ HTTP/1.1" 401 16
INFO 2025-09-10 17:08:10,357 security_middleware 20864 4172 REQUEST - GET /api/redoc/ - User: Anonymous - IP: 127.0.0.1 - User-Agent: python-requests/2.32.4
INFO 2025-09-10 17:08:10,358 security_middleware 20864 4172 API_REQUEST [34903784] - GET /api/redoc/ - User: Anonymous
INFO 2025-09-10 17:08:10,358 security_middleware 20864 4172 API_RESPONSE [34903784] - GET /api/redoc/ - Status: 401
WARNING 2025-09-10 17:08:10,359 security_middleware 20864 4172 RESPONSE - GET /api/redoc/ - Status: 401 - Duration: 0.001s
WARNING 2025-09-10 17:08:10,359 log 20864 4172 Unauthorized: /api/redoc/
WARNING 2025-09-10 17:08:10,359 basehttp 20864 4172 "GET /api/redoc/ HTTP/1.1" 401 16
INFO 2025-09-10 17:08:10,360 security_middleware 20864 4172 REQUEST - GET /api/schema/ - User: Anonymous - IP: 127.0.0.1 - User-Agent: python-requests/2.32.4
INFO 2025-09-10 17:08:10,360 security_middleware 20864 4172 API_REQUEST [562dd560] - GET /api/schema/ - User: Anonymous
INFO 2025-09-10 17:08:10,476 security_middleware 20864 4172 API_RESPONSE [562dd560] - GET /api/schema/ - Status: 500
WARNING 2025-09-10 17:08:10,476 security_middleware 20864 4172 RESPONSE - GET /api/schema/ - Status: 500 - Duration: 0.116s
ERROR 2025-09-10 17:08:10,477 basehttp 20864 4172 "GET /api/schema/ HTTP/1.1" 500 131833
INFO 2025-09-10 17:08:10,479 security_middleware 20864 4172 REQUEST - GET /api/ - User: Anonymous - IP: 127.0.0.1 - User-Agent: python-requests/2.32.4
INFO 2025-09-10 17:08:10,479 security_middleware 20864 4172 API_REQUEST [2f04b136] - GET /api/ - User: Anonymous
INFO 2025-09-10 17:08:10,485 security_middleware 20864 4172 API_RESPONSE [2f04b136] - GET /api/ - Status: 404
WARNING 2025-09-10 17:08:10,485 security_middleware 20864 4172 RESPONSE - GET /api/ - Status: 404 - Duration: 0.006s
WARNING 2025-09-10 17:08:10,485 log 20864 4172 Not Found: /api/
WARNING 2025-09-10 17:08:10,486 basehttp 20864 4172 "GET /api/ HTTP/1.1" 404 5859
INFO 2025-09-10 17:08:10,487 security_middleware 20864 4172 REQUEST - GET /api/users/ - User: Anonymous - IP: 127.0.0.1 - User-Agent: python-requests/2.32.4
INFO 2025-09-10 17:08:10,487 security_middleware 20864 4172 API_REQUEST [84f77f89] - GET /api/users/ - User: Anonymous
INFO 2025-09-10 17:08:10,491 security_middleware 20864 4172 API_RESPONSE [84f77f89] - GET /api/users/ - Status: 404
WARNING 2025-09-10 17:08:10,492 security_middleware 20864 4172 RESPONSE - GET /api/users/ - Status: 404 - Duration: 0.004s
WARNING 2025-09-10 17:08:10,492 log 20864 4172 Not Found: /api/users/
WARNING 2025-09-10 17:08:10,492 basehttp 20864 4172 "GET /api/users/ HTTP/1.1" 404 8303
INFO 2025-09-10 17:08:10,493 security_middleware 20864 4172 REQUEST - GET /api/courses/ - User: Anonymous - IP: 127.0.0.1 - User-Agent: python-requests/2.32.4
INFO 2025-09-10 17:08:10,494 security_middleware 20864 4172 API_REQUEST [f44fab89] - GET /api/courses/ - User: Anonymous
INFO 2025-09-10 17:08:10,495 security_middleware 20864 4172 API_RESPONSE [f44fab89] - GET /api/courses/ - Status: 401
WARNING 2025-09-10 17:08:10,495 security_middleware 20864 4172 RESPONSE - GET /api/courses/ - Status: 401 - Duration: 0.002s
WARNING 2025-09-10 17:08:10,495 log 20864 4172 Unauthorized: /api/courses/
WARNING 2025-09-10 17:08:10,496 basehttp 20864 4172 "GET /api/courses/ HTTP/1.1" 401 178
INFO 2025-09-10 17:08:10,497 security_middleware 20864 4172 REQUEST - GET /api/announcements/ - User: Anonymous - IP: 127.0.0.1 - User-Agent: python-requests/2.32.4
INFO 2025-09-10 17:08:10,497 security_middleware 20864 4172 API_REQUEST [5e18a22a] - GET /api/announcements/ - User: Anonymous
INFO 2025-09-10 17:08:10,497 security_middleware 20864 4172 API_RESPONSE [5e18a22a] - GET /api/announcements/ - Status: 401
WARNING 2025-09-10 17:08:10,498 security_middleware 20864 4172 RESPONSE - GET /api/announcements/ - Status: 401 - Duration: 0.001s
WARNING 2025-09-10 17:08:10,498 log 20864 4172 Unauthorized: /api/announcements/
WARNING 2025-09-10 17:08:10,498 basehttp 20864 4172 "GET /api/announcements/ HTTP/1.1" 401 184
INFO 2025-09-10 17:08:10,499 security_middleware 20864 4172 REQUEST - GET /api/assignments/ - User: Anonymous - IP: 127.0.0.1 - User-Agent: python-requests/2.32.4
INFO 2025-09-10 17:08:10,499 security_middleware 20864 4172 API_REQUEST [675465de] - GET /api/assignments/ - User: Anonymous
INFO 2025-09-10 17:08:10,500 security_middleware 20864 4172 API_RESPONSE [675465de] - GET /api/assignments/ - Status: 401
WARNING 2025-09-10 17:08:10,500 security_middleware 20864 4172 RESPONSE - GET /api/assignments/ - Status: 401 - Duration: 0.001s
WARNING 2025-09-10 17:08:10,500 log 20864 4172 Unauthorized: /api/assignments/
WARNING 2025-09-10 17:08:10,501 basehttp 20864 4172 "GET /api/assignments/ HTTP/1.1" 401 182
INFO 2025-09-10 17:08:10,502 security_middleware 20864 4172 REQUEST - GET /api/nonexistent/ - User: Anonymous - IP: 127.0.0.1 - User-Agent: python-requests/2.32.4
INFO 2025-09-10 17:08:10,502 security_middleware 20864 4172 API_REQUEST [7d6b7ae1] - GET /api/nonexistent/ - User: Anonymous
INFO 2025-09-10 17:08:10,506 security_middleware 20864 4172 API_RESPONSE [7d6b7ae1] - GET /api/nonexistent/ - Status: 404
WARNING 2025-09-10 17:08:10,506 security_middleware 20864 4172 RESPONSE - GET /api/nonexistent/ - Status: 404 - Duration: 0.004s
WARNING 2025-09-10 17:08:10,507 log 20864 4172 Not Found: /api/nonexistent/
WARNING 2025-09-10 17:08:10,507 basehttp 20864 4172 "GET /api/nonexistent/ HTTP/1.1" 404 5895
INFO 2025-09-10 17:08:10,509 security_middleware 20864 4172 REQUEST - POST /api/health/ - User: Anonymous - IP: 127.0.0.1 - User-Agent: python-requests/2.32.4
INFO 2025-09-10 17:08:10,510 security_middleware 20864 4172 API_REQUEST [68a16c63] - POST /api/health/ - User: Anonymous
INFO 2025-09-10 17:08:10,511 security_middleware 20864 4172 API_RESPONSE [68a16c63] - POST /api/health/ - Status: 405
WARNING 2025-09-10 17:08:10,511 security_middleware 20864 4172 RESPONSE - POST /api/health/ - Status: 405 - Duration: 0.002s
WARNING 2025-09-10 17:08:10,511 log 20864 4172 Method Not Allowed: /api/health/
WARNING 2025-09-10 17:08:10,511 basehttp 20864 4172 "POST /api/health/ HTTP/1.1" 405 168
INFO 2025-09-10 17:08:10,513 security_middleware 20864 4172 REQUEST - GET /api/health/ - User: Anonymous - IP: 127.0.0.1 - User-Agent: python-requests/2.32.4
INFO 2025-09-10 17:08:10,513 security_middleware 20864 4172 API_REQUEST [ef116806] - GET /api/health/ - User: Anonymous
INFO 2025-09-10 17:08:10,513 security_middleware 20864 4172 API_RESPONSE [ef116806] - GET /api/health/ - Status: 200
INFO 2025-09-10 17:08:10,513 security_middleware 20864 4172 RESPONSE - GET /api/health/ - Status: 200 - Duration: 0.001s
INFO 2025-09-10 17:08:10,514 basehttp 20864 4172 "GET /api/health/ HTTP/1.1" 200 251
INFO 2025-09-10 17:08:10,515 security_middleware 20864 4172 REQUEST - GET /api/version/ - User: Anonymous - IP: 127.0.0.1 - User-Agent: python-requests/2.32.4
INFO 2025-09-10 17:08:10,515 security_middleware 20864 4172 API_REQUEST [fc1dabd6] - GET /api/version/ - User: Anonymous
INFO 2025-09-10 17:08:10,516 security_middleware 20864 4172 API_RESPONSE [fc1dabd6] - GET /api/version/ - Status: 200
INFO 2025-09-10 17:08:10,517 security_middleware 20864 4172 RESPONSE - GET /api/version/ - Status: 200 - Duration: 0.001s
INFO 2025-09-10 17:08:10,517 basehttp 20864 4172 "GET /api/version/ HTTP/1.1" 200 914
INFO 2025-09-10 17:08:10,518 security_middleware 20864 4172 REQUEST - GET /api/health/ - User: Anonymous - IP: 127.0.0.1 - User-Agent: python-requests/2.32.4
INFO 2025-09-10 17:08:10,518 security_middleware 20864 4172 API_REQUEST [9a6cd807] - GET /api/health/ - User: Anonymous
INFO 2025-09-10 17:08:10,523 security_middleware 20864 4172 API_RESPONSE [9a6cd807] - GET /api/health/ - Status: 200
INFO 2025-09-10 17:08:10,523 security_middleware 20864 4172 RESPONSE - GET /api/health/ - Status: 200 - Duration: 0.005s
INFO 2025-09-10 17:08:10,523 basehttp 20864 4172 "GET /api/health/ HTTP/1.1" 200 251
INFO 2025-09-10 17:08:10,524 security_middleware 20864 4172 REQUEST - GET /api/health/ - User: Anonymous - IP: 127.0.0.1 - User-Agent: python-requests/2.32.4
INFO 2025-09-10 17:08:10,525 security_middleware 20864 4172 API_REQUEST [ff67ad69] - GET /api/health/ - User: Anonymous
INFO 2025-09-10 17:08:10,525 security_middleware 20864 4172 API_RESPONSE [ff67ad69] - GET /api/health/ - Status: 200
INFO 2025-09-10 17:08:10,525 security_middleware 20864 4172 RESPONSE - GET /api/health/ - Status: 200 - Duration: 0.001s
INFO 2025-09-10 17:08:10,526 basehttp 20864 4172 "GET /api/health/ HTTP/1.1" 200 251
INFO 2025-09-10 17:08:10,526 security_middleware 20864 4172 REQUEST - GET /api/health/ - User: Anonymous - IP: 127.0.0.1 - User-Agent: python-requests/2.32.4
INFO 2025-09-10 17:08:10,527 security_middleware 20864 4172 API_REQUEST [5f278361] - GET /api/health/ - User: Anonymous
INFO 2025-09-10 17:08:10,533 security_middleware 20864 4172 API_RESPONSE [5f278361] - GET /api/health/ - Status: 200
INFO 2025-09-10 17:08:10,533 security_middleware 20864 4172 RESPONSE - GET /api/health/ - Status: 200 - Duration: 0.006s
INFO 2025-09-10 17:08:10,533 basehttp 20864 4172 "GET /api/health/ HTTP/1.1" 200 251
INFO 2025-09-10 17:08:25,308 security_middleware 20864 14352 REQUEST - GET /api/health/ - User: Anonymous - IP: 127.0.0.1 - User-Agent: Mozilla/5.0 (Windows NT 10.0; Win64; x64) AppleWebKit/537.36 (KHTML, like Gecko) Code/1.103.2 Chrome/138.0.7204.100 Electron/37.2.3 Safari/537.36
INFO 2025-09-10 17:08:25,308 security_middleware 20864 14352 API_REQUEST [4d15bce4] - GET /api/health/ - User: Anonymous
INFO 2025-09-10 17:08:25,431 security_middleware 20864 14352 API_RESPONSE [4d15bce4] - GET /api/health/ - Status: 200
INFO 2025-09-10 17:08:25,432 security_middleware 20864 14352 RESPONSE - GET /api/health/ - Status: 200 - Duration: 0.124s
INFO 2025-09-10 17:08:25,433 basehttp 20864 14352 "GET /api/health/?id=7eda25ab-688e-4790-acbd-62584a55e741&vscodeBrowserReqId=1757511505303 HTTP/1.1" 200 6242
INFO 2025-09-10 17:10:20,225 autoreload 20864 19916 D:\project\uni\backend\config\settings.py changed, reloading.
INFO 2025-09-10 17:10:21,070 autoreload 1964 21200 Watching for file changes with StatReloader
INFO 2025-09-10 17:13:45,827 autoreload 20432 12508 Watching for file changes with StatReloader
INFO 2025-09-10 17:17:32,431 autoreload 1964 21200 D:\project\uni\backend\apps\notifications\models.py changed, reloading.
INFO 2025-09-10 17:17:33,205 autoreload 21656 3248 Watching for file changes with StatReloader
INFO 2025-09-10 17:21:01,701 autoreload 21656 3248 D:\project\uni\backend\config\settings.py changed, reloading.
INFO 2025-09-10 17:21:02,490 autoreload 11220 22348 Watching for file changes with StatReloader
INFO 2025-09-10 17:21:08,240 autoreload 11220 22348 D:\project\uni\backend\config\settings.py changed, reloading.
INFO 2025-09-10 17:21:08,910 autoreload 7840 21984 Watching for file changes with StatReloader
INFO 2025-09-10 17:21:18,867 autoreload 7840 21984 D:\project\uni\backend\config\settings.py changed, reloading.
INFO 2025-09-10 17:21:19,719 autoreload 18184 16108 Watching for file changes with StatReloader
INFO 2025-09-10 17:24:14,519 autoreload 18184 16108 D:\project\uni\backend\apps\notifications\views.py changed, reloading.
INFO 2025-09-10 17:24:15,230 autoreload 21772 19756 Watching for file changes with StatReloader
INFO 2025-09-10 17:27:02,750 autoreload 21772 19756 D:\project\uni\backend\apps\notifications\views.py changed, reloading.
INFO 2025-09-10 17:27:03,421 autoreload 22128 10748 Watching for file changes with StatReloader
INFO 2025-09-10 17:27:13,223 autoreload 22128 10748 D:\project\uni\backend\apps\notifications\serializers.py changed, reloading.
INFO 2025-09-10 17:27:13,850 autoreload 1964 21120 Watching for file changes with StatReloader
INFO 2025-09-10 17:27:24,742 autoreload 1964 21120 D:\project\uni\backend\apps\notifications\services.py changed, reloading.
INFO 2025-09-10 17:27:25,372 autoreload 13132 21576 Watching for file changes with StatReloader
INFO 2025-09-10 17:27:45,838 autoreload 13132 21576 D:\project\uni\backend\apps\notifications\services.py changed, reloading.
INFO 2025-09-10 17:27:46,567 autoreload 16600 7136 Watching for file changes with StatReloader
INFO 2025-09-10 17:27:57,582 autoreload 16600 7136 D:\project\uni\backend\apps\notifications\services.py changed, reloading.
INFO 2025-09-10 17:27:58,253 autoreload 18284 14036 Watching for file changes with StatReloader
INFO 2025-09-10 17:28:14,532 autoreload 18284 14036 D:\project\uni\backend\apps\notifications\services.py changed, reloading.
INFO 2025-09-10 17:28:15,267 autoreload 19468 19876 Watching for file changes with StatReloader
INFO 2025-09-10 17:28:27,323 autoreload 19468 19876 D:\project\uni\backend\apps\notifications\services.py changed, reloading.
INFO 2025-09-10 17:28:28,035 autoreload 4508 6376 Watching for file changes with StatReloader
INFO 2025-09-10 17:28:39,070 autoreload 4508 6376 D:\project\uni\backend\apps\notifications\services.py changed, reloading.
INFO 2025-09-10 17:28:39,721 autoreload 7136 21028 Watching for file changes with StatReloader
INFO 2025-09-10 17:28:53,833 autoreload 7136 21028 D:\project\uni\backend\apps\notifications\services.py changed, reloading.
INFO 2025-09-10 17:28:54,595 autoreload 21768 22400 Watching for file changes with StatReloader
INFO 2025-09-10 17:29:24,251 autoreload 21768 22400 D:\project\uni\backend\apps\notifications\services.py changed, reloading.
INFO 2025-09-10 17:29:24,969 autoreload 15092 6540 Watching for file changes with StatReloader
INFO 2025-09-10 17:35:23,654 autoreload 15092 6540 D:\project\uni\backend\apps\notifications\urls.py changed, reloading.
INFO 2025-09-10 17:35:24,458 autoreload 20932 4136 Watching for file changes with StatReloader
